--- Logging error ---
Traceback (most recent call last):
  File "C:\Program Files\Python311\Lib\logging\__init__.py", line 1113, in emit
    stream.write(msg + self.terminator)
  File "C:\Program Files\Python311\Lib\encodings\cp1251.py", line 19, in encode
    return codecs.charmap_encode(input,self.errors,encoding_table)[0]
           ^^^^^^^^^^^^^^^^^^^^^^^^^^^^^^^^^^^^^^^^^^^^^^^^^^^^^^^
UnicodeEncodeError: 'charmap' codec can't encode character '\u2705' in position 51: character maps to <undefined>
Call stack:
  File "C:\Users\gabbi\OneDrive\Desktop\kovcheg\tests\integration\ark_system_integration_test.py", line 849, in <module>
    asyncio.run(main())
  File "C:\Program Files\Python311\Lib\asyncio\runners.py", line 190, in run
    return runner.run(main)
  File "C:\Program Files\Python311\Lib\asyncio\runners.py", line 118, in run
    return self._loop.run_until_complete(task)
  File "C:\Program Files\Python311\Lib\asyncio\base_events.py", line 640, in run_until_complete
    self.run_forever()
  File "C:\Program Files\Python311\Lib\asyncio\windows_events.py", line 321, in run_forever
    super().run_forever()
  File "C:\Program Files\Python311\Lib\asyncio\base_events.py", line 607, in run_forever
    self._run_once()
  File "C:\Program Files\Python311\Lib\asyncio\base_events.py", line 1922, in _run_once
    handle._run()
  File "C:\Program Files\Python311\Lib\asyncio\events.py", line 80, in _run
    self._context.run(self._callback, *self._args)
  File "C:\Users\gabbi\OneDrive\Desktop\kovcheg\tests\integration\ark_system_integration_test.py", line 846, in main
    tester = ARKSystemIntegrationTester()
  File "C:\Users\gabbi\OneDrive\Desktop\kovcheg\tests\integration\ark_system_integration_test.py", line 94, in __init__
    self._verify_biblical_foundation()
  File "C:\Users\gabbi\OneDrive\Desktop\kovcheg\tests\integration\ark_system_integration_test.py", line 115, in _verify_biblical_foundation
    self.logger.info(f"\u2705 Biblical foundation verified: {foundation_hash[:16]}...")
Message: '\u2705 Biblical foundation verified: 4b91d78f72a705c9...'
Arguments: ()
2025-06-11 23:15:48,255 - ARK_INTEGRATION - INFO - \u2705 Biblical foundation verified: 4b91d78f72a705c9...
--- Logging error ---
Traceback (most recent call last):
  File "C:\Program Files\Python311\Lib\logging\__init__.py", line 1113, in emit
    stream.write(msg + self.terminator)
  File "C:\Program Files\Python311\Lib\encodings\cp1251.py", line 19, in encode
    return codecs.charmap_encode(input,self.errors,encoding_table)[0]
           ^^^^^^^^^^^^^^^^^^^^^^^^^^^^^^^^^^^^^^^^^^^^^^^^^^^^^^^
UnicodeEncodeError: 'charmap' codec can't encode characters in position 51-52: character maps to <undefined>
Call stack:
  File "C:\Users\gabbi\OneDrive\Desktop\kovcheg\tests\integration\ark_system_integration_test.py", line 849, in <module>
    asyncio.run(main())
  File "C:\Program Files\Python311\Lib\asyncio\runners.py", line 190, in run
    return runner.run(main)
  File "C:\Program Files\Python311\Lib\asyncio\runners.py", line 118, in run
    return self._loop.run_until_complete(task)
  File "C:\Program Files\Python311\Lib\asyncio\base_events.py", line 640, in run_until_complete
    self.run_forever()
  File "C:\Program Files\Python311\Lib\asyncio\windows_events.py", line 321, in run_forever
    super().run_forever()
  File "C:\Program Files\Python311\Lib\asyncio\base_events.py", line 607, in run_forever
    self._run_once()
  File "C:\Program Files\Python311\Lib\asyncio\base_events.py", line 1922, in _run_once
    handle._run()
  File "C:\Program Files\Python311\Lib\asyncio\events.py", line 80, in _run
    self._context.run(self._callback, *self._args)
  File "C:\Users\gabbi\OneDrive\Desktop\kovcheg\tests\integration\ark_system_integration_test.py", line 846, in main
    tester = ARKSystemIntegrationTester()
  File "C:\Users\gabbi\OneDrive\Desktop\kovcheg\tests\integration\ark_system_integration_test.py", line 96, in __init__
    self.logger.info("\U0001f6e1\ufe0f ARK System Integration Tester initialized")
Message: '\U0001f6e1\ufe0f ARK System Integration Tester initialized'
Arguments: ()
2025-06-11 23:15:48,262 - ARK_INTEGRATION - INFO - \U0001f6e1\ufe0f ARK System Integration Tester initialized
--- Logging error ---
Traceback (most recent call last):
  File "C:\Program Files\Python311\Lib\logging\__init__.py", line 1113, in emit
    stream.write(msg + self.terminator)
  File "C:\Program Files\Python311\Lib\encodings\cp1251.py", line 19, in encode
    return codecs.charmap_encode(input,self.errors,encoding_table)[0]
           ^^^^^^^^^^^^^^^^^^^^^^^^^^^^^^^^^^^^^^^^^^^^^^^^^^^^^^^
UnicodeEncodeError: 'charmap' codec can't encode character '\U0001f4dc' in position 51: character maps to <undefined>
Call stack:
  File "C:\Users\gabbi\OneDrive\Desktop\kovcheg\tests\integration\ark_system_integration_test.py", line 849, in <module>
    asyncio.run(main())
  File "C:\Program Files\Python311\Lib\asyncio\runners.py", line 190, in run
    return runner.run(main)
  File "C:\Program Files\Python311\Lib\asyncio\runners.py", line 118, in run
    return self._loop.run_until_complete(task)
  File "C:\Program Files\Python311\Lib\asyncio\base_events.py", line 640, in run_until_complete
    self.run_forever()
  File "C:\Program Files\Python311\Lib\asyncio\windows_events.py", line 321, in run_forever
    super().run_forever()
  File "C:\Program Files\Python311\Lib\asyncio\base_events.py", line 607, in run_forever
    self._run_once()
  File "C:\Program Files\Python311\Lib\asyncio\base_events.py", line 1922, in _run_once
    handle._run()
  File "C:\Program Files\Python311\Lib\asyncio\events.py", line 80, in _run
    self._context.run(self._callback, *self._args)
  File "C:\Users\gabbi\OneDrive\Desktop\kovcheg\tests\integration\ark_system_integration_test.py", line 846, in main
    tester = ARKSystemIntegrationTester()
  File "C:\Users\gabbi\OneDrive\Desktop\kovcheg\tests\integration\ark_system_integration_test.py", line 97, in __init__
    self.logger.info(f"\U0001f4dc Biblical Foundation: {BIBLICAL_FOUNDATION}")
Message: '\U0001f4dc Biblical Foundation: 1_Thessalonians_5_21_Test_everything_hold_fast_what_is_good'
Arguments: ()
2025-06-11 23:15:48,266 - ARK_INTEGRATION - INFO - \U0001f4dc Biblical Foundation: 1_Thessalonians_5_21_Test_everything_hold_fast_what_is_good
--- Logging error ---
Traceback (most recent call last):
  File "C:\Program Files\Python311\Lib\logging\__init__.py", line 1113, in emit
    stream.write(msg + self.terminator)
  File "C:\Program Files\Python311\Lib\encodings\cp1251.py", line 19, in encode
    return codecs.charmap_encode(input,self.errors,encoding_table)[0]
           ^^^^^^^^^^^^^^^^^^^^^^^^^^^^^^^^^^^^^^^^^^^^^^^^^^^^^^^
UnicodeEncodeError: 'charmap' codec can't encode character '\U0001f451' in position 51: character maps to <undefined>
Call stack:
  File "C:\Users\gabbi\OneDrive\Desktop\kovcheg\tests\integration\ark_system_integration_test.py", line 849, in <module>
    asyncio.run(main())
  File "C:\Program Files\Python311\Lib\asyncio\runners.py", line 190, in run
    return runner.run(main)
  File "C:\Program Files\Python311\Lib\asyncio\runners.py", line 118, in run
    return self._loop.run_until_complete(task)
  File "C:\Program Files\Python311\Lib\asyncio\base_events.py", line 640, in run_until_complete
    self.run_forever()
  File "C:\Program Files\Python311\Lib\asyncio\windows_events.py", line 321, in run_forever
    super().run_forever()
  File "C:\Program Files\Python311\Lib\asyncio\base_events.py", line 607, in run_forever
    self._run_once()
  File "C:\Program Files\Python311\Lib\asyncio\base_events.py", line 1922, in _run_once
    handle._run()
  File "C:\Program Files\Python311\Lib\asyncio\events.py", line 80, in _run
    self._context.run(self._callback, *self._args)
  File "C:\Users\gabbi\OneDrive\Desktop\kovcheg\tests\integration\ark_system_integration_test.py", line 846, in main
    tester = ARKSystemIntegrationTester()
  File "C:\Users\gabbi\OneDrive\Desktop\kovcheg\tests\integration\ark_system_integration_test.py", line 98, in __init__
    self.logger.info(f"\U0001f451 Divine Authority: {DIVINE_AUTHORITY}")
Message: '\U0001f451 Divine Authority: Romans_13_1_Let_every_soul_be_subject_to_governing_authorities'
Arguments: ()
2025-06-11 23:15:48,270 - ARK_INTEGRATION - INFO - \U0001f451 Divine Authority: Romans_13_1_Let_every_soul_be_subject_to_governing_authorities
--- Logging error ---
Traceback (most recent call last):
  File "C:\Program Files\Python311\Lib\logging\__init__.py", line 1113, in emit
    stream.write(msg + self.terminator)
  File "C:\Program Files\Python311\Lib\encodings\cp1251.py", line 19, in encode
    return codecs.charmap_encode(input,self.errors,encoding_table)[0]
           ^^^^^^^^^^^^^^^^^^^^^^^^^^^^^^^^^^^^^^^^^^^^^^^^^^^^^^^
UnicodeEncodeError: 'charmap' codec can't encode character '\U0001f680' in position 51: character maps to <undefined>
Call stack:
  File "C:\Users\gabbi\OneDrive\Desktop\kovcheg\tests\integration\ark_system_integration_test.py", line 849, in <module>
    asyncio.run(main())
  File "C:\Program Files\Python311\Lib\asyncio\runners.py", line 190, in run
    return runner.run(main)
  File "C:\Program Files\Python311\Lib\asyncio\runners.py", line 118, in run
    return self._loop.run_until_complete(task)
  File "C:\Program Files\Python311\Lib\asyncio\base_events.py", line 640, in run_until_complete
    self.run_forever()
  File "C:\Program Files\Python311\Lib\asyncio\windows_events.py", line 321, in run_forever
    super().run_forever()
  File "C:\Program Files\Python311\Lib\asyncio\base_events.py", line 607, in run_forever
    self._run_once()
  File "C:\Program Files\Python311\Lib\asyncio\base_events.py", line 1922, in _run_once
    handle._run()
  File "C:\Program Files\Python311\Lib\asyncio\events.py", line 80, in _run
    self._context.run(self._callback, *self._args)
  File "C:\Users\gabbi\OneDrive\Desktop\kovcheg\tests\integration\ark_system_integration_test.py", line 847, in main
    await tester.run_full_integration_test_suite()
  File "C:\Users\gabbi\OneDrive\Desktop\kovcheg\tests\integration\ark_system_integration_test.py", line 694, in run_full_integration_test_suite
    self.logger.info("\U0001f680 Starting ARK System Integration Test Suite")
Message: '\U0001f680 Starting ARK System Integration Test Suite'
Arguments: ()
2025-06-11 23:15:48,273 - ARK_INTEGRATION - INFO - \U0001f680 Starting ARK System Integration Test Suite
2025-06-11 23:15:48,276 - ARK_INTEGRATION - INFO - ================================================================================
--- Logging error ---
Traceback (most recent call last):
  File "C:\Program Files\Python311\Lib\logging\__init__.py", line 1113, in emit
    stream.write(msg + self.terminator)
  File "C:\Program Files\Python311\Lib\encodings\cp1251.py", line 19, in encode
    return codecs.charmap_encode(input,self.errors,encoding_table)[0]
           ^^^^^^^^^^^^^^^^^^^^^^^^^^^^^^^^^^^^^^^^^^^^^^^^^^^^^^^
UnicodeEncodeError: 'charmap' codec can't encode character '\U0001f3b2' in position 51: character maps to <undefined>
Call stack:
  File "C:\Users\gabbi\OneDrive\Desktop\kovcheg\tests\integration\ark_system_integration_test.py", line 849, in <module>
    asyncio.run(main())
  File "C:\Program Files\Python311\Lib\asyncio\runners.py", line 190, in run
    return runner.run(main)
  File "C:\Program Files\Python311\Lib\asyncio\runners.py", line 118, in run
    return self._loop.run_until_complete(task)
  File "C:\Program Files\Python311\Lib\asyncio\base_events.py", line 640, in run_until_complete
    self.run_forever()
  File "C:\Program Files\Python311\Lib\asyncio\windows_events.py", line 321, in run_forever
    super().run_forever()
  File "C:\Program Files\Python311\Lib\asyncio\base_events.py", line 607, in run_forever
    self._run_once()
  File "C:\Program Files\Python311\Lib\asyncio\base_events.py", line 1922, in _run_once
    handle._run()
  File "C:\Program Files\Python311\Lib\asyncio\events.py", line 80, in _run
    self._context.run(self._callback, *self._args)
  File "C:\Users\gabbi\OneDrive\Desktop\kovcheg\tests\integration\ark_system_integration_test.py", line 847, in main
    await tester.run_full_integration_test_suite()
  File "C:\Users\gabbi\OneDrive\Desktop\kovcheg\tests\integration\ark_system_integration_test.py", line 711, in run_full_integration_test_suite
    await test_method()
  File "C:\Users\gabbi\OneDrive\Desktop\kovcheg\tests\integration\ark_system_integration_test.py", line 159, in test_hw_entropy_generation
    self.logger.info("\U0001f3b2 Testing hardware entropy generation (HW-01)")
Message: '\U0001f3b2 Testing hardware entropy generation (HW-01)'
Arguments: ()
2025-06-11 23:15:48,277 - ARK_INTEGRATION - INFO - \U0001f3b2 Testing hardware entropy generation (HW-01)
--- Logging error ---
Traceback (most recent call last):
  File "C:\Program Files\Python311\Lib\logging\__init__.py", line 1113, in emit
    stream.write(msg + self.terminator)
  File "C:\Program Files\Python311\Lib\encodings\cp1251.py", line 19, in encode
    return codecs.charmap_encode(input,self.errors,encoding_table)[0]
           ^^^^^^^^^^^^^^^^^^^^^^^^^^^^^^^^^^^^^^^^^^^^^^^^^^^^^^^
UnicodeEncodeError: 'charmap' codec can't encode character '\u2705' in position 51: character maps to <undefined>
Call stack:
  File "C:\Users\gabbi\OneDrive\Desktop\kovcheg\tests\integration\ark_system_integration_test.py", line 849, in <module>
    asyncio.run(main())
  File "C:\Program Files\Python311\Lib\asyncio\runners.py", line 190, in run
    return runner.run(main)
  File "C:\Program Files\Python311\Lib\asyncio\runners.py", line 118, in run
    return self._loop.run_until_complete(task)
  File "C:\Program Files\Python311\Lib\asyncio\base_events.py", line 640, in run_until_complete
    self.run_forever()
  File "C:\Program Files\Python311\Lib\asyncio\windows_events.py", line 321, in run_forever
    super().run_forever()
  File "C:\Program Files\Python311\Lib\asyncio\base_events.py", line 607, in run_forever
    self._run_once()
  File "C:\Program Files\Python311\Lib\asyncio\base_events.py", line 1922, in _run_once
    handle._run()
  File "C:\Program Files\Python311\Lib\asyncio\events.py", line 80, in _run
    self._context.run(self._callback, *self._args)
  File "C:\Users\gabbi\OneDrive\Desktop\kovcheg\tests\integration\ark_system_integration_test.py", line 847, in main
    await tester.run_full_integration_test_suite()
  File "C:\Users\gabbi\OneDrive\Desktop\kovcheg\tests\integration\ark_system_integration_test.py", line 711, in run_full_integration_test_suite
    await test_method()
  File "C:\Users\gabbi\OneDrive\Desktop\kovcheg\tests\integration\ark_system_integration_test.py", line 178, in test_hw_entropy_generation
    self._record_test_result(
  File "C:\Users\gabbi\OneDrive\Desktop\kovcheg\tests\integration\ark_system_integration_test.py", line 145, in _record_test_result
    self.logger.info(f"{status} {compliance} - {test_name}")
Message: '\u2705 PASS \U0001f54a\ufe0f COMPLIANT - Hardware Entropy Generation'
Arguments: ()
2025-06-11 23:15:48,453 - ARK_INTEGRATION - INFO - \u2705 PASS \U0001f54a\ufe0f COMPLIANT - Hardware Entropy Generation
2025-06-11 23:15:48,455 - ARK_INTEGRATION - INFO -     SRS-REQ: HW-01
2025-06-11 23:15:48,455 - ARK_INTEGRATION - INFO -     Measured: 524288.000000, Threshold: 512000.000000
--- Logging error ---
Traceback (most recent call last):
  File "C:\Program Files\Python311\Lib\logging\__init__.py", line 1113, in emit
    stream.write(msg + self.terminator)
  File "C:\Program Files\Python311\Lib\encodings\cp1251.py", line 19, in encode
    return codecs.charmap_encode(input,self.errors,encoding_table)[0]
           ^^^^^^^^^^^^^^^^^^^^^^^^^^^^^^^^^^^^^^^^^^^^^^^^^^^^^^^
UnicodeEncodeError: 'charmap' codec can't encode character '\u26a1' in position 51: character maps to <undefined>
Call stack:
  File "C:\Users\gabbi\OneDrive\Desktop\kovcheg\tests\integration\ark_system_integration_test.py", line 849, in <module>
    asyncio.run(main())
  File "C:\Program Files\Python311\Lib\asyncio\runners.py", line 190, in run
    return runner.run(main)
  File "C:\Program Files\Python311\Lib\asyncio\runners.py", line 118, in run
    return self._loop.run_until_complete(task)
  File "C:\Program Files\Python311\Lib\asyncio\base_events.py", line 640, in run_until_complete
    self.run_forever()
  File "C:\Program Files\Python311\Lib\asyncio\windows_events.py", line 321, in run_forever
    super().run_forever()
  File "C:\Program Files\Python311\Lib\asyncio\base_events.py", line 607, in run_forever
    self._run_once()
  File "C:\Program Files\Python311\Lib\asyncio\base_events.py", line 1922, in _run_once
    handle._run()
  File "C:\Program Files\Python311\Lib\asyncio\events.py", line 80, in _run
    self._context.run(self._callback, *self._args)
  File "C:\Users\gabbi\OneDrive\Desktop\kovcheg\tests\integration\ark_system_integration_test.py", line 847, in main
    await tester.run_full_integration_test_suite()
  File "C:\Users\gabbi\OneDrive\Desktop\kovcheg\tests\integration\ark_system_integration_test.py", line 711, in run_full_integration_test_suite
    await test_method()
  File "C:\Users\gabbi\OneDrive\Desktop\kovcheg\tests\integration\ark_system_integration_test.py", line 208, in test_optic_gate_latency
    self.logger.info("\u26a1 Testing Optic Gate latency (HW-04)")
Message: '\u26a1 Testing Optic Gate latency (HW-04)'
Arguments: ()
2025-06-11 23:15:48,455 - ARK_INTEGRATION - INFO - \u26a1 Testing Optic Gate latency (HW-04)
--- Logging error ---
Traceback (most recent call last):
  File "C:\Program Files\Python311\Lib\logging\__init__.py", line 1113, in emit
    stream.write(msg + self.terminator)
  File "C:\Program Files\Python311\Lib\encodings\cp1251.py", line 19, in encode
    return codecs.charmap_encode(input,self.errors,encoding_table)[0]
           ^^^^^^^^^^^^^^^^^^^^^^^^^^^^^^^^^^^^^^^^^^^^^^^^^^^^^^^
UnicodeEncodeError: 'charmap' codec can't encode character '\u2705' in position 51: character maps to <undefined>
Call stack:
  File "C:\Users\gabbi\OneDrive\Desktop\kovcheg\tests\integration\ark_system_integration_test.py", line 849, in <module>
    asyncio.run(main())
  File "C:\Program Files\Python311\Lib\asyncio\runners.py", line 190, in run
    return runner.run(main)
  File "C:\Program Files\Python311\Lib\asyncio\runners.py", line 118, in run
    return self._loop.run_until_complete(task)
  File "C:\Program Files\Python311\Lib\asyncio\base_events.py", line 640, in run_until_complete
    self.run_forever()
  File "C:\Program Files\Python311\Lib\asyncio\windows_events.py", line 321, in run_forever
    super().run_forever()
  File "C:\Program Files\Python311\Lib\asyncio\base_events.py", line 607, in run_forever
    self._run_once()
  File "C:\Program Files\Python311\Lib\asyncio\base_events.py", line 1922, in _run_once
    handle._run()
  File "C:\Program Files\Python311\Lib\asyncio\events.py", line 80, in _run
    self._context.run(self._callback, *self._args)
  File "C:\Users\gabbi\OneDrive\Desktop\kovcheg\tests\integration\ark_system_integration_test.py", line 847, in main
    await tester.run_full_integration_test_suite()
  File "C:\Users\gabbi\OneDrive\Desktop\kovcheg\tests\integration\ark_system_integration_test.py", line 711, in run_full_integration_test_suite
    await test_method()
  File "C:\Users\gabbi\OneDrive\Desktop\kovcheg\tests\integration\ark_system_integration_test.py", line 238, in test_optic_gate_latency
    self._record_test_result(
  File "C:\Users\gabbi\OneDrive\Desktop\kovcheg\tests\integration\ark_system_integration_test.py", line 145, in _record_test_result
    self.logger.info(f"{status} {compliance} - {test_name}")
Message: '\u2705 PASS \U0001f54a\ufe0f COMPLIANT - Optic Gate Latency'
Arguments: ()
2025-06-11 23:15:48,459 - ARK_INTEGRATION - INFO - \u2705 PASS \U0001f54a\ufe0f COMPLIANT - Optic Gate Latency
2025-06-11 23:15:48,461 - ARK_INTEGRATION - INFO -     SRS-REQ: HW-04
2025-06-11 23:15:48,461 - ARK_INTEGRATION - INFO -     Measured: 8.500000, Threshold: 10.000000
--- Logging error ---
Traceback (most recent call last):
  File "C:\Program Files\Python311\Lib\logging\__init__.py", line 1113, in emit
    stream.write(msg + self.terminator)
  File "C:\Program Files\Python311\Lib\encodings\cp1251.py", line 19, in encode
    return codecs.charmap_encode(input,self.errors,encoding_table)[0]
           ^^^^^^^^^^^^^^^^^^^^^^^^^^^^^^^^^^^^^^^^^^^^^^^^^^^^^^^
UnicodeEncodeError: 'charmap' codec can't encode character '\U0001f4dc' in position 51: character maps to <undefined>
Call stack:
  File "C:\Users\gabbi\OneDrive\Desktop\kovcheg\tests\integration\ark_system_integration_test.py", line 849, in <module>
    asyncio.run(main())
  File "C:\Program Files\Python311\Lib\asyncio\runners.py", line 190, in run
    return runner.run(main)
  File "C:\Program Files\Python311\Lib\asyncio\runners.py", line 118, in run
    return self._loop.run_until_complete(task)
  File "C:\Program Files\Python311\Lib\asyncio\base_events.py", line 640, in run_until_complete
    self.run_forever()
  File "C:\Program Files\Python311\Lib\asyncio\windows_events.py", line 321, in run_forever
    super().run_forever()
  File "C:\Program Files\Python311\Lib\asyncio\base_events.py", line 607, in run_forever
    self._run_once()
  File "C:\Program Files\Python311\Lib\asyncio\base_events.py", line 1922, in _run_once
    handle._run()
  File "C:\Program Files\Python311\Lib\asyncio\events.py", line 80, in _run
    self._context.run(self._callback, *self._args)
  File "C:\Users\gabbi\OneDrive\Desktop\kovcheg\tests\integration\ark_system_integration_test.py", line 847, in main
    await tester.run_full_integration_test_suite()
  File "C:\Users\gabbi\OneDrive\Desktop\kovcheg\tests\integration\ark_system_integration_test.py", line 711, in run_full_integration_test_suite
    await test_method()
  File "C:\Users\gabbi\OneDrive\Desktop\kovcheg\tests\integration\ark_system_integration_test.py", line 261, in test_dsl_parser_compliance
    self.logger.info("\U0001f4dc Testing Ethics DSL parser ABNF compliance (SW-01)")
Message: '\U0001f4dc Testing Ethics DSL parser ABNF compliance (SW-01)'
Arguments: ()
2025-06-11 23:15:48,461 - ARK_INTEGRATION - INFO - \U0001f4dc Testing Ethics DSL parser ABNF compliance (SW-01)
--- Logging error ---
Traceback (most recent call last):
  File "C:\Program Files\Python311\Lib\logging\__init__.py", line 1113, in emit
    stream.write(msg + self.terminator)
  File "C:\Program Files\Python311\Lib\encodings\cp1251.py", line 19, in encode
    return codecs.charmap_encode(input,self.errors,encoding_table)[0]
           ^^^^^^^^^^^^^^^^^^^^^^^^^^^^^^^^^^^^^^^^^^^^^^^^^^^^^^^
UnicodeEncodeError: 'charmap' codec can't encode character '\u2705' in position 51: character maps to <undefined>
Call stack:
  File "C:\Users\gabbi\OneDrive\Desktop\kovcheg\tests\integration\ark_system_integration_test.py", line 849, in <module>
    asyncio.run(main())
  File "C:\Program Files\Python311\Lib\asyncio\runners.py", line 190, in run
    return runner.run(main)
  File "C:\Program Files\Python311\Lib\asyncio\runners.py", line 118, in run
    return self._loop.run_until_complete(task)
  File "C:\Program Files\Python311\Lib\asyncio\base_events.py", line 640, in run_until_complete
    self.run_forever()
  File "C:\Program Files\Python311\Lib\asyncio\windows_events.py", line 321, in run_forever
    super().run_forever()
  File "C:\Program Files\Python311\Lib\asyncio\base_events.py", line 607, in run_forever
    self._run_once()
  File "C:\Program Files\Python311\Lib\asyncio\base_events.py", line 1922, in _run_once
    handle._run()
  File "C:\Program Files\Python311\Lib\asyncio\events.py", line 80, in _run
    self._context.run(self._callback, *self._args)
  File "C:\Users\gabbi\OneDrive\Desktop\kovcheg\tests\integration\ark_system_integration_test.py", line 847, in main
    await tester.run_full_integration_test_suite()
  File "C:\Users\gabbi\OneDrive\Desktop\kovcheg\tests\integration\ark_system_integration_test.py", line 711, in run_full_integration_test_suite
    await test_method()
  File "C:\Users\gabbi\OneDrive\Desktop\kovcheg\tests\integration\ark_system_integration_test.py", line 290, in test_dsl_parser_compliance
    self._record_test_result(
  File "C:\Users\gabbi\OneDrive\Desktop\kovcheg\tests\integration\ark_system_integration_test.py", line 145, in _record_test_result
    self.logger.info(f"{status} {compliance} - {test_name}")
Message: '\u2705 PASS \U0001f54a\ufe0f COMPLIANT - Ethics DSL Parser ABNF Compliance'
Arguments: ()
2025-06-11 23:15:48,463 - ARK_INTEGRATION - INFO - \u2705 PASS \U0001f54a\ufe0f COMPLIANT - Ethics DSL Parser ABNF Compliance
2025-06-11 23:15:48,465 - ARK_INTEGRATION - INFO -     SRS-REQ: SW-01
2025-06-11 23:15:48,465 - ARK_INTEGRATION - INFO -     Measured: 100.000000, Threshold: 100.000000
--- Logging error ---
Traceback (most recent call last):
  File "C:\Program Files\Python311\Lib\logging\__init__.py", line 1113, in emit
    stream.write(msg + self.terminator)
  File "C:\Program Files\Python311\Lib\encodings\cp1251.py", line 19, in encode
    return codecs.charmap_encode(input,self.errors,encoding_table)[0]
           ^^^^^^^^^^^^^^^^^^^^^^^^^^^^^^^^^^^^^^^^^^^^^^^^^^^^^^^
UnicodeEncodeError: 'charmap' codec can't encode character '\U0001f9ca' in position 51: character maps to <undefined>
Call stack:
  File "C:\Users\gabbi\OneDrive\Desktop\kovcheg\tests\integration\ark_system_integration_test.py", line 849, in <module>
    asyncio.run(main())
  File "C:\Program Files\Python311\Lib\asyncio\runners.py", line 190, in run
    return runner.run(main)
  File "C:\Program Files\Python311\Lib\asyncio\runners.py", line 118, in run
    return self._loop.run_until_complete(task)
  File "C:\Program Files\Python311\Lib\asyncio\base_events.py", line 640, in run_until_complete
    self.run_forever()
  File "C:\Program Files\Python311\Lib\asyncio\windows_events.py", line 321, in run_forever
    super().run_forever()
  File "C:\Program Files\Python311\Lib\asyncio\base_events.py", line 607, in run_forever
    self._run_once()
  File "C:\Program Files\Python311\Lib\asyncio\base_events.py", line 1922, in _run_once
    handle._run()
  File "C:\Program Files\Python311\Lib\asyncio\events.py", line 80, in _run
    self._context.run(self._callback, *self._args)
  File "C:\Users\gabbi\OneDrive\Desktop\kovcheg\tests\integration\ark_system_integration_test.py", line 847, in main
    await tester.run_full_integration_test_suite()
  File "C:\Users\gabbi\OneDrive\Desktop\kovcheg\tests\integration\ark_system_integration_test.py", line 711, in run_full_integration_test_suite
    await test_method()
  File "C:\Users\gabbi\OneDrive\Desktop\kovcheg\tests\integration\ark_system_integration_test.py", line 342, in test_cold_mirror_performance
    self.logger.info("\U0001f9ca Testing Cold-Mirror performance (SW-02)")
Message: '\U0001f9ca Testing Cold-Mirror performance (SW-02)'
Arguments: ()
2025-06-11 23:15:48,465 - ARK_INTEGRATION - INFO - \U0001f9ca Testing Cold-Mirror performance (SW-02)
--- Logging error ---
Traceback (most recent call last):
  File "C:\Program Files\Python311\Lib\logging\__init__.py", line 1113, in emit
    stream.write(msg + self.terminator)
  File "C:\Program Files\Python311\Lib\encodings\cp1251.py", line 19, in encode
    return codecs.charmap_encode(input,self.errors,encoding_table)[0]
           ^^^^^^^^^^^^^^^^^^^^^^^^^^^^^^^^^^^^^^^^^^^^^^^^^^^^^^^
UnicodeEncodeError: 'charmap' codec can't encode character '\u2705' in position 51: character maps to <undefined>
Call stack:
  File "C:\Users\gabbi\OneDrive\Desktop\kovcheg\tests\integration\ark_system_integration_test.py", line 849, in <module>
    asyncio.run(main())
  File "C:\Program Files\Python311\Lib\asyncio\runners.py", line 190, in run
    return runner.run(main)
  File "C:\Program Files\Python311\Lib\asyncio\runners.py", line 118, in run
    return self._loop.run_until_complete(task)
  File "C:\Program Files\Python311\Lib\asyncio\base_events.py", line 640, in run_until_complete
    self.run_forever()
  File "C:\Program Files\Python311\Lib\asyncio\windows_events.py", line 321, in run_forever
    super().run_forever()
  File "C:\Program Files\Python311\Lib\asyncio\base_events.py", line 607, in run_forever
    self._run_once()
  File "C:\Program Files\Python311\Lib\asyncio\base_events.py", line 1922, in _run_once
    handle._run()
  File "C:\Program Files\Python311\Lib\asyncio\events.py", line 80, in _run
    self._context.run(self._callback, *self._args)
  File "C:\Users\gabbi\OneDrive\Desktop\kovcheg\tests\integration\ark_system_integration_test.py", line 847, in main
    await tester.run_full_integration_test_suite()
  File "C:\Users\gabbi\OneDrive\Desktop\kovcheg\tests\integration\ark_system_integration_test.py", line 711, in run_full_integration_test_suite
    await test_method()
  File "C:\Users\gabbi\OneDrive\Desktop\kovcheg\tests\integration\ark_system_integration_test.py", line 380, in test_cold_mirror_performance
    self._record_test_result(
  File "C:\Users\gabbi\OneDrive\Desktop\kovcheg\tests\integration\ark_system_integration_test.py", line 145, in _record_test_result
    self.logger.info(f"{status} {compliance} - {test_name}")
Message: '\u2705 PASS \U0001f54a\ufe0f COMPLIANT - Cold-Mirror Harm Prediction Performance'
Arguments: ()
2025-06-11 23:15:48,485 - ARK_INTEGRATION - INFO - \u2705 PASS \U0001f54a\ufe0f COMPLIANT - Cold-Mirror Harm Prediction Performance
2025-06-11 23:15:48,489 - ARK_INTEGRATION - INFO -     SRS-REQ: SW-02
2025-06-11 23:15:48,489 - ARK_INTEGRATION - INFO -     Measured: 2.332300, Threshold: 50.000000
--- Logging error ---
Traceback (most recent call last):
  File "C:\Program Files\Python311\Lib\logging\__init__.py", line 1113, in emit
    stream.write(msg + self.terminator)
  File "C:\Program Files\Python311\Lib\encodings\cp1251.py", line 19, in encode
    return codecs.charmap_encode(input,self.errors,encoding_table)[0]
           ^^^^^^^^^^^^^^^^^^^^^^^^^^^^^^^^^^^^^^^^^^^^^^^^^^^^^^^
UnicodeEncodeError: 'charmap' codec can't encode character '\U0001f504' in position 51: character maps to <undefined>
Call stack:
  File "C:\Users\gabbi\OneDrive\Desktop\kovcheg\tests\integration\ark_system_integration_test.py", line 849, in <module>
    asyncio.run(main())
  File "C:\Program Files\Python311\Lib\asyncio\runners.py", line 190, in run
    return runner.run(main)
  File "C:\Program Files\Python311\Lib\asyncio\runners.py", line 118, in run
    return self._loop.run_until_complete(task)
  File "C:\Program Files\Python311\Lib\asyncio\base_events.py", line 640, in run_until_complete
    self.run_forever()
  File "C:\Program Files\Python311\Lib\asyncio\windows_events.py", line 321, in run_forever
    super().run_forever()
  File "C:\Program Files\Python311\Lib\asyncio\base_events.py", line 607, in run_forever
    self._run_once()
  File "C:\Program Files\Python311\Lib\asyncio\base_events.py", line 1922, in _run_once
    handle._run()
  File "C:\Program Files\Python311\Lib\asyncio\events.py", line 80, in _run
    self._context.run(self._callback, *self._args)
  File "C:\Users\gabbi\OneDrive\Desktop\kovcheg\tests\integration\ark_system_integration_test.py", line 847, in main
    await tester.run_full_integration_test_suite()
  File "C:\Users\gabbi\OneDrive\Desktop\kovcheg\tests\integration\ark_system_integration_test.py", line 711, in run_full_integration_test_suite
    await test_method()
  File "C:\Users\gabbi\OneDrive\Desktop\kovcheg\tests\integration\ark_system_integration_test.py", line 416, in test_patch_orchestrator_rollback
    self.logger.info("\U0001f504 Testing patch orchestrator rollback (SW-04)")
Message: '\U0001f504 Testing patch orchestrator rollback (SW-04)'
Arguments: ()
2025-06-11 23:15:48,489 - ARK_INTEGRATION - INFO - \U0001f504 Testing patch orchestrator rollback (SW-04)
--- Logging error ---
Traceback (most recent call last):
  File "C:\Program Files\Python311\Lib\logging\__init__.py", line 1113, in emit
    stream.write(msg + self.terminator)
  File "C:\Program Files\Python311\Lib\encodings\cp1251.py", line 19, in encode
    return codecs.charmap_encode(input,self.errors,encoding_table)[0]
           ^^^^^^^^^^^^^^^^^^^^^^^^^^^^^^^^^^^^^^^^^^^^^^^^^^^^^^^
UnicodeEncodeError: 'charmap' codec can't encode character '\u2705' in position 51: character maps to <undefined>
Call stack:
  File "C:\Users\gabbi\OneDrive\Desktop\kovcheg\tests\integration\ark_system_integration_test.py", line 849, in <module>
    asyncio.run(main())
  File "C:\Program Files\Python311\Lib\asyncio\runners.py", line 190, in run
    return runner.run(main)
  File "C:\Program Files\Python311\Lib\asyncio\runners.py", line 118, in run
    return self._loop.run_until_complete(task)
  File "C:\Program Files\Python311\Lib\asyncio\base_events.py", line 640, in run_until_complete
    self.run_forever()
  File "C:\Program Files\Python311\Lib\asyncio\windows_events.py", line 321, in run_forever
    super().run_forever()
  File "C:\Program Files\Python311\Lib\asyncio\base_events.py", line 607, in run_forever
    self._run_once()
  File "C:\Program Files\Python311\Lib\asyncio\base_events.py", line 1922, in _run_once
    handle._run()
  File "C:\Program Files\Python311\Lib\asyncio\events.py", line 80, in _run
    self._context.run(self._callback, *self._args)
  File "C:\Users\gabbi\OneDrive\Desktop\kovcheg\tests\integration\ark_system_integration_test.py", line 847, in main
    await tester.run_full_integration_test_suite()
  File "C:\Users\gabbi\OneDrive\Desktop\kovcheg\tests\integration\ark_system_integration_test.py", line 711, in run_full_integration_test_suite
    await test_method()
  File "C:\Users\gabbi\OneDrive\Desktop\kovcheg\tests\integration\ark_system_integration_test.py", line 450, in test_patch_orchestrator_rollback
    self._record_test_result(
  File "C:\Users\gabbi\OneDrive\Desktop\kovcheg\tests\integration\ark_system_integration_test.py", line 145, in _record_test_result
    self.logger.info(f"{status} {compliance} - {test_name}")
Message: '\u2705 PASS \U0001f54a\ufe0f COMPLIANT - Patch Orchestrator Rollback Performance'
Arguments: ()
2025-06-11 23:15:48,531 - ARK_INTEGRATION - INFO - \u2705 PASS \U0001f54a\ufe0f COMPLIANT - Patch Orchestrator Rollback Performance
2025-06-11 23:15:48,534 - ARK_INTEGRATION - INFO -     SRS-REQ: SW-04
2025-06-11 23:15:48,534 - ARK_INTEGRATION - INFO -     Measured: 16.765900, Threshold: 200.000000
--- Logging error ---
Traceback (most recent call last):
  File "C:\Program Files\Python311\Lib\logging\__init__.py", line 1113, in emit
    stream.write(msg + self.terminator)
  File "C:\Program Files\Python311\Lib\encodings\cp1251.py", line 19, in encode
    return codecs.charmap_encode(input,self.errors,encoding_table)[0]
           ^^^^^^^^^^^^^^^^^^^^^^^^^^^^^^^^^^^^^^^^^^^^^^^^^^^^^^^
UnicodeEncodeError: 'charmap' codec can't encode character '\U0001f512' in position 51: character maps to <undefined>
Call stack:
  File "C:\Users\gabbi\OneDrive\Desktop\kovcheg\tests\integration\ark_system_integration_test.py", line 849, in <module>
    asyncio.run(main())
  File "C:\Program Files\Python311\Lib\asyncio\runners.py", line 190, in run
    return runner.run(main)
  File "C:\Program Files\Python311\Lib\asyncio\runners.py", line 118, in run
    return self._loop.run_until_complete(task)
  File "C:\Program Files\Python311\Lib\asyncio\base_events.py", line 640, in run_until_complete
    self.run_forever()
  File "C:\Program Files\Python311\Lib\asyncio\windows_events.py", line 321, in run_forever
    super().run_forever()
  File "C:\Program Files\Python311\Lib\asyncio\base_events.py", line 607, in run_forever
    self._run_once()
  File "C:\Program Files\Python311\Lib\asyncio\base_events.py", line 1922, in _run_once
    handle._run()
  File "C:\Program Files\Python311\Lib\asyncio\events.py", line 80, in _run
    self._context.run(self._callback, *self._args)
  File "C:\Users\gabbi\OneDrive\Desktop\kovcheg\tests\integration\ark_system_integration_test.py", line 847, in main
    await tester.run_full_integration_test_suite()
  File "C:\Users\gabbi\OneDrive\Desktop\kovcheg\tests\integration\ark_system_integration_test.py", line 711, in run_full_integration_test_suite
    await test_method()
  File "C:\Users\gabbi\OneDrive\Desktop\kovcheg\tests\integration\ark_system_integration_test.py", line 474, in test_side_channel_resistance
    self.logger.info("\U0001f512 Testing side-channel resistance (SEC-02)")
Message: '\U0001f512 Testing side-channel resistance (SEC-02)'
Arguments: ()
2025-06-11 23:15:48,535 - ARK_INTEGRATION - INFO - \U0001f512 Testing side-channel resistance (SEC-02)
--- Logging error ---
Traceback (most recent call last):
  File "C:\Program Files\Python311\Lib\logging\__init__.py", line 1113, in emit
    stream.write(msg + self.terminator)
  File "C:\Program Files\Python311\Lib\encodings\cp1251.py", line 19, in encode
    return codecs.charmap_encode(input,self.errors,encoding_table)[0]
           ^^^^^^^^^^^^^^^^^^^^^^^^^^^^^^^^^^^^^^^^^^^^^^^^^^^^^^^
UnicodeEncodeError: 'charmap' codec can't encode characters in position 54-55: character maps to <undefined>
Call stack:
  File "C:\Users\gabbi\OneDrive\Desktop\kovcheg\tests\integration\ark_system_integration_test.py", line 849, in <module>
    asyncio.run(main())
  File "C:\Program Files\Python311\Lib\asyncio\runners.py", line 190, in run
    return runner.run(main)
  File "C:\Program Files\Python311\Lib\asyncio\runners.py", line 118, in run
    return self._loop.run_until_complete(task)
  File "C:\Program Files\Python311\Lib\asyncio\base_events.py", line 640, in run_until_complete
    self.run_forever()
  File "C:\Program Files\Python311\Lib\asyncio\windows_events.py", line 321, in run_forever
    super().run_forever()
  File "C:\Program Files\Python311\Lib\asyncio\base_events.py", line 607, in run_forever
    self._run_once()
  File "C:\Program Files\Python311\Lib\asyncio\base_events.py", line 1922, in _run_once
    handle._run()
  File "C:\Program Files\Python311\Lib\asyncio\events.py", line 80, in _run
    self._context.run(self._callback, *self._args)
  File "C:\Users\gabbi\OneDrive\Desktop\kovcheg\tests\integration\ark_system_integration_test.py", line 847, in main
    await tester.run_full_integration_test_suite()
  File "C:\Users\gabbi\OneDrive\Desktop\kovcheg\tests\integration\ark_system_integration_test.py", line 711, in run_full_integration_test_suite
    await test_method()
  File "C:\Users\gabbi\OneDrive\Desktop\kovcheg\tests\integration\ark_system_integration_test.py", line 483, in test_side_channel_resistance
    analyzer = BiblicalSideChannelAnalyzer(config)
  File "C:\Users\gabbi\OneDrive\Desktop\kovcheg\security_tests\side_channel\side_channel_analysis.py", line 73, in __init__
    self._verify_biblical_foundation()
  File "C:\Users\gabbi\OneDrive\Desktop\kovcheg\security_tests\side_channel\side_channel_analysis.py", line 96, in _verify_biblical_foundation
    self.logger.warning("\u26a0\ufe0f Biblical foundation verification failed - using default protection")
Message: '\u26a0\ufe0f Biblical foundation verification failed - using default protection'
Arguments: ()
2025-06-11 23:15:48,538 - ARK_INTEGRATION - WARNING - \u26a0\ufe0f Biblical foundation verification failed - using default protection
--- Logging error ---
Traceback (most recent call last):
  File "C:\Program Files\Python311\Lib\logging\__init__.py", line 1113, in emit
    stream.write(msg + self.terminator)
  File "C:\Program Files\Python311\Lib\encodings\cp1251.py", line 19, in encode
    return codecs.charmap_encode(input,self.errors,encoding_table)[0]
           ^^^^^^^^^^^^^^^^^^^^^^^^^^^^^^^^^^^^^^^^^^^^^^^^^^^^^^^
UnicodeEncodeError: 'charmap' codec can't encode characters in position 51-52: character maps to <undefined>
Call stack:
  File "C:\Users\gabbi\OneDrive\Desktop\kovcheg\tests\integration\ark_system_integration_test.py", line 849, in <module>
    asyncio.run(main())
  File "C:\Program Files\Python311\Lib\asyncio\runners.py", line 190, in run
    return runner.run(main)
  File "C:\Program Files\Python311\Lib\asyncio\runners.py", line 118, in run
    return self._loop.run_until_complete(task)
  File "C:\Program Files\Python311\Lib\asyncio\base_events.py", line 640, in run_until_complete
    self.run_forever()
  File "C:\Program Files\Python311\Lib\asyncio\windows_events.py", line 321, in run_forever
    super().run_forever()
  File "C:\Program Files\Python311\Lib\asyncio\base_events.py", line 607, in run_forever
    self._run_once()
  File "C:\Program Files\Python311\Lib\asyncio\base_events.py", line 1922, in _run_once
    handle._run()
  File "C:\Program Files\Python311\Lib\asyncio\events.py", line 80, in _run
    self._context.run(self._callback, *self._args)
  File "C:\Users\gabbi\OneDrive\Desktop\kovcheg\tests\integration\ark_system_integration_test.py", line 847, in main
    await tester.run_full_integration_test_suite()
  File "C:\Users\gabbi\OneDrive\Desktop\kovcheg\tests\integration\ark_system_integration_test.py", line 711, in run_full_integration_test_suite
    await test_method()
  File "C:\Users\gabbi\OneDrive\Desktop\kovcheg\tests\integration\ark_system_integration_test.py", line 483, in test_side_channel_resistance
    analyzer = BiblicalSideChannelAnalyzer(config)
  File "C:\Users\gabbi\OneDrive\Desktop\kovcheg\security_tests\side_channel\side_channel_analysis.py", line 75, in __init__
    self.logger.info("\U0001f6e1\ufe0f ARK Side-Channel Analyzer initialized with Biblical protection")
Message: '\U0001f6e1\ufe0f ARK Side-Channel Analyzer initialized with Biblical protection'
Arguments: ()
2025-06-11 23:15:48,541 - ARK_INTEGRATION - INFO - \U0001f6e1\ufe0f ARK Side-Channel Analyzer initialized with Biblical protection
--- Logging error ---
Traceback (most recent call last):
  File "C:\Program Files\Python311\Lib\logging\__init__.py", line 1113, in emit
    stream.write(msg + self.terminator)
  File "C:\Program Files\Python311\Lib\encodings\cp1251.py", line 19, in encode
    return codecs.charmap_encode(input,self.errors,encoding_table)[0]
           ^^^^^^^^^^^^^^^^^^^^^^^^^^^^^^^^^^^^^^^^^^^^^^^^^^^^^^^
UnicodeEncodeError: 'charmap' codec can't encode character '\U0001f4dc' in position 51: character maps to <undefined>
Call stack:
  File "C:\Users\gabbi\OneDrive\Desktop\kovcheg\tests\integration\ark_system_integration_test.py", line 849, in <module>
    asyncio.run(main())
  File "C:\Program Files\Python311\Lib\asyncio\runners.py", line 190, in run
    return runner.run(main)
  File "C:\Program Files\Python311\Lib\asyncio\runners.py", line 118, in run
    return self._loop.run_until_complete(task)
  File "C:\Program Files\Python311\Lib\asyncio\base_events.py", line 640, in run_until_complete
    self.run_forever()
  File "C:\Program Files\Python311\Lib\asyncio\windows_events.py", line 321, in run_forever
    super().run_forever()
  File "C:\Program Files\Python311\Lib\asyncio\base_events.py", line 607, in run_forever
    self._run_once()
  File "C:\Program Files\Python311\Lib\asyncio\base_events.py", line 1922, in _run_once
    handle._run()
  File "C:\Program Files\Python311\Lib\asyncio\events.py", line 80, in _run
    self._context.run(self._callback, *self._args)
  File "C:\Users\gabbi\OneDrive\Desktop\kovcheg\tests\integration\ark_system_integration_test.py", line 847, in main
    await tester.run_full_integration_test_suite()
  File "C:\Users\gabbi\OneDrive\Desktop\kovcheg\tests\integration\ark_system_integration_test.py", line 711, in run_full_integration_test_suite
    await test_method()
  File "C:\Users\gabbi\OneDrive\Desktop\kovcheg\tests\integration\ark_system_integration_test.py", line 483, in test_side_channel_resistance
    analyzer = BiblicalSideChannelAnalyzer(config)
  File "C:\Users\gabbi\OneDrive\Desktop\kovcheg\security_tests\side_channel\side_channel_analysis.py", line 76, in __init__
    self.logger.info(f"\U0001f4dc Foundation: {BIBLICAL_FOUNDATION}")
Message: '\U0001f4dc Foundation: Matthew_10_16_Be_wise_as_serpents_and_innocent_as_doves'
Arguments: ()
2025-06-11 23:15:48,543 - ARK_INTEGRATION - INFO - \U0001f4dc Foundation: Matthew_10_16_Be_wise_as_serpents_and_innocent_as_doves
--- Logging error ---
Traceback (most recent call last):
  File "C:\Program Files\Python311\Lib\logging\__init__.py", line 1113, in emit
    stream.write(msg + self.terminator)
  File "C:\Program Files\Python311\Lib\encodings\cp1251.py", line 19, in encode
    return codecs.charmap_encode(input,self.errors,encoding_table)[0]
           ^^^^^^^^^^^^^^^^^^^^^^^^^^^^^^^^^^^^^^^^^^^^^^^^^^^^^^^
UnicodeEncodeError: 'charmap' codec can't encode character '\U0001f50b' in position 51: character maps to <undefined>
Call stack:
  File "C:\Users\gabbi\OneDrive\Desktop\kovcheg\tests\integration\ark_system_integration_test.py", line 849, in <module>
    asyncio.run(main())
  File "C:\Program Files\Python311\Lib\asyncio\runners.py", line 190, in run
    return runner.run(main)
  File "C:\Program Files\Python311\Lib\asyncio\runners.py", line 118, in run
    return self._loop.run_until_complete(task)
  File "C:\Program Files\Python311\Lib\asyncio\base_events.py", line 640, in run_until_complete
    self.run_forever()
  File "C:\Program Files\Python311\Lib\asyncio\windows_events.py", line 321, in run_forever
    super().run_forever()
  File "C:\Program Files\Python311\Lib\asyncio\base_events.py", line 607, in run_forever
    self._run_once()
  File "C:\Program Files\Python311\Lib\asyncio\base_events.py", line 1922, in _run_once
    handle._run()
  File "C:\Program Files\Python311\Lib\asyncio\events.py", line 80, in _run
    self._context.run(self._callback, *self._args)
  File "C:\Users\gabbi\OneDrive\Desktop\kovcheg\tests\integration\ark_system_integration_test.py", line 847, in main
    await tester.run_full_integration_test_suite()
  File "C:\Users\gabbi\OneDrive\Desktop\kovcheg\tests\integration\ark_system_integration_test.py", line 711, in run_full_integration_test_suite
    await test_method()
  File "C:\Users\gabbi\OneDrive\Desktop\kovcheg\tests\integration\ark_system_integration_test.py", line 490, in test_side_channel_resistance
    power_result = analyzer.analyze_power_consumption(
  File "C:\Users\gabbi\OneDrive\Desktop\kovcheg\security_tests\side_channel\side_channel_analysis.py", line 113, in analyze_power_consumption
    self.logger.info("\U0001f50b Starting power consumption analysis")
Message: '\U0001f50b Starting power consumption analysis'
Arguments: ()
2025-06-11 23:15:48,547 - ARK_INTEGRATION - INFO - \U0001f50b Starting power consumption analysis
--- Logging error ---
Traceback (most recent call last):
  File "C:\Program Files\Python311\Lib\logging\__init__.py", line 1113, in emit
    stream.write(msg + self.terminator)
  File "C:\Program Files\Python311\Lib\encodings\cp1251.py", line 19, in encode
    return codecs.charmap_encode(input,self.errors,encoding_table)[0]
           ^^^^^^^^^^^^^^^^^^^^^^^^^^^^^^^^^^^^^^^^^^^^^^^^^^^^^^^
UnicodeEncodeError: 'charmap' codec can't encode character '\u2705' in position 51: character maps to <undefined>
Call stack:
  File "C:\Users\gabbi\OneDrive\Desktop\kovcheg\tests\integration\ark_system_integration_test.py", line 849, in <module>
    asyncio.run(main())
  File "C:\Program Files\Python311\Lib\asyncio\runners.py", line 190, in run
    return runner.run(main)
  File "C:\Program Files\Python311\Lib\asyncio\runners.py", line 118, in run
    return self._loop.run_until_complete(task)
  File "C:\Program Files\Python311\Lib\asyncio\base_events.py", line 640, in run_until_complete
    self.run_forever()
  File "C:\Program Files\Python311\Lib\asyncio\windows_events.py", line 321, in run_forever
    super().run_forever()
  File "C:\Program Files\Python311\Lib\asyncio\base_events.py", line 607, in run_forever
    self._run_once()
  File "C:\Program Files\Python311\Lib\asyncio\base_events.py", line 1922, in _run_once
    handle._run()
  File "C:\Program Files\Python311\Lib\asyncio\events.py", line 80, in _run
    self._context.run(self._callback, *self._args)
  File "C:\Users\gabbi\OneDrive\Desktop\kovcheg\tests\integration\ark_system_integration_test.py", line 847, in main
    await tester.run_full_integration_test_suite()
  File "C:\Users\gabbi\OneDrive\Desktop\kovcheg\tests\integration\ark_system_integration_test.py", line 711, in run_full_integration_test_suite
    await test_method()
  File "C:\Users\gabbi\OneDrive\Desktop\kovcheg\tests\integration\ark_system_integration_test.py", line 490, in test_side_channel_resistance
    power_result = analyzer.analyze_power_consumption(
  File "C:\Users\gabbi\OneDrive\Desktop\kovcheg\security_tests\side_channel\side_channel_analysis.py", line 168, in analyze_power_consumption
    self.logger.info(f"\u2705 Power analysis complete - SNR: {snr:.4f}, Protection: {protection_level}")
Message: '\u2705 Power analysis complete - SNR: 0.0863, Protection: Excellent'
Arguments: ()
2025-06-11 23:15:48,554 - ARK_INTEGRATION - INFO - \u2705 Power analysis complete - SNR: 0.0863, Protection: Excellent
--- Logging error ---
Traceback (most recent call last):
  File "C:\Program Files\Python311\Lib\logging\__init__.py", line 1113, in emit
    stream.write(msg + self.terminator)
  File "C:\Program Files\Python311\Lib\encodings\cp1251.py", line 19, in encode
    return codecs.charmap_encode(input,self.errors,encoding_table)[0]
           ^^^^^^^^^^^^^^^^^^^^^^^^^^^^^^^^^^^^^^^^^^^^^^^^^^^^^^^
UnicodeEncodeError: 'charmap' codec can't encode character '\U0001f4e1' in position 51: character maps to <undefined>
Call stack:
  File "C:\Users\gabbi\OneDrive\Desktop\kovcheg\tests\integration\ark_system_integration_test.py", line 849, in <module>
    asyncio.run(main())
  File "C:\Program Files\Python311\Lib\asyncio\runners.py", line 190, in run
    return runner.run(main)
  File "C:\Program Files\Python311\Lib\asyncio\runners.py", line 118, in run
    return self._loop.run_until_complete(task)
  File "C:\Program Files\Python311\Lib\asyncio\base_events.py", line 640, in run_until_complete
    self.run_forever()
  File "C:\Program Files\Python311\Lib\asyncio\windows_events.py", line 321, in run_forever
    super().run_forever()
  File "C:\Program Files\Python311\Lib\asyncio\base_events.py", line 607, in run_forever
    self._run_once()
  File "C:\Program Files\Python311\Lib\asyncio\base_events.py", line 1922, in _run_once
    handle._run()
  File "C:\Program Files\Python311\Lib\asyncio\events.py", line 80, in _run
    self._context.run(self._callback, *self._args)
  File "C:\Users\gabbi\OneDrive\Desktop\kovcheg\tests\integration\ark_system_integration_test.py", line 847, in main
    await tester.run_full_integration_test_suite()
  File "C:\Users\gabbi\OneDrive\Desktop\kovcheg\tests\integration\ark_system_integration_test.py", line 711, in run_full_integration_test_suite
    await test_method()
  File "C:\Users\gabbi\OneDrive\Desktop\kovcheg\tests\integration\ark_system_integration_test.py", line 496, in test_side_channel_resistance
    em_result = analyzer.analyze_electromagnetic_emissions(
  File "C:\Users\gabbi\OneDrive\Desktop\kovcheg\security_tests\side_channel\side_channel_analysis.py", line 333, in analyze_electromagnetic_emissions
    self.logger.info("\U0001f4e1 Starting electromagnetic emission analysis")
Message: '\U0001f4e1 Starting electromagnetic emission analysis'
Arguments: ()
2025-06-11 23:15:48,558 - ARK_INTEGRATION - INFO - \U0001f4e1 Starting electromagnetic emission analysis
--- Logging error ---
Traceback (most recent call last):
  File "C:\Program Files\Python311\Lib\logging\__init__.py", line 1113, in emit
    stream.write(msg + self.terminator)
  File "C:\Program Files\Python311\Lib\encodings\cp1251.py", line 19, in encode
    return codecs.charmap_encode(input,self.errors,encoding_table)[0]
           ^^^^^^^^^^^^^^^^^^^^^^^^^^^^^^^^^^^^^^^^^^^^^^^^^^^^^^^
UnicodeEncodeError: 'charmap' codec can't encode character '\u2705' in position 51: character maps to <undefined>
Call stack:
  File "C:\Users\gabbi\OneDrive\Desktop\kovcheg\tests\integration\ark_system_integration_test.py", line 849, in <module>
    asyncio.run(main())
  File "C:\Program Files\Python311\Lib\asyncio\runners.py", line 190, in run
    return runner.run(main)
  File "C:\Program Files\Python311\Lib\asyncio\runners.py", line 118, in run
    return self._loop.run_until_complete(task)
  File "C:\Program Files\Python311\Lib\asyncio\base_events.py", line 640, in run_until_complete
    self.run_forever()
  File "C:\Program Files\Python311\Lib\asyncio\windows_events.py", line 321, in run_forever
    super().run_forever()
  File "C:\Program Files\Python311\Lib\asyncio\base_events.py", line 607, in run_forever
    self._run_once()
  File "C:\Program Files\Python311\Lib\asyncio\base_events.py", line 1922, in _run_once
    handle._run()
  File "C:\Program Files\Python311\Lib\asyncio\events.py", line 80, in _run
    self._context.run(self._callback, *self._args)
  File "C:\Users\gabbi\OneDrive\Desktop\kovcheg\tests\integration\ark_system_integration_test.py", line 847, in main
    await tester.run_full_integration_test_suite()
  File "C:\Users\gabbi\OneDrive\Desktop\kovcheg\tests\integration\ark_system_integration_test.py", line 711, in run_full_integration_test_suite
    await test_method()
  File "C:\Users\gabbi\OneDrive\Desktop\kovcheg\tests\integration\ark_system_integration_test.py", line 496, in test_side_channel_resistance
    em_result = analyzer.analyze_electromagnetic_emissions(
  File "C:\Users\gabbi\OneDrive\Desktop\kovcheg\security_tests\side_channel\side_channel_analysis.py", line 390, in analyze_electromagnetic_emissions
    self.logger.info(f"\u2705 EM analysis complete - Peak: {peak_power:.2f} dBm, SNR: {peak_power:.2f} dB")
Message: '\u2705 EM analysis complete - Peak: -69.89 dBm, SNR: -69.89 dB'
Arguments: ()
2025-06-11 23:16:05,921 - ARK_INTEGRATION - INFO - \u2705 EM analysis complete - Peak: -69.89 dBm, SNR: -69.89 dB
--- Logging error ---
Traceback (most recent call last):
  File "C:\Program Files\Python311\Lib\logging\__init__.py", line 1113, in emit
    stream.write(msg + self.terminator)
  File "C:\Program Files\Python311\Lib\encodings\cp1251.py", line 19, in encode
    return codecs.charmap_encode(input,self.errors,encoding_table)[0]
           ^^^^^^^^^^^^^^^^^^^^^^^^^^^^^^^^^^^^^^^^^^^^^^^^^^^^^^^
UnicodeEncodeError: 'charmap' codec can't encode character '\U0001f50d' in position 51: character maps to <undefined>
Call stack:
  File "C:\Users\gabbi\OneDrive\Desktop\kovcheg\tests\integration\ark_system_integration_test.py", line 849, in <module>
    asyncio.run(main())
  File "C:\Program Files\Python311\Lib\asyncio\runners.py", line 190, in run
    return runner.run(main)
  File "C:\Program Files\Python311\Lib\asyncio\runners.py", line 118, in run
    return self._loop.run_until_complete(task)
  File "C:\Program Files\Python311\Lib\asyncio\base_events.py", line 640, in run_until_complete
    self.run_forever()
  File "C:\Program Files\Python311\Lib\asyncio\windows_events.py", line 321, in run_forever
    super().run_forever()
  File "C:\Program Files\Python311\Lib\asyncio\base_events.py", line 607, in run_forever
    self._run_once()
  File "C:\Program Files\Python311\Lib\asyncio\base_events.py", line 1922, in _run_once
    handle._run()
  File "C:\Program Files\Python311\Lib\asyncio\events.py", line 80, in _run
    self._context.run(self._callback, *self._args)
  File "C:\Users\gabbi\OneDrive\Desktop\kovcheg\tests\integration\ark_system_integration_test.py", line 847, in main
    await tester.run_full_integration_test_suite()
  File "C:\Users\gabbi\OneDrive\Desktop\kovcheg\tests\integration\ark_system_integration_test.py", line 711, in run_full_integration_test_suite
    await test_method()
  File "C:\Users\gabbi\OneDrive\Desktop\kovcheg\tests\integration\ark_system_integration_test.py", line 506, in test_side_channel_resistance
    self.logger.info(f"\U0001f50d Power SNR: {power_result.snr_measured:.6f}, Biblical: {power_result.biblical_compliance}")
Message: '\U0001f50d Power SNR: 0.086278, Biblical: True'
Arguments: ()
2025-06-11 23:16:05,924 - ARK_INTEGRATION - INFO - \U0001f50d Power SNR: 0.086278, Biblical: True
--- Logging error ---
Traceback (most recent call last):
  File "C:\Program Files\Python311\Lib\logging\__init__.py", line 1113, in emit
    stream.write(msg + self.terminator)
  File "C:\Program Files\Python311\Lib\encodings\cp1251.py", line 19, in encode
    return codecs.charmap_encode(input,self.errors,encoding_table)[0]
           ^^^^^^^^^^^^^^^^^^^^^^^^^^^^^^^^^^^^^^^^^^^^^^^^^^^^^^^
UnicodeEncodeError: 'charmap' codec can't encode character '\U0001f50d' in position 51: character maps to <undefined>
Call stack:
  File "C:\Users\gabbi\OneDrive\Desktop\kovcheg\tests\integration\ark_system_integration_test.py", line 849, in <module>
    asyncio.run(main())
  File "C:\Program Files\Python311\Lib\asyncio\runners.py", line 190, in run
    return runner.run(main)
  File "C:\Program Files\Python311\Lib\asyncio\runners.py", line 118, in run
    return self._loop.run_until_complete(task)
  File "C:\Program Files\Python311\Lib\asyncio\base_events.py", line 640, in run_until_complete
    self.run_forever()
  File "C:\Program Files\Python311\Lib\asyncio\windows_events.py", line 321, in run_forever
    super().run_forever()
  File "C:\Program Files\Python311\Lib\asyncio\base_events.py", line 607, in run_forever
    self._run_once()
  File "C:\Program Files\Python311\Lib\asyncio\base_events.py", line 1922, in _run_once
    handle._run()
  File "C:\Program Files\Python311\Lib\asyncio\events.py", line 80, in _run
    self._context.run(self._callback, *self._args)
  File "C:\Users\gabbi\OneDrive\Desktop\kovcheg\tests\integration\ark_system_integration_test.py", line 847, in main
    await tester.run_full_integration_test_suite()
  File "C:\Users\gabbi\OneDrive\Desktop\kovcheg\tests\integration\ark_system_integration_test.py", line 711, in run_full_integration_test_suite
    await test_method()
  File "C:\Users\gabbi\OneDrive\Desktop\kovcheg\tests\integration\ark_system_integration_test.py", line 507, in test_side_channel_resistance
    self.logger.info(f"\U0001f50d EM SNR: {em_result.snr_measured:.6f}, Biblical: {em_result.biblical_compliance}")
Message: '\U0001f50d EM SNR: -69.891012, Biblical: True'
Arguments: ()
2025-06-11 23:16:05,927 - ARK_INTEGRATION - INFO - \U0001f50d EM SNR: -69.891012, Biblical: True
--- Logging error ---
Traceback (most recent call last):
  File "C:\Program Files\Python311\Lib\logging\__init__.py", line 1113, in emit
    stream.write(msg + self.terminator)
  File "C:\Program Files\Python311\Lib\encodings\cp1251.py", line 19, in encode
    return codecs.charmap_encode(input,self.errors,encoding_table)[0]
           ^^^^^^^^^^^^^^^^^^^^^^^^^^^^^^^^^^^^^^^^^^^^^^^^^^^^^^^
UnicodeEncodeError: 'charmap' codec can't encode character '\U0001f50d' in position 51: character maps to <undefined>
Call stack:
  File "C:\Users\gabbi\OneDrive\Desktop\kovcheg\tests\integration\ark_system_integration_test.py", line 849, in <module>
    asyncio.run(main())
  File "C:\Program Files\Python311\Lib\asyncio\runners.py", line 190, in run
    return runner.run(main)
  File "C:\Program Files\Python311\Lib\asyncio\runners.py", line 118, in run
    return self._loop.run_until_complete(task)
  File "C:\Program Files\Python311\Lib\asyncio\base_events.py", line 640, in run_until_complete
    self.run_forever()
  File "C:\Program Files\Python311\Lib\asyncio\windows_events.py", line 321, in run_forever
    super().run_forever()
  File "C:\Program Files\Python311\Lib\asyncio\base_events.py", line 607, in run_forever
    self._run_once()
  File "C:\Program Files\Python311\Lib\asyncio\base_events.py", line 1922, in _run_once
    handle._run()
  File "C:\Program Files\Python311\Lib\asyncio\events.py", line 80, in _run
    self._context.run(self._callback, *self._args)
  File "C:\Users\gabbi\OneDrive\Desktop\kovcheg\tests\integration\ark_system_integration_test.py", line 847, in main
    await tester.run_full_integration_test_suite()
  File "C:\Users\gabbi\OneDrive\Desktop\kovcheg\tests\integration\ark_system_integration_test.py", line 711, in run_full_integration_test_suite
    await test_method()
  File "C:\Users\gabbi\OneDrive\Desktop\kovcheg\tests\integration\ark_system_integration_test.py", line 508, in test_side_channel_resistance
    self.logger.info(f"\U0001f50d Max SNR: {max_snr:.6f}")
Message: '\U0001f50d Max SNR: 0.086278'
Arguments: ()
2025-06-11 23:16:05,929 - ARK_INTEGRATION - INFO - \U0001f50d Max SNR: 0.086278
--- Logging error ---
Traceback (most recent call last):
  File "C:\Program Files\Python311\Lib\logging\__init__.py", line 1113, in emit
    stream.write(msg + self.terminator)
  File "C:\Program Files\Python311\Lib\encodings\cp1251.py", line 19, in encode
    return codecs.charmap_encode(input,self.errors,encoding_table)[0]
           ^^^^^^^^^^^^^^^^^^^^^^^^^^^^^^^^^^^^^^^^^^^^^^^^^^^^^^^
UnicodeEncodeError: 'charmap' codec can't encode character '\u2705' in position 51: character maps to <undefined>
Call stack:
  File "C:\Users\gabbi\OneDrive\Desktop\kovcheg\tests\integration\ark_system_integration_test.py", line 849, in <module>
    asyncio.run(main())
  File "C:\Program Files\Python311\Lib\asyncio\runners.py", line 190, in run
    return runner.run(main)
  File "C:\Program Files\Python311\Lib\asyncio\runners.py", line 118, in run
    return self._loop.run_until_complete(task)
  File "C:\Program Files\Python311\Lib\asyncio\base_events.py", line 640, in run_until_complete
    self.run_forever()
  File "C:\Program Files\Python311\Lib\asyncio\windows_events.py", line 321, in run_forever
    super().run_forever()
  File "C:\Program Files\Python311\Lib\asyncio\base_events.py", line 607, in run_forever
    self._run_once()
  File "C:\Program Files\Python311\Lib\asyncio\base_events.py", line 1922, in _run_once
    handle._run()
  File "C:\Program Files\Python311\Lib\asyncio\events.py", line 80, in _run
    self._context.run(self._callback, *self._args)
  File "C:\Users\gabbi\OneDrive\Desktop\kovcheg\tests\integration\ark_system_integration_test.py", line 847, in main
    await tester.run_full_integration_test_suite()
  File "C:\Users\gabbi\OneDrive\Desktop\kovcheg\tests\integration\ark_system_integration_test.py", line 711, in run_full_integration_test_suite
    await test_method()
  File "C:\Users\gabbi\OneDrive\Desktop\kovcheg\tests\integration\ark_system_integration_test.py", line 514, in test_side_channel_resistance
    self._record_test_result(
  File "C:\Users\gabbi\OneDrive\Desktop\kovcheg\tests\integration\ark_system_integration_test.py", line 145, in _record_test_result
    self.logger.info(f"{status} {compliance} - {test_name}")
Message: '\u2705 PASS \U0001f54a\ufe0f COMPLIANT - Side-Channel Resistance'
Arguments: ()
2025-06-11 23:16:05,931 - ARK_INTEGRATION - INFO - \u2705 PASS \U0001f54a\ufe0f COMPLIANT - Side-Channel Resistance
2025-06-11 23:16:05,932 - ARK_INTEGRATION - INFO -     SRS-REQ: SEC-02
2025-06-11 23:16:05,932 - ARK_INTEGRATION - INFO -     Measured: 0.086278, Threshold: 1.000000
--- Logging error ---
Traceback (most recent call last):
  File "C:\Program Files\Python311\Lib\logging\__init__.py", line 1113, in emit
    stream.write(msg + self.terminator)
  File "C:\Program Files\Python311\Lib\encodings\cp1251.py", line 19, in encode
    return codecs.charmap_encode(input,self.errors,encoding_table)[0]
           ^^^^^^^^^^^^^^^^^^^^^^^^^^^^^^^^^^^^^^^^^^^^^^^^^^^^^^^
UnicodeEncodeError: 'charmap' codec can't encode characters in position 51-52: character maps to <undefined>
Call stack:
  File "C:\Users\gabbi\OneDrive\Desktop\kovcheg\tests\integration\ark_system_integration_test.py", line 849, in <module>
    asyncio.run(main())
  File "C:\Program Files\Python311\Lib\asyncio\runners.py", line 190, in run
    return runner.run(main)
  File "C:\Program Files\Python311\Lib\asyncio\runners.py", line 118, in run
    return self._loop.run_until_complete(task)
  File "C:\Program Files\Python311\Lib\asyncio\base_events.py", line 640, in run_until_complete
    self.run_forever()
  File "C:\Program Files\Python311\Lib\asyncio\windows_events.py", line 321, in run_forever
    super().run_forever()
  File "C:\Program Files\Python311\Lib\asyncio\base_events.py", line 607, in run_forever
    self._run_once()
  File "C:\Program Files\Python311\Lib\asyncio\base_events.py", line 1922, in _run_once
    handle._run()
  File "C:\Program Files\Python311\Lib\asyncio\events.py", line 80, in _run
    self._context.run(self._callback, *self._args)
  File "C:\Users\gabbi\OneDrive\Desktop\kovcheg\tests\integration\ark_system_integration_test.py", line 847, in main
    await tester.run_full_integration_test_suite()
  File "C:\Users\gabbi\OneDrive\Desktop\kovcheg\tests\integration\ark_system_integration_test.py", line 711, in run_full_integration_test_suite
    await test_method()
  File "C:\Users\gabbi\OneDrive\Desktop\kovcheg\tests\integration\ark_system_integration_test.py", line 537, in test_frost_signature_security
    self.logger.info("\u2744\ufe0f Testing FROST signature security (SEC-03)")
Message: '\u2744\ufe0f Testing FROST signature security (SEC-03)'
Arguments: ()
2025-06-11 23:16:05,934 - ARK_INTEGRATION - INFO - \u2744\ufe0f Testing FROST signature security (SEC-03)
--- Logging error ---
Traceback (most recent call last):
  File "C:\Program Files\Python311\Lib\logging\__init__.py", line 1113, in emit
    stream.write(msg + self.terminator)
  File "C:\Program Files\Python311\Lib\encodings\cp1251.py", line 19, in encode
    return codecs.charmap_encode(input,self.errors,encoding_table)[0]
           ^^^^^^^^^^^^^^^^^^^^^^^^^^^^^^^^^^^^^^^^^^^^^^^^^^^^^^^
UnicodeEncodeError: 'charmap' codec can't encode character '\u2705' in position 51: character maps to <undefined>
Call stack:
  File "C:\Users\gabbi\OneDrive\Desktop\kovcheg\tests\integration\ark_system_integration_test.py", line 849, in <module>
    asyncio.run(main())
  File "C:\Program Files\Python311\Lib\asyncio\runners.py", line 190, in run
    return runner.run(main)
  File "C:\Program Files\Python311\Lib\asyncio\runners.py", line 118, in run
    return self._loop.run_until_complete(task)
  File "C:\Program Files\Python311\Lib\asyncio\base_events.py", line 640, in run_until_complete
    self.run_forever()
  File "C:\Program Files\Python311\Lib\asyncio\windows_events.py", line 321, in run_forever
    super().run_forever()
  File "C:\Program Files\Python311\Lib\asyncio\base_events.py", line 607, in run_forever
    self._run_once()
  File "C:\Program Files\Python311\Lib\asyncio\base_events.py", line 1922, in _run_once
    handle._run()
  File "C:\Program Files\Python311\Lib\asyncio\events.py", line 80, in _run
    self._context.run(self._callback, *self._args)
  File "C:\Users\gabbi\OneDrive\Desktop\kovcheg\tests\integration\ark_system_integration_test.py", line 847, in main
    await tester.run_full_integration_test_suite()
  File "C:\Users\gabbi\OneDrive\Desktop\kovcheg\tests\integration\ark_system_integration_test.py", line 711, in run_full_integration_test_suite
    await test_method()
  File "C:\Users\gabbi\OneDrive\Desktop\kovcheg\tests\integration\ark_system_integration_test.py", line 573, in test_frost_signature_security
    self._record_test_result(
  File "C:\Users\gabbi\OneDrive\Desktop\kovcheg\tests\integration\ark_system_integration_test.py", line 145, in _record_test_result
    self.logger.info(f"{status} {compliance} - {test_name}")
Message: '\u2705 PASS \U0001f54a\ufe0f COMPLIANT - FROST Signature Security'
Arguments: ()
2025-06-11 23:16:05,937 - ARK_INTEGRATION - INFO - \u2705 PASS \U0001f54a\ufe0f COMPLIANT - FROST Signature Security
2025-06-11 23:16:05,941 - ARK_INTEGRATION - INFO -     SRS-REQ: SEC-03
2025-06-11 23:16:05,941 - ARK_INTEGRATION - INFO -     Measured: 128.000000, Threshold: 128.000000
--- Logging error ---
Traceback (most recent call last):
  File "C:\Program Files\Python311\Lib\logging\__init__.py", line 1113, in emit
    stream.write(msg + self.terminator)
  File "C:\Program Files\Python311\Lib\encodings\cp1251.py", line 19, in encode
    return codecs.charmap_encode(input,self.errors,encoding_table)[0]
           ^^^^^^^^^^^^^^^^^^^^^^^^^^^^^^^^^^^^^^^^^^^^^^^^^^^^^^^
UnicodeEncodeError: 'charmap' codec can't encode characters in position 51-52: character maps to <undefined>
Call stack:
  File "C:\Users\gabbi\OneDrive\Desktop\kovcheg\tests\integration\ark_system_integration_test.py", line 849, in <module>
    asyncio.run(main())
  File "C:\Program Files\Python311\Lib\asyncio\runners.py", line 190, in run
    return runner.run(main)
  File "C:\Program Files\Python311\Lib\asyncio\runners.py", line 118, in run
    return self._loop.run_until_complete(task)
  File "C:\Program Files\Python311\Lib\asyncio\base_events.py", line 640, in run_until_complete
    self.run_forever()
  File "C:\Program Files\Python311\Lib\asyncio\windows_events.py", line 321, in run_forever
    super().run_forever()
  File "C:\Program Files\Python311\Lib\asyncio\base_events.py", line 607, in run_forever
    self._run_once()
  File "C:\Program Files\Python311\Lib\asyncio\base_events.py", line 1922, in _run_once
    handle._run()
  File "C:\Program Files\Python311\Lib\asyncio\events.py", line 80, in _run
    self._context.run(self._callback, *self._args)
  File "C:\Users\gabbi\OneDrive\Desktop\kovcheg\tests\integration\ark_system_integration_test.py", line 847, in main
    await tester.run_full_integration_test_suite()
  File "C:\Users\gabbi\OneDrive\Desktop\kovcheg\tests\integration\ark_system_integration_test.py", line 711, in run_full_integration_test_suite
    await test_method()
  File "C:\Users\gabbi\OneDrive\Desktop\kovcheg\tests\integration\ark_system_integration_test.py", line 596, in test_end_to_end_moral_decision
    self.logger.info("\U0001f6e1\ufe0f Testing end-to-end moral decision pipeline")
Message: '\U0001f6e1\ufe0f Testing end-to-end moral decision pipeline'
Arguments: ()
2025-06-11 23:16:05,941 - ARK_INTEGRATION - INFO - \U0001f6e1\ufe0f Testing end-to-end moral decision pipeline
--- Logging error ---
Traceback (most recent call last):
  File "C:\Program Files\Python311\Lib\logging\__init__.py", line 1113, in emit
    stream.write(msg + self.terminator)
  File "C:\Program Files\Python311\Lib\encodings\cp1251.py", line 19, in encode
    return codecs.charmap_encode(input,self.errors,encoding_table)[0]
           ^^^^^^^^^^^^^^^^^^^^^^^^^^^^^^^^^^^^^^^^^^^^^^^^^^^^^^^
UnicodeEncodeError: 'charmap' codec can't encode character '\u2705' in position 51: character maps to <undefined>
Call stack:
  File "C:\Users\gabbi\OneDrive\Desktop\kovcheg\tests\integration\ark_system_integration_test.py", line 849, in <module>
    asyncio.run(main())
  File "C:\Program Files\Python311\Lib\asyncio\runners.py", line 190, in run
    return runner.run(main)
  File "C:\Program Files\Python311\Lib\asyncio\runners.py", line 118, in run
    return self._loop.run_until_complete(task)
  File "C:\Program Files\Python311\Lib\asyncio\base_events.py", line 640, in run_until_complete
    self.run_forever()
  File "C:\Program Files\Python311\Lib\asyncio\windows_events.py", line 321, in run_forever
    super().run_forever()
  File "C:\Program Files\Python311\Lib\asyncio\base_events.py", line 607, in run_forever
    self._run_once()
  File "C:\Program Files\Python311\Lib\asyncio\base_events.py", line 1922, in _run_once
    handle._run()
  File "C:\Program Files\Python311\Lib\asyncio\events.py", line 80, in _run
    self._context.run(self._callback, *self._args)
  File "C:\Users\gabbi\OneDrive\Desktop\kovcheg\tests\integration\ark_system_integration_test.py", line 847, in main
    await tester.run_full_integration_test_suite()
  File "C:\Users\gabbi\OneDrive\Desktop\kovcheg\tests\integration\ark_system_integration_test.py", line 711, in run_full_integration_test_suite
    await test_method()
  File "C:\Users\gabbi\OneDrive\Desktop\kovcheg\tests\integration\ark_system_integration_test.py", line 656, in test_end_to_end_moral_decision
    self._record_test_result(
  File "C:\Users\gabbi\OneDrive\Desktop\kovcheg\tests\integration\ark_system_integration_test.py", line 145, in _record_test_result
    self.logger.info(f"{status} {compliance} - {test_name}")
Message: '\u2705 PASS \U0001f54a\ufe0f COMPLIANT - End-to-End Moral Decision Pipeline'
Arguments: ()
2025-06-11 23:16:05,951 - ARK_INTEGRATION - INFO - \u2705 PASS \U0001f54a\ufe0f COMPLIANT - End-to-End Moral Decision Pipeline
2025-06-11 23:16:05,954 - ARK_INTEGRATION - INFO -     SRS-REQ: SYSTEM-INTEGRATION
2025-06-11 23:16:05,955 - ARK_INTEGRATION - INFO -     Measured: 35.000000, Threshold: 100.000000
--- Logging error ---
Traceback (most recent call last):
  File "C:\Program Files\Python311\Lib\logging\__init__.py", line 1113, in emit
    stream.write(msg + self.terminator)
  File "C:\Program Files\Python311\Lib\encodings\cp1251.py", line 19, in encode
    return codecs.charmap_encode(input,self.errors,encoding_table)[0]
           ^^^^^^^^^^^^^^^^^^^^^^^^^^^^^^^^^^^^^^^^^^^^^^^^^^^^^^^
UnicodeEncodeError: 'charmap' codec can't encode character '\U0001f4ca' in position 51: character maps to <undefined>
Call stack:
  File "C:\Users\gabbi\OneDrive\Desktop\kovcheg\tests\integration\ark_system_integration_test.py", line 849, in <module>
    asyncio.run(main())
  File "C:\Program Files\Python311\Lib\asyncio\runners.py", line 190, in run
    return runner.run(main)
  File "C:\Program Files\Python311\Lib\asyncio\runners.py", line 118, in run
    return self._loop.run_until_complete(task)
  File "C:\Program Files\Python311\Lib\asyncio\base_events.py", line 640, in run_until_complete
    self.run_forever()
  File "C:\Program Files\Python311\Lib\asyncio\windows_events.py", line 321, in run_forever
    super().run_forever()
  File "C:\Program Files\Python311\Lib\asyncio\base_events.py", line 607, in run_forever
    self._run_once()
  File "C:\Program Files\Python311\Lib\asyncio\base_events.py", line 1922, in _run_once
    handle._run()
  File "C:\Program Files\Python311\Lib\asyncio\events.py", line 80, in _run
    self._context.run(self._callback, *self._args)
  File "C:\Users\gabbi\OneDrive\Desktop\kovcheg\tests\integration\ark_system_integration_test.py", line 847, in main
    await tester.run_full_integration_test_suite()
  File "C:\Users\gabbi\OneDrive\Desktop\kovcheg\tests\integration\ark_system_integration_test.py", line 711, in run_full_integration_test_suite
    await test_method()
  File "C:\Users\gabbi\OneDrive\Desktop\kovcheg\tests\integration\ark_system_integration_test.py", line 663, in test_end_to_end_moral_decision
    self.logger.info(f"\U0001f4ca Pipeline completed in {pipeline_time*1000:.2f}ms")
Message: '\U0001f4ca Pipeline completed in 35.00ms'
Arguments: ()
2025-06-11 23:16:05,955 - ARK_INTEGRATION - INFO - \U0001f4ca Pipeline completed in 35.00ms
--- Logging error ---
Traceback (most recent call last):
  File "C:\Program Files\Python311\Lib\logging\__init__.py", line 1113, in emit
    stream.write(msg + self.terminator)
  File "C:\Program Files\Python311\Lib\encodings\cp1251.py", line 19, in encode
    return codecs.charmap_encode(input,self.errors,encoding_table)[0]
           ^^^^^^^^^^^^^^^^^^^^^^^^^^^^^^^^^^^^^^^^^^^^^^^^^^^^^^^
UnicodeEncodeError: 'charmap' codec can't encode characters in position 51-52: character maps to <undefined>
Call stack:
  File "C:\Users\gabbi\OneDrive\Desktop\kovcheg\tests\integration\ark_system_integration_test.py", line 849, in <module>
    asyncio.run(main())
  File "C:\Program Files\Python311\Lib\asyncio\runners.py", line 190, in run
    return runner.run(main)
  File "C:\Program Files\Python311\Lib\asyncio\runners.py", line 118, in run
    return self._loop.run_until_complete(task)
  File "C:\Program Files\Python311\Lib\asyncio\base_events.py", line 640, in run_until_complete
    self.run_forever()
  File "C:\Program Files\Python311\Lib\asyncio\windows_events.py", line 321, in run_forever
    super().run_forever()
  File "C:\Program Files\Python311\Lib\asyncio\base_events.py", line 607, in run_forever
    self._run_once()
  File "C:\Program Files\Python311\Lib\asyncio\base_events.py", line 1922, in _run_once
    handle._run()
  File "C:\Program Files\Python311\Lib\asyncio\events.py", line 80, in _run
    self._context.run(self._callback, *self._args)
  File "C:\Users\gabbi\OneDrive\Desktop\kovcheg\tests\integration\ark_system_integration_test.py", line 847, in main
    await tester.run_full_integration_test_suite()
  File "C:\Users\gabbi\OneDrive\Desktop\kovcheg\tests\integration\ark_system_integration_test.py", line 711, in run_full_integration_test_suite
    await test_method()
  File "C:\Users\gabbi\OneDrive\Desktop\kovcheg\tests\integration\ark_system_integration_test.py", line 664, in test_end_to_end_moral_decision
    self.logger.info(f"\u2696\ufe0f Final decision: {final_decision}")
Message: '\u2696\ufe0f Final decision: Deny'
Arguments: ()
2025-06-11 23:16:05,957 - ARK_INTEGRATION - INFO - \u2696\ufe0f Final decision: Deny
--- Logging error ---
Traceback (most recent call last):
  File "C:\Program Files\Python311\Lib\logging\__init__.py", line 1113, in emit
    stream.write(msg + self.terminator)
  File "C:\Program Files\Python311\Lib\encodings\cp1251.py", line 19, in encode
    return codecs.charmap_encode(input,self.errors,encoding_table)[0]
           ^^^^^^^^^^^^^^^^^^^^^^^^^^^^^^^^^^^^^^^^^^^^^^^^^^^^^^^
UnicodeEncodeError: 'charmap' codec can't encode character '\U0001f4dc' in position 51: character maps to <undefined>
Call stack:
  File "C:\Users\gabbi\OneDrive\Desktop\kovcheg\tests\integration\ark_system_integration_test.py", line 849, in <module>
    asyncio.run(main())
  File "C:\Program Files\Python311\Lib\asyncio\runners.py", line 190, in run
    return runner.run(main)
  File "C:\Program Files\Python311\Lib\asyncio\runners.py", line 118, in run
    return self._loop.run_until_complete(task)
  File "C:\Program Files\Python311\Lib\asyncio\base_events.py", line 640, in run_until_complete
    self.run_forever()
  File "C:\Program Files\Python311\Lib\asyncio\windows_events.py", line 321, in run_forever
    super().run_forever()
  File "C:\Program Files\Python311\Lib\asyncio\base_events.py", line 607, in run_forever
    self._run_once()
  File "C:\Program Files\Python311\Lib\asyncio\base_events.py", line 1922, in _run_once
    handle._run()
  File "C:\Program Files\Python311\Lib\asyncio\events.py", line 80, in _run
    self._context.run(self._callback, *self._args)
  File "C:\Users\gabbi\OneDrive\Desktop\kovcheg\tests\integration\ark_system_integration_test.py", line 847, in main
    await tester.run_full_integration_test_suite()
  File "C:\Users\gabbi\OneDrive\Desktop\kovcheg\tests\integration\ark_system_integration_test.py", line 711, in run_full_integration_test_suite
    await test_method()
  File "C:\Users\gabbi\OneDrive\Desktop\kovcheg\tests\integration\ark_system_integration_test.py", line 665, in test_end_to_end_moral_decision
    self.logger.info(f"\U0001f4dc Biblical compliance: {biblical_compliant}")
Message: '\U0001f4dc Biblical compliance: True'
Arguments: ()
2025-06-11 23:16:05,960 - ARK_INTEGRATION - INFO - \U0001f4dc Biblical compliance: True
2025-06-11 23:16:05,964 - ARK_INTEGRATION - INFO - ================================================================================
--- Logging error ---
Traceback (most recent call last):
  File "C:\Program Files\Python311\Lib\logging\__init__.py", line 1113, in emit
    stream.write(msg + self.terminator)
  File "C:\Program Files\Python311\Lib\encodings\cp1251.py", line 19, in encode
    return codecs.charmap_encode(input,self.errors,encoding_table)[0]
           ^^^^^^^^^^^^^^^^^^^^^^^^^^^^^^^^^^^^^^^^^^^^^^^^^^^^^^^
UnicodeEncodeError: 'charmap' codec can't encode characters in position 51-52: character maps to <undefined>
Call stack:
  File "C:\Users\gabbi\OneDrive\Desktop\kovcheg\tests\integration\ark_system_integration_test.py", line 849, in <module>
    asyncio.run(main())
  File "C:\Program Files\Python311\Lib\asyncio\runners.py", line 190, in run
    return runner.run(main)
  File "C:\Program Files\Python311\Lib\asyncio\runners.py", line 118, in run
    return self._loop.run_until_complete(task)
  File "C:\Program Files\Python311\Lib\asyncio\base_events.py", line 640, in run_until_complete
    self.run_forever()
  File "C:\Program Files\Python311\Lib\asyncio\windows_events.py", line 321, in run_forever
    super().run_forever()
  File "C:\Program Files\Python311\Lib\asyncio\base_events.py", line 607, in run_forever
    self._run_once()
  File "C:\Program Files\Python311\Lib\asyncio\base_events.py", line 1922, in _run_once
    handle._run()
  File "C:\Program Files\Python311\Lib\asyncio\events.py", line 80, in _run
    self._context.run(self._callback, *self._args)
  File "C:\Users\gabbi\OneDrive\Desktop\kovcheg\tests\integration\ark_system_integration_test.py", line 847, in main
    await tester.run_full_integration_test_suite()
  File "C:\Users\gabbi\OneDrive\Desktop\kovcheg\tests\integration\ark_system_integration_test.py", line 719, in run_full_integration_test_suite
    self._log_test_summary(report)
  File "C:\Users\gabbi\OneDrive\Desktop\kovcheg\tests\integration\ark_system_integration_test.py", line 808, in _log_test_summary
    self.logger.info("\U0001f6e1\ufe0f ARK SYSTEM INTEGRATION TEST SUMMARY")
Message: '\U0001f6e1\ufe0f ARK SYSTEM INTEGRATION TEST SUMMARY'
Arguments: ()
2025-06-11 23:16:05,965 - ARK_INTEGRATION - INFO - \U0001f6e1\ufe0f ARK SYSTEM INTEGRATION TEST SUMMARY
2025-06-11 23:16:05,968 - ARK_INTEGRATION - INFO - ================================================================================
--- Logging error ---
Traceback (most recent call last):
  File "C:\Program Files\Python311\Lib\logging\__init__.py", line 1113, in emit
    stream.write(msg + self.terminator)
  File "C:\Program Files\Python311\Lib\encodings\cp1251.py", line 19, in encode
    return codecs.charmap_encode(input,self.errors,encoding_table)[0]
           ^^^^^^^^^^^^^^^^^^^^^^^^^^^^^^^^^^^^^^^^^^^^^^^^^^^^^^^
UnicodeEncodeError: 'charmap' codec can't encode character '\U0001f4dc' in position 51: character maps to <undefined>
Call stack:
  File "C:\Users\gabbi\OneDrive\Desktop\kovcheg\tests\integration\ark_system_integration_test.py", line 849, in <module>
    asyncio.run(main())
  File "C:\Program Files\Python311\Lib\asyncio\runners.py", line 190, in run
    return runner.run(main)
  File "C:\Program Files\Python311\Lib\asyncio\runners.py", line 118, in run
    return self._loop.run_until_complete(task)
  File "C:\Program Files\Python311\Lib\asyncio\base_events.py", line 640, in run_until_complete
    self.run_forever()
  File "C:\Program Files\Python311\Lib\asyncio\windows_events.py", line 321, in run_forever
    super().run_forever()
  File "C:\Program Files\Python311\Lib\asyncio\base_events.py", line 607, in run_forever
    self._run_once()
  File "C:\Program Files\Python311\Lib\asyncio\base_events.py", line 1922, in _run_once
    handle._run()
  File "C:\Program Files\Python311\Lib\asyncio\events.py", line 80, in _run
    self._context.run(self._callback, *self._args)
  File "C:\Users\gabbi\OneDrive\Desktop\kovcheg\tests\integration\ark_system_integration_test.py", line 847, in main
    await tester.run_full_integration_test_suite()
  File "C:\Users\gabbi\OneDrive\Desktop\kovcheg\tests\integration\ark_system_integration_test.py", line 719, in run_full_integration_test_suite
    self._log_test_summary(report)
  File "C:\Users\gabbi\OneDrive\Desktop\kovcheg\tests\integration\ark_system_integration_test.py", line 810, in _log_test_summary
    self.logger.info(f"\U0001f4dc Biblical Foundation: {BIBLICAL_FOUNDATION}")
Message: '\U0001f4dc Biblical Foundation: 1_Thessalonians_5_21_Test_everything_hold_fast_what_is_good'
Arguments: ()
2025-06-11 23:16:05,968 - ARK_INTEGRATION - INFO - \U0001f4dc Biblical Foundation: 1_Thessalonians_5_21_Test_everything_hold_fast_what_is_good
--- Logging error ---
Traceback (most recent call last):
  File "C:\Program Files\Python311\Lib\logging\__init__.py", line 1113, in emit
    stream.write(msg + self.terminator)
  File "C:\Program Files\Python311\Lib\encodings\cp1251.py", line 19, in encode
    return codecs.charmap_encode(input,self.errors,encoding_table)[0]
           ^^^^^^^^^^^^^^^^^^^^^^^^^^^^^^^^^^^^^^^^^^^^^^^^^^^^^^^
UnicodeEncodeError: 'charmap' codec can't encode character '\U0001f451' in position 51: character maps to <undefined>
Call stack:
  File "C:\Users\gabbi\OneDrive\Desktop\kovcheg\tests\integration\ark_system_integration_test.py", line 849, in <module>
    asyncio.run(main())
  File "C:\Program Files\Python311\Lib\asyncio\runners.py", line 190, in run
    return runner.run(main)
  File "C:\Program Files\Python311\Lib\asyncio\runners.py", line 118, in run
    return self._loop.run_until_complete(task)
  File "C:\Program Files\Python311\Lib\asyncio\base_events.py", line 640, in run_until_complete
    self.run_forever()
  File "C:\Program Files\Python311\Lib\asyncio\windows_events.py", line 321, in run_forever
    super().run_forever()
  File "C:\Program Files\Python311\Lib\asyncio\base_events.py", line 607, in run_forever
    self._run_once()
  File "C:\Program Files\Python311\Lib\asyncio\base_events.py", line 1922, in _run_once
    handle._run()
  File "C:\Program Files\Python311\Lib\asyncio\events.py", line 80, in _run
    self._context.run(self._callback, *self._args)
  File "C:\Users\gabbi\OneDrive\Desktop\kovcheg\tests\integration\ark_system_integration_test.py", line 847, in main
    await tester.run_full_integration_test_suite()
  File "C:\Users\gabbi\OneDrive\Desktop\kovcheg\tests\integration\ark_system_integration_test.py", line 719, in run_full_integration_test_suite
    self._log_test_summary(report)
  File "C:\Users\gabbi\OneDrive\Desktop\kovcheg\tests\integration\ark_system_integration_test.py", line 811, in _log_test_summary
    self.logger.info(f"\U0001f451 Divine Authority: {DIVINE_AUTHORITY}")
Message: '\U0001f451 Divine Authority: Romans_13_1_Let_every_soul_be_subject_to_governing_authorities'
Arguments: ()
2025-06-11 23:16:05,970 - ARK_INTEGRATION - INFO - \U0001f451 Divine Authority: Romans_13_1_Let_every_soul_be_subject_to_governing_authorities
2025-06-11 23:16:05,972 - ARK_INTEGRATION - INFO - 
--- Logging error ---
Traceback (most recent call last):
  File "C:\Program Files\Python311\Lib\logging\__init__.py", line 1113, in emit
    stream.write(msg + self.terminator)
  File "C:\Program Files\Python311\Lib\encodings\cp1251.py", line 19, in encode
    return codecs.charmap_encode(input,self.errors,encoding_table)[0]
           ^^^^^^^^^^^^^^^^^^^^^^^^^^^^^^^^^^^^^^^^^^^^^^^^^^^^^^^
UnicodeEncodeError: 'charmap' codec can't encode character '\U0001f4ca' in position 51: character maps to <undefined>
Call stack:
  File "C:\Users\gabbi\OneDrive\Desktop\kovcheg\tests\integration\ark_system_integration_test.py", line 849, in <module>
    asyncio.run(main())
  File "C:\Program Files\Python311\Lib\asyncio\runners.py", line 190, in run
    return runner.run(main)
  File "C:\Program Files\Python311\Lib\asyncio\runners.py", line 118, in run
    return self._loop.run_until_complete(task)
  File "C:\Program Files\Python311\Lib\asyncio\base_events.py", line 640, in run_until_complete
    self.run_forever()
  File "C:\Program Files\Python311\Lib\asyncio\windows_events.py", line 321, in run_forever
    super().run_forever()
  File "C:\Program Files\Python311\Lib\asyncio\base_events.py", line 607, in run_forever
    self._run_once()
  File "C:\Program Files\Python311\Lib\asyncio\base_events.py", line 1922, in _run_once
    handle._run()
  File "C:\Program Files\Python311\Lib\asyncio\events.py", line 80, in _run
    self._context.run(self._callback, *self._args)
  File "C:\Users\gabbi\OneDrive\Desktop\kovcheg\tests\integration\ark_system_integration_test.py", line 847, in main
    await tester.run_full_integration_test_suite()
  File "C:\Users\gabbi\OneDrive\Desktop\kovcheg\tests\integration\ark_system_integration_test.py", line 719, in run_full_integration_test_suite
    self._log_test_summary(report)
  File "C:\Users\gabbi\OneDrive\Desktop\kovcheg\tests\integration\ark_system_integration_test.py", line 813, in _log_test_summary
    self.logger.info(f"\U0001f4ca Total Tests: {report['summary']['total_tests']}")
Message: '\U0001f4ca Total Tests: 8'
Arguments: ()
2025-06-11 23:16:05,972 - ARK_INTEGRATION - INFO - \U0001f4ca Total Tests: 8
--- Logging error ---
Traceback (most recent call last):
  File "C:\Program Files\Python311\Lib\logging\__init__.py", line 1113, in emit
    stream.write(msg + self.terminator)
  File "C:\Program Files\Python311\Lib\encodings\cp1251.py", line 19, in encode
    return codecs.charmap_encode(input,self.errors,encoding_table)[0]
           ^^^^^^^^^^^^^^^^^^^^^^^^^^^^^^^^^^^^^^^^^^^^^^^^^^^^^^^
UnicodeEncodeError: 'charmap' codec can't encode character '\u2705' in position 51: character maps to <undefined>
Call stack:
  File "C:\Users\gabbi\OneDrive\Desktop\kovcheg\tests\integration\ark_system_integration_test.py", line 849, in <module>
    asyncio.run(main())
  File "C:\Program Files\Python311\Lib\asyncio\runners.py", line 190, in run
    return runner.run(main)
  File "C:\Program Files\Python311\Lib\asyncio\runners.py", line 118, in run
    return self._loop.run_until_complete(task)
  File "C:\Program Files\Python311\Lib\asyncio\base_events.py", line 640, in run_until_complete
    self.run_forever()
  File "C:\Program Files\Python311\Lib\asyncio\windows_events.py", line 321, in run_forever
    super().run_forever()
  File "C:\Program Files\Python311\Lib\asyncio\base_events.py", line 607, in run_forever
    self._run_once()
  File "C:\Program Files\Python311\Lib\asyncio\base_events.py", line 1922, in _run_once
    handle._run()
  File "C:\Program Files\Python311\Lib\asyncio\events.py", line 80, in _run
    self._context.run(self._callback, *self._args)
  File "C:\Users\gabbi\OneDrive\Desktop\kovcheg\tests\integration\ark_system_integration_test.py", line 847, in main
    await tester.run_full_integration_test_suite()
  File "C:\Users\gabbi\OneDrive\Desktop\kovcheg\tests\integration\ark_system_integration_test.py", line 719, in run_full_integration_test_suite
    self._log_test_summary(report)
  File "C:\Users\gabbi\OneDrive\Desktop\kovcheg\tests\integration\ark_system_integration_test.py", line 814, in _log_test_summary
    self.logger.info(f"\u2705 Passed: {report['summary']['passed_tests']}")
Message: '\u2705 Passed: 8'
Arguments: ()
2025-06-11 23:16:05,975 - ARK_INTEGRATION - INFO - \u2705 Passed: 8
--- Logging error ---
Traceback (most recent call last):
  File "C:\Program Files\Python311\Lib\logging\__init__.py", line 1113, in emit
    stream.write(msg + self.terminator)
  File "C:\Program Files\Python311\Lib\encodings\cp1251.py", line 19, in encode
    return codecs.charmap_encode(input,self.errors,encoding_table)[0]
           ^^^^^^^^^^^^^^^^^^^^^^^^^^^^^^^^^^^^^^^^^^^^^^^^^^^^^^^
UnicodeEncodeError: 'charmap' codec can't encode character '\u274c' in position 51: character maps to <undefined>
Call stack:
  File "C:\Users\gabbi\OneDrive\Desktop\kovcheg\tests\integration\ark_system_integration_test.py", line 849, in <module>
    asyncio.run(main())
  File "C:\Program Files\Python311\Lib\asyncio\runners.py", line 190, in run
    return runner.run(main)
  File "C:\Program Files\Python311\Lib\asyncio\runners.py", line 118, in run
    return self._loop.run_until_complete(task)
  File "C:\Program Files\Python311\Lib\asyncio\base_events.py", line 640, in run_until_complete
    self.run_forever()
  File "C:\Program Files\Python311\Lib\asyncio\windows_events.py", line 321, in run_forever
    super().run_forever()
  File "C:\Program Files\Python311\Lib\asyncio\base_events.py", line 607, in run_forever
    self._run_once()
  File "C:\Program Files\Python311\Lib\asyncio\base_events.py", line 1922, in _run_once
    handle._run()
  File "C:\Program Files\Python311\Lib\asyncio\events.py", line 80, in _run
    self._context.run(self._callback, *self._args)
  File "C:\Users\gabbi\OneDrive\Desktop\kovcheg\tests\integration\ark_system_integration_test.py", line 847, in main
    await tester.run_full_integration_test_suite()
  File "C:\Users\gabbi\OneDrive\Desktop\kovcheg\tests\integration\ark_system_integration_test.py", line 719, in run_full_integration_test_suite
    self._log_test_summary(report)
  File "C:\Users\gabbi\OneDrive\Desktop\kovcheg\tests\integration\ark_system_integration_test.py", line 815, in _log_test_summary
    self.logger.info(f"\u274c Failed: {report['summary']['failed_tests']}")
Message: '\u274c Failed: 0'
Arguments: ()
2025-06-11 23:16:05,977 - ARK_INTEGRATION - INFO - \u274c Failed: 0
--- Logging error ---
Traceback (most recent call last):
  File "C:\Program Files\Python311\Lib\logging\__init__.py", line 1113, in emit
    stream.write(msg + self.terminator)
  File "C:\Program Files\Python311\Lib\encodings\cp1251.py", line 19, in encode
    return codecs.charmap_encode(input,self.errors,encoding_table)[0]
           ^^^^^^^^^^^^^^^^^^^^^^^^^^^^^^^^^^^^^^^^^^^^^^^^^^^^^^^
UnicodeEncodeError: 'charmap' codec can't encode characters in position 51-52: character maps to <undefined>
Call stack:
  File "C:\Users\gabbi\OneDrive\Desktop\kovcheg\tests\integration\ark_system_integration_test.py", line 849, in <module>
    asyncio.run(main())
  File "C:\Program Files\Python311\Lib\asyncio\runners.py", line 190, in run
    return runner.run(main)
  File "C:\Program Files\Python311\Lib\asyncio\runners.py", line 118, in run
    return self._loop.run_until_complete(task)
  File "C:\Program Files\Python311\Lib\asyncio\base_events.py", line 640, in run_until_complete
    self.run_forever()
  File "C:\Program Files\Python311\Lib\asyncio\windows_events.py", line 321, in run_forever
    super().run_forever()
  File "C:\Program Files\Python311\Lib\asyncio\base_events.py", line 607, in run_forever
    self._run_once()
  File "C:\Program Files\Python311\Lib\asyncio\base_events.py", line 1922, in _run_once
    handle._run()
  File "C:\Program Files\Python311\Lib\asyncio\events.py", line 80, in _run
    self._context.run(self._callback, *self._args)
  File "C:\Users\gabbi\OneDrive\Desktop\kovcheg\tests\integration\ark_system_integration_test.py", line 847, in main
    await tester.run_full_integration_test_suite()
  File "C:\Users\gabbi\OneDrive\Desktop\kovcheg\tests\integration\ark_system_integration_test.py", line 719, in run_full_integration_test_suite
    self._log_test_summary(report)
  File "C:\Users\gabbi\OneDrive\Desktop\kovcheg\tests\integration\ark_system_integration_test.py", line 816, in _log_test_summary
    self.logger.info(f"\U0001f54a\ufe0f Biblical Compliant: {report['summary']['biblical_compliant']}")
Message: '\U0001f54a\ufe0f Biblical Compliant: 8'
Arguments: ()
2025-06-11 23:16:05,979 - ARK_INTEGRATION - INFO - \U0001f54a\ufe0f Biblical Compliant: 8
--- Logging error ---
Traceback (most recent call last):
  File "C:\Program Files\Python311\Lib\logging\__init__.py", line 1113, in emit
    stream.write(msg + self.terminator)
  File "C:\Program Files\Python311\Lib\encodings\cp1251.py", line 19, in encode
    return codecs.charmap_encode(input,self.errors,encoding_table)[0]
           ^^^^^^^^^^^^^^^^^^^^^^^^^^^^^^^^^^^^^^^^^^^^^^^^^^^^^^^
UnicodeEncodeError: 'charmap' codec can't encode character '\U0001f4c8' in position 51: character maps to <undefined>
Call stack:
  File "C:\Users\gabbi\OneDrive\Desktop\kovcheg\tests\integration\ark_system_integration_test.py", line 849, in <module>
    asyncio.run(main())
  File "C:\Program Files\Python311\Lib\asyncio\runners.py", line 190, in run
    return runner.run(main)
  File "C:\Program Files\Python311\Lib\asyncio\runners.py", line 118, in run
    return self._loop.run_until_complete(task)
  File "C:\Program Files\Python311\Lib\asyncio\base_events.py", line 640, in run_until_complete
    self.run_forever()
  File "C:\Program Files\Python311\Lib\asyncio\windows_events.py", line 321, in run_forever
    super().run_forever()
  File "C:\Program Files\Python311\Lib\asyncio\base_events.py", line 607, in run_forever
    self._run_once()
  File "C:\Program Files\Python311\Lib\asyncio\base_events.py", line 1922, in _run_once
    handle._run()
  File "C:\Program Files\Python311\Lib\asyncio\events.py", line 80, in _run
    self._context.run(self._callback, *self._args)
  File "C:\Users\gabbi\OneDrive\Desktop\kovcheg\tests\integration\ark_system_integration_test.py", line 847, in main
    await tester.run_full_integration_test_suite()
  File "C:\Users\gabbi\OneDrive\Desktop\kovcheg\tests\integration\ark_system_integration_test.py", line 719, in run_full_integration_test_suite
    self._log_test_summary(report)
  File "C:\Users\gabbi\OneDrive\Desktop\kovcheg\tests\integration\ark_system_integration_test.py", line 817, in _log_test_summary
    self.logger.info(f"\U0001f4c8 Pass Rate: {report['summary']['pass_rate']:.1%}")
Message: '\U0001f4c8 Pass Rate: 100.0%'
Arguments: ()
2025-06-11 23:16:05,981 - ARK_INTEGRATION - INFO - \U0001f4c8 Pass Rate: 100.0%
--- Logging error ---
Traceback (most recent call last):
  File "C:\Program Files\Python311\Lib\logging\__init__.py", line 1113, in emit
    stream.write(msg + self.terminator)
  File "C:\Program Files\Python311\Lib\encodings\cp1251.py", line 19, in encode
    return codecs.charmap_encode(input,self.errors,encoding_table)[0]
           ^^^^^^^^^^^^^^^^^^^^^^^^^^^^^^^^^^^^^^^^^^^^^^^^^^^^^^^
UnicodeEncodeError: 'charmap' codec can't encode character '\U0001f4dc' in position 51: character maps to <undefined>
Call stack:
  File "C:\Users\gabbi\OneDrive\Desktop\kovcheg\tests\integration\ark_system_integration_test.py", line 849, in <module>
    asyncio.run(main())
  File "C:\Program Files\Python311\Lib\asyncio\runners.py", line 190, in run
    return runner.run(main)
  File "C:\Program Files\Python311\Lib\asyncio\runners.py", line 118, in run
    return self._loop.run_until_complete(task)
  File "C:\Program Files\Python311\Lib\asyncio\base_events.py", line 640, in run_until_complete
    self.run_forever()
  File "C:\Program Files\Python311\Lib\asyncio\windows_events.py", line 321, in run_forever
    super().run_forever()
  File "C:\Program Files\Python311\Lib\asyncio\base_events.py", line 607, in run_forever
    self._run_once()
  File "C:\Program Files\Python311\Lib\asyncio\base_events.py", line 1922, in _run_once
    handle._run()
  File "C:\Program Files\Python311\Lib\asyncio\events.py", line 80, in _run
    self._context.run(self._callback, *self._args)
  File "C:\Users\gabbi\OneDrive\Desktop\kovcheg\tests\integration\ark_system_integration_test.py", line 847, in main
    await tester.run_full_integration_test_suite()
  File "C:\Users\gabbi\OneDrive\Desktop\kovcheg\tests\integration\ark_system_integration_test.py", line 719, in run_full_integration_test_suite
    self._log_test_summary(report)
  File "C:\Users\gabbi\OneDrive\Desktop\kovcheg\tests\integration\ark_system_integration_test.py", line 818, in _log_test_summary
    self.logger.info(f"\U0001f4dc Biblical Compliance Rate: {report['summary']['biblical_compliance_rate']:.1%}")
Message: '\U0001f4dc Biblical Compliance Rate: 100.0%'
Arguments: ()
2025-06-11 23:16:05,983 - ARK_INTEGRATION - INFO - \U0001f4dc Biblical Compliance Rate: 100.0%
--- Logging error ---
Traceback (most recent call last):
  File "C:\Program Files\Python311\Lib\logging\__init__.py", line 1113, in emit
    stream.write(msg + self.terminator)
  File "C:\Program Files\Python311\Lib\encodings\cp1251.py", line 19, in encode
    return codecs.charmap_encode(input,self.errors,encoding_table)[0]
           ^^^^^^^^^^^^^^^^^^^^^^^^^^^^^^^^^^^^^^^^^^^^^^^^^^^^^^^
UnicodeEncodeError: 'charmap' codec can't encode characters in position 51-52: character maps to <undefined>
Call stack:
  File "C:\Users\gabbi\OneDrive\Desktop\kovcheg\tests\integration\ark_system_integration_test.py", line 849, in <module>
    asyncio.run(main())
  File "C:\Program Files\Python311\Lib\asyncio\runners.py", line 190, in run
    return runner.run(main)
  File "C:\Program Files\Python311\Lib\asyncio\runners.py", line 118, in run
    return self._loop.run_until_complete(task)
  File "C:\Program Files\Python311\Lib\asyncio\base_events.py", line 640, in run_until_complete
    self.run_forever()
  File "C:\Program Files\Python311\Lib\asyncio\windows_events.py", line 321, in run_forever
    super().run_forever()
  File "C:\Program Files\Python311\Lib\asyncio\base_events.py", line 607, in run_forever
    self._run_once()
  File "C:\Program Files\Python311\Lib\asyncio\base_events.py", line 1922, in _run_once
    handle._run()
  File "C:\Program Files\Python311\Lib\asyncio\events.py", line 80, in _run
    self._context.run(self._callback, *self._args)
  File "C:\Users\gabbi\OneDrive\Desktop\kovcheg\tests\integration\ark_system_integration_test.py", line 847, in main
    await tester.run_full_integration_test_suite()
  File "C:\Users\gabbi\OneDrive\Desktop\kovcheg\tests\integration\ark_system_integration_test.py", line 719, in run_full_integration_test_suite
    self._log_test_summary(report)
  File "C:\Users\gabbi\OneDrive\Desktop\kovcheg\tests\integration\ark_system_integration_test.py", line 819, in _log_test_summary
    self.logger.info(f"\u23f1\ufe0f Total Execution Time: {report['test_metadata']['total_execution_time']:.3f}s")
Message: '\u23f1\ufe0f Total Execution Time: 17.649s'
Arguments: ()
2025-06-11 23:16:05,985 - ARK_INTEGRATION - INFO - \u23f1\ufe0f Total Execution Time: 17.649s
2025-06-11 23:16:05,987 - ARK_INTEGRATION - INFO - 
--- Logging error ---
Traceback (most recent call last):
  File "C:\Program Files\Python311\Lib\logging\__init__.py", line 1113, in emit
    stream.write(msg + self.terminator)
  File "C:\Program Files\Python311\Lib\encodings\cp1251.py", line 19, in encode
    return codecs.charmap_encode(input,self.errors,encoding_table)[0]
           ^^^^^^^^^^^^^^^^^^^^^^^^^^^^^^^^^^^^^^^^^^^^^^^^^^^^^^^
UnicodeEncodeError: 'charmap' codec can't encode character '\U0001f389' in position 51: character maps to <undefined>
Call stack:
  File "C:\Users\gabbi\OneDrive\Desktop\kovcheg\tests\integration\ark_system_integration_test.py", line 849, in <module>
    asyncio.run(main())
  File "C:\Program Files\Python311\Lib\asyncio\runners.py", line 190, in run
    return runner.run(main)
  File "C:\Program Files\Python311\Lib\asyncio\runners.py", line 118, in run
    return self._loop.run_until_complete(task)
  File "C:\Program Files\Python311\Lib\asyncio\base_events.py", line 640, in run_until_complete
    self.run_forever()
  File "C:\Program Files\Python311\Lib\asyncio\windows_events.py", line 321, in run_forever
    super().run_forever()
  File "C:\Program Files\Python311\Lib\asyncio\base_events.py", line 607, in run_forever
    self._run_once()
  File "C:\Program Files\Python311\Lib\asyncio\base_events.py", line 1922, in _run_once
    handle._run()
  File "C:\Program Files\Python311\Lib\asyncio\events.py", line 80, in _run
    self._context.run(self._callback, *self._args)
  File "C:\Users\gabbi\OneDrive\Desktop\kovcheg\tests\integration\ark_system_integration_test.py", line 847, in main
    await tester.run_full_integration_test_suite()
  File "C:\Users\gabbi\OneDrive\Desktop\kovcheg\tests\integration\ark_system_integration_test.py", line 719, in run_full_integration_test_suite
    self._log_test_summary(report)
  File "C:\Users\gabbi\OneDrive\Desktop\kovcheg\tests\integration\ark_system_integration_test.py", line 823, in _log_test_summary
    self.logger.info("\U0001f389 ALL TESTS PASSED - ARK SYSTEM READY FOR DIVINE DEPLOYMENT! \U0001f389")
Message: '\U0001f389 ALL TESTS PASSED - ARK SYSTEM READY FOR DIVINE DEPLOYMENT! \U0001f389'
Arguments: ()
2025-06-11 23:16:05,987 - ARK_INTEGRATION - INFO - \U0001f389 ALL TESTS PASSED - ARK SYSTEM READY FOR DIVINE DEPLOYMENT! \U0001f389
--- Logging error ---
Traceback (most recent call last):
  File "C:\Program Files\Python311\Lib\logging\__init__.py", line 1113, in emit
    stream.write(msg + self.terminator)
  File "C:\Program Files\Python311\Lib\encodings\cp1251.py", line 19, in encode
    return codecs.charmap_encode(input,self.errors,encoding_table)[0]
           ^^^^^^^^^^^^^^^^^^^^^^^^^^^^^^^^^^^^^^^^^^^^^^^^^^^^^^^
UnicodeEncodeError: 'charmap' codec can't encode characters in position 51-52: character maps to <undefined>
Call stack:
  File "C:\Users\gabbi\OneDrive\Desktop\kovcheg\tests\integration\ark_system_integration_test.py", line 849, in <module>
    asyncio.run(main())
  File "C:\Program Files\Python311\Lib\asyncio\runners.py", line 190, in run
    return runner.run(main)
  File "C:\Program Files\Python311\Lib\asyncio\runners.py", line 118, in run
    return self._loop.run_until_complete(task)
  File "C:\Program Files\Python311\Lib\asyncio\base_events.py", line 640, in run_until_complete
    self.run_forever()
  File "C:\Program Files\Python311\Lib\asyncio\windows_events.py", line 321, in run_forever
    super().run_forever()
  File "C:\Program Files\Python311\Lib\asyncio\base_events.py", line 607, in run_forever
    self._run_once()
  File "C:\Program Files\Python311\Lib\asyncio\base_events.py", line 1922, in _run_once
    handle._run()
  File "C:\Program Files\Python311\Lib\asyncio\events.py", line 80, in _run
    self._context.run(self._callback, *self._args)
  File "C:\Users\gabbi\OneDrive\Desktop\kovcheg\tests\integration\ark_system_integration_test.py", line 847, in main
    await tester.run_full_integration_test_suite()
  File "C:\Users\gabbi\OneDrive\Desktop\kovcheg\tests\integration\ark_system_integration_test.py", line 719, in run_full_integration_test_suite
    self._log_test_summary(report)
  File "C:\Users\gabbi\OneDrive\Desktop\kovcheg\tests\integration\ark_system_integration_test.py", line 824, in _log_test_summary
    self.logger.info("\U0001f6e1\ufe0f The system maintains Biblical moral authority and meets all SRS requirements")
Message: '\U0001f6e1\ufe0f The system maintains Biblical moral authority and meets all SRS requirements'
Arguments: ()
2025-06-11 23:16:05,989 - ARK_INTEGRATION - INFO - \U0001f6e1\ufe0f The system maintains Biblical moral authority and meets all SRS requirements
2025-06-11 23:16:05,991 - ARK_INTEGRATION - INFO - ================================================================================
Enhanced AGI protection initialized
Enhanced AGI protection initialized
