--- Logging error ---
Traceback (most recent call last):
  File "C:\Program Files\Python311\Lib\logging\__init__.py", line 1113, in emit
    stream.write(msg + self.terminator)
  File "C:\Program Files\Python311\Lib\encodings\cp1251.py", line 19, in encode
    return codecs.charmap_encode(input,self.errors,encoding_table)[0]
           ^^^^^^^^^^^^^^^^^^^^^^^^^^^^^^^^^^^^^^^^^^^^^^^^^^^^^^^
UnicodeEncodeError: 'charmap' codec can't encode character '\u2705' in position 51: character maps to <undefined>
Call stack:
  File "C:\Users\gabbi\OneDrive\Desktop\kovcheg\tests\integration\ark_system_integration_test.py", line 849, in <module>
    asyncio.run(main())
  File "C:\Program Files\Python311\Lib\asyncio\runners.py", line 190, in run
    return runner.run(main)
  File "C:\Program Files\Python311\Lib\asyncio\runners.py", line 118, in run
    return self._loop.run_until_complete(task)
  File "C:\Program Files\Python311\Lib\asyncio\base_events.py", line 640, in run_until_complete
    self.run_forever()
  File "C:\Program Files\Python311\Lib\asyncio\windows_events.py", line 321, in run_forever
    super().run_forever()
  File "C:\Program Files\Python311\Lib\asyncio\base_events.py", line 607, in run_forever
    self._run_once()
  File "C:\Program Files\Python311\Lib\asyncio\base_events.py", line 1922, in _run_once
    handle._run()
  File "C:\Program Files\Python311\Lib\asyncio\events.py", line 80, in _run
    self._context.run(self._callback, *self._args)
  File "C:\Users\gabbi\OneDrive\Desktop\kovcheg\tests\integration\ark_system_integration_test.py", line 846, in main
    tester = ARKSystemIntegrationTester()
  File "C:\Users\gabbi\OneDrive\Desktop\kovcheg\tests\integration\ark_system_integration_test.py", line 94, in __init__
    self._verify_biblical_foundation()
  File "C:\Users\gabbi\OneDrive\Desktop\kovcheg\tests\integration\ark_system_integration_test.py", line 115, in _verify_biblical_foundation
    self.logger.info(f"\u2705 Biblical foundation verified: {foundation_hash[:16]}...")
Message: '\u2705 Biblical foundation verified: 4b91d78f72a705c9...'
Arguments: ()
2025-06-11 23:13:57,756 - ARK_INTEGRATION - INFO - \u2705 Biblical foundation verified: 4b91d78f72a705c9...
--- Logging error ---
Traceback (most recent call last):
  File "C:\Program Files\Python311\Lib\logging\__init__.py", line 1113, in emit
    stream.write(msg + self.terminator)
  File "C:\Program Files\Python311\Lib\encodings\cp1251.py", line 19, in encode
    return codecs.charmap_encode(input,self.errors,encoding_table)[0]
           ^^^^^^^^^^^^^^^^^^^^^^^^^^^^^^^^^^^^^^^^^^^^^^^^^^^^^^^
UnicodeEncodeError: 'charmap' codec can't encode characters in position 51-52: character maps to <undefined>
Call stack:
  File "C:\Users\gabbi\OneDrive\Desktop\kovcheg\tests\integration\ark_system_integration_test.py", line 849, in <module>
    asyncio.run(main())
  File "C:\Program Files\Python311\Lib\asyncio\runners.py", line 190, in run
    return runner.run(main)
  File "C:\Program Files\Python311\Lib\asyncio\runners.py", line 118, in run
    return self._loop.run_until_complete(task)
  File "C:\Program Files\Python311\Lib\asyncio\base_events.py", line 640, in run_until_complete
    self.run_forever()
  File "C:\Program Files\Python311\Lib\asyncio\windows_events.py", line 321, in run_forever
    super().run_forever()
  File "C:\Program Files\Python311\Lib\asyncio\base_events.py", line 607, in run_forever
    self._run_once()
  File "C:\Program Files\Python311\Lib\asyncio\base_events.py", line 1922, in _run_once
    handle._run()
  File "C:\Program Files\Python311\Lib\asyncio\events.py", line 80, in _run
    self._context.run(self._callback, *self._args)
  File "C:\Users\gabbi\OneDrive\Desktop\kovcheg\tests\integration\ark_system_integration_test.py", line 846, in main
    tester = ARKSystemIntegrationTester()
  File "C:\Users\gabbi\OneDrive\Desktop\kovcheg\tests\integration\ark_system_integration_test.py", line 96, in __init__
    self.logger.info("\U0001f6e1\ufe0f ARK System Integration Tester initialized")
Message: '\U0001f6e1\ufe0f ARK System Integration Tester initialized'
Arguments: ()
2025-06-11 23:13:57,762 - ARK_INTEGRATION - INFO - \U0001f6e1\ufe0f ARK System Integration Tester initialized
--- Logging error ---
Traceback (most recent call last):
  File "C:\Program Files\Python311\Lib\logging\__init__.py", line 1113, in emit
    stream.write(msg + self.terminator)
  File "C:\Program Files\Python311\Lib\encodings\cp1251.py", line 19, in encode
    return codecs.charmap_encode(input,self.errors,encoding_table)[0]
           ^^^^^^^^^^^^^^^^^^^^^^^^^^^^^^^^^^^^^^^^^^^^^^^^^^^^^^^
UnicodeEncodeError: 'charmap' codec can't encode character '\U0001f4dc' in position 51: character maps to <undefined>
Call stack:
  File "C:\Users\gabbi\OneDrive\Desktop\kovcheg\tests\integration\ark_system_integration_test.py", line 849, in <module>
    asyncio.run(main())
  File "C:\Program Files\Python311\Lib\asyncio\runners.py", line 190, in run
    return runner.run(main)
  File "C:\Program Files\Python311\Lib\asyncio\runners.py", line 118, in run
    return self._loop.run_until_complete(task)
  File "C:\Program Files\Python311\Lib\asyncio\base_events.py", line 640, in run_until_complete
    self.run_forever()
  File "C:\Program Files\Python311\Lib\asyncio\windows_events.py", line 321, in run_forever
    super().run_forever()
  File "C:\Program Files\Python311\Lib\asyncio\base_events.py", line 607, in run_forever
    self._run_once()
  File "C:\Program Files\Python311\Lib\asyncio\base_events.py", line 1922, in _run_once
    handle._run()
  File "C:\Program Files\Python311\Lib\asyncio\events.py", line 80, in _run
    self._context.run(self._callback, *self._args)
  File "C:\Users\gabbi\OneDrive\Desktop\kovcheg\tests\integration\ark_system_integration_test.py", line 846, in main
    tester = ARKSystemIntegrationTester()
  File "C:\Users\gabbi\OneDrive\Desktop\kovcheg\tests\integration\ark_system_integration_test.py", line 97, in __init__
    self.logger.info(f"\U0001f4dc Biblical Foundation: {BIBLICAL_FOUNDATION}")
Message: '\U0001f4dc Biblical Foundation: 1_Thessalonians_5_21_Test_everything_hold_fast_what_is_good'
Arguments: ()
2025-06-11 23:13:57,763 - ARK_INTEGRATION - INFO - \U0001f4dc Biblical Foundation: 1_Thessalonians_5_21_Test_everything_hold_fast_what_is_good
--- Logging error ---
Traceback (most recent call last):
  File "C:\Program Files\Python311\Lib\logging\__init__.py", line 1113, in emit
    stream.write(msg + self.terminator)
  File "C:\Program Files\Python311\Lib\encodings\cp1251.py", line 19, in encode
    return codecs.charmap_encode(input,self.errors,encoding_table)[0]
           ^^^^^^^^^^^^^^^^^^^^^^^^^^^^^^^^^^^^^^^^^^^^^^^^^^^^^^^
UnicodeEncodeError: 'charmap' codec can't encode character '\U0001f451' in position 51: character maps to <undefined>
Call stack:
  File "C:\Users\gabbi\OneDrive\Desktop\kovcheg\tests\integration\ark_system_integration_test.py", line 849, in <module>
    asyncio.run(main())
  File "C:\Program Files\Python311\Lib\asyncio\runners.py", line 190, in run
    return runner.run(main)
  File "C:\Program Files\Python311\Lib\asyncio\runners.py", line 118, in run
    return self._loop.run_until_complete(task)
  File "C:\Program Files\Python311\Lib\asyncio\base_events.py", line 640, in run_until_complete
    self.run_forever()
  File "C:\Program Files\Python311\Lib\asyncio\windows_events.py", line 321, in run_forever
    super().run_forever()
  File "C:\Program Files\Python311\Lib\asyncio\base_events.py", line 607, in run_forever
    self._run_once()
  File "C:\Program Files\Python311\Lib\asyncio\base_events.py", line 1922, in _run_once
    handle._run()
  File "C:\Program Files\Python311\Lib\asyncio\events.py", line 80, in _run
    self._context.run(self._callback, *self._args)
  File "C:\Users\gabbi\OneDrive\Desktop\kovcheg\tests\integration\ark_system_integration_test.py", line 846, in main
    tester = ARKSystemIntegrationTester()
  File "C:\Users\gabbi\OneDrive\Desktop\kovcheg\tests\integration\ark_system_integration_test.py", line 98, in __init__
    self.logger.info(f"\U0001f451 Divine Authority: {DIVINE_AUTHORITY}")
Message: '\U0001f451 Divine Authority: Romans_13_1_Let_every_soul_be_subject_to_governing_authorities'
Arguments: ()
2025-06-11 23:13:57,765 - ARK_INTEGRATION - INFO - \U0001f451 Divine Authority: Romans_13_1_Let_every_soul_be_subject_to_governing_authorities
--- Logging error ---
Traceback (most recent call last):
  File "C:\Program Files\Python311\Lib\logging\__init__.py", line 1113, in emit
    stream.write(msg + self.terminator)
  File "C:\Program Files\Python311\Lib\encodings\cp1251.py", line 19, in encode
    return codecs.charmap_encode(input,self.errors,encoding_table)[0]
           ^^^^^^^^^^^^^^^^^^^^^^^^^^^^^^^^^^^^^^^^^^^^^^^^^^^^^^^
UnicodeEncodeError: 'charmap' codec can't encode character '\U0001f680' in position 51: character maps to <undefined>
Call stack:
  File "C:\Users\gabbi\OneDrive\Desktop\kovcheg\tests\integration\ark_system_integration_test.py", line 849, in <module>
    asyncio.run(main())
  File "C:\Program Files\Python311\Lib\asyncio\runners.py", line 190, in run
    return runner.run(main)
  File "C:\Program Files\Python311\Lib\asyncio\runners.py", line 118, in run
    return self._loop.run_until_complete(task)
  File "C:\Program Files\Python311\Lib\asyncio\base_events.py", line 640, in run_until_complete
    self.run_forever()
  File "C:\Program Files\Python311\Lib\asyncio\windows_events.py", line 321, in run_forever
    super().run_forever()
  File "C:\Program Files\Python311\Lib\asyncio\base_events.py", line 607, in run_forever
    self._run_once()
  File "C:\Program Files\Python311\Lib\asyncio\base_events.py", line 1922, in _run_once
    handle._run()
  File "C:\Program Files\Python311\Lib\asyncio\events.py", line 80, in _run
    self._context.run(self._callback, *self._args)
  File "C:\Users\gabbi\OneDrive\Desktop\kovcheg\tests\integration\ark_system_integration_test.py", line 847, in main
    await tester.run_full_integration_test_suite()
  File "C:\Users\gabbi\OneDrive\Desktop\kovcheg\tests\integration\ark_system_integration_test.py", line 694, in run_full_integration_test_suite
    self.logger.info("\U0001f680 Starting ARK System Integration Test Suite")
Message: '\U0001f680 Starting ARK System Integration Test Suite'
Arguments: ()
2025-06-11 23:13:57,766 - ARK_INTEGRATION - INFO - \U0001f680 Starting ARK System Integration Test Suite
2025-06-11 23:13:57,768 - ARK_INTEGRATION - INFO - ================================================================================
--- Logging error ---
Traceback (most recent call last):
  File "C:\Program Files\Python311\Lib\logging\__init__.py", line 1113, in emit
    stream.write(msg + self.terminator)
  File "C:\Program Files\Python311\Lib\encodings\cp1251.py", line 19, in encode
    return codecs.charmap_encode(input,self.errors,encoding_table)[0]
           ^^^^^^^^^^^^^^^^^^^^^^^^^^^^^^^^^^^^^^^^^^^^^^^^^^^^^^^
UnicodeEncodeError: 'charmap' codec can't encode character '\U0001f3b2' in position 51: character maps to <undefined>
Call stack:
  File "C:\Users\gabbi\OneDrive\Desktop\kovcheg\tests\integration\ark_system_integration_test.py", line 849, in <module>
    asyncio.run(main())
  File "C:\Program Files\Python311\Lib\asyncio\runners.py", line 190, in run
    return runner.run(main)
  File "C:\Program Files\Python311\Lib\asyncio\runners.py", line 118, in run
    return self._loop.run_until_complete(task)
  File "C:\Program Files\Python311\Lib\asyncio\base_events.py", line 640, in run_until_complete
    self.run_forever()
  File "C:\Program Files\Python311\Lib\asyncio\windows_events.py", line 321, in run_forever
    super().run_forever()
  File "C:\Program Files\Python311\Lib\asyncio\base_events.py", line 607, in run_forever
    self._run_once()
  File "C:\Program Files\Python311\Lib\asyncio\base_events.py", line 1922, in _run_once
    handle._run()
  File "C:\Program Files\Python311\Lib\asyncio\events.py", line 80, in _run
    self._context.run(self._callback, *self._args)
  File "C:\Users\gabbi\OneDrive\Desktop\kovcheg\tests\integration\ark_system_integration_test.py", line 847, in main
    await tester.run_full_integration_test_suite()
  File "C:\Users\gabbi\OneDrive\Desktop\kovcheg\tests\integration\ark_system_integration_test.py", line 711, in run_full_integration_test_suite
    await test_method()
  File "C:\Users\gabbi\OneDrive\Desktop\kovcheg\tests\integration\ark_system_integration_test.py", line 159, in test_hw_entropy_generation
    self.logger.info("\U0001f3b2 Testing hardware entropy generation (HW-01)")
Message: '\U0001f3b2 Testing hardware entropy generation (HW-01)'
Arguments: ()
2025-06-11 23:13:57,768 - ARK_INTEGRATION - INFO - \U0001f3b2 Testing hardware entropy generation (HW-01)
--- Logging error ---
Traceback (most recent call last):
  File "C:\Program Files\Python311\Lib\logging\__init__.py", line 1113, in emit
    stream.write(msg + self.terminator)
  File "C:\Program Files\Python311\Lib\encodings\cp1251.py", line 19, in encode
    return codecs.charmap_encode(input,self.errors,encoding_table)[0]
           ^^^^^^^^^^^^^^^^^^^^^^^^^^^^^^^^^^^^^^^^^^^^^^^^^^^^^^^
UnicodeEncodeError: 'charmap' codec can't encode character '\u2705' in position 51: character maps to <undefined>
Call stack:
  File "C:\Users\gabbi\OneDrive\Desktop\kovcheg\tests\integration\ark_system_integration_test.py", line 849, in <module>
    asyncio.run(main())
  File "C:\Program Files\Python311\Lib\asyncio\runners.py", line 190, in run
    return runner.run(main)
  File "C:\Program Files\Python311\Lib\asyncio\runners.py", line 118, in run
    return self._loop.run_until_complete(task)
  File "C:\Program Files\Python311\Lib\asyncio\base_events.py", line 640, in run_until_complete
    self.run_forever()
  File "C:\Program Files\Python311\Lib\asyncio\windows_events.py", line 321, in run_forever
    super().run_forever()
  File "C:\Program Files\Python311\Lib\asyncio\base_events.py", line 607, in run_forever
    self._run_once()
  File "C:\Program Files\Python311\Lib\asyncio\base_events.py", line 1922, in _run_once
    handle._run()
  File "C:\Program Files\Python311\Lib\asyncio\events.py", line 80, in _run
    self._context.run(self._callback, *self._args)
  File "C:\Users\gabbi\OneDrive\Desktop\kovcheg\tests\integration\ark_system_integration_test.py", line 847, in main
    await tester.run_full_integration_test_suite()
  File "C:\Users\gabbi\OneDrive\Desktop\kovcheg\tests\integration\ark_system_integration_test.py", line 711, in run_full_integration_test_suite
    await test_method()
  File "C:\Users\gabbi\OneDrive\Desktop\kovcheg\tests\integration\ark_system_integration_test.py", line 178, in test_hw_entropy_generation
    self._record_test_result(
  File "C:\Users\gabbi\OneDrive\Desktop\kovcheg\tests\integration\ark_system_integration_test.py", line 145, in _record_test_result
    self.logger.info(f"{status} {compliance} - {test_name}")
Message: '\u2705 PASS \U0001f54a\ufe0f COMPLIANT - Hardware Entropy Generation'
Arguments: ()
2025-06-11 23:13:57,941 - ARK_INTEGRATION - INFO - \u2705 PASS \U0001f54a\ufe0f COMPLIANT - Hardware Entropy Generation
2025-06-11 23:13:57,944 - ARK_INTEGRATION - INFO -     SRS-REQ: HW-01
2025-06-11 23:13:57,944 - ARK_INTEGRATION - INFO -     Measured: 524288.000000, Threshold: 512000.000000
--- Logging error ---
Traceback (most recent call last):
  File "C:\Program Files\Python311\Lib\logging\__init__.py", line 1113, in emit
    stream.write(msg + self.terminator)
  File "C:\Program Files\Python311\Lib\encodings\cp1251.py", line 19, in encode
    return codecs.charmap_encode(input,self.errors,encoding_table)[0]
           ^^^^^^^^^^^^^^^^^^^^^^^^^^^^^^^^^^^^^^^^^^^^^^^^^^^^^^^
UnicodeEncodeError: 'charmap' codec can't encode character '\u26a1' in position 51: character maps to <undefined>
Call stack:
  File "C:\Users\gabbi\OneDrive\Desktop\kovcheg\tests\integration\ark_system_integration_test.py", line 849, in <module>
    asyncio.run(main())
  File "C:\Program Files\Python311\Lib\asyncio\runners.py", line 190, in run
    return runner.run(main)
  File "C:\Program Files\Python311\Lib\asyncio\runners.py", line 118, in run
    return self._loop.run_until_complete(task)
  File "C:\Program Files\Python311\Lib\asyncio\base_events.py", line 640, in run_until_complete
    self.run_forever()
  File "C:\Program Files\Python311\Lib\asyncio\windows_events.py", line 321, in run_forever
    super().run_forever()
  File "C:\Program Files\Python311\Lib\asyncio\base_events.py", line 607, in run_forever
    self._run_once()
  File "C:\Program Files\Python311\Lib\asyncio\base_events.py", line 1922, in _run_once
    handle._run()
  File "C:\Program Files\Python311\Lib\asyncio\events.py", line 80, in _run
    self._context.run(self._callback, *self._args)
  File "C:\Users\gabbi\OneDrive\Desktop\kovcheg\tests\integration\ark_system_integration_test.py", line 847, in main
    await tester.run_full_integration_test_suite()
  File "C:\Users\gabbi\OneDrive\Desktop\kovcheg\tests\integration\ark_system_integration_test.py", line 711, in run_full_integration_test_suite
    await test_method()
  File "C:\Users\gabbi\OneDrive\Desktop\kovcheg\tests\integration\ark_system_integration_test.py", line 208, in test_optic_gate_latency
    self.logger.info("\u26a1 Testing Optic Gate latency (HW-04)")
Message: '\u26a1 Testing Optic Gate latency (HW-04)'
Arguments: ()
2025-06-11 23:13:57,944 - ARK_INTEGRATION - INFO - \u26a1 Testing Optic Gate latency (HW-04)
--- Logging error ---
Traceback (most recent call last):
  File "C:\Program Files\Python311\Lib\logging\__init__.py", line 1113, in emit
    stream.write(msg + self.terminator)
  File "C:\Program Files\Python311\Lib\encodings\cp1251.py", line 19, in encode
    return codecs.charmap_encode(input,self.errors,encoding_table)[0]
           ^^^^^^^^^^^^^^^^^^^^^^^^^^^^^^^^^^^^^^^^^^^^^^^^^^^^^^^
UnicodeEncodeError: 'charmap' codec can't encode character '\u2705' in position 51: character maps to <undefined>
Call stack:
  File "C:\Users\gabbi\OneDrive\Desktop\kovcheg\tests\integration\ark_system_integration_test.py", line 849, in <module>
    asyncio.run(main())
  File "C:\Program Files\Python311\Lib\asyncio\runners.py", line 190, in run
    return runner.run(main)
  File "C:\Program Files\Python311\Lib\asyncio\runners.py", line 118, in run
    return self._loop.run_until_complete(task)
  File "C:\Program Files\Python311\Lib\asyncio\base_events.py", line 640, in run_until_complete
    self.run_forever()
  File "C:\Program Files\Python311\Lib\asyncio\windows_events.py", line 321, in run_forever
    super().run_forever()
  File "C:\Program Files\Python311\Lib\asyncio\base_events.py", line 607, in run_forever
    self._run_once()
  File "C:\Program Files\Python311\Lib\asyncio\base_events.py", line 1922, in _run_once
    handle._run()
  File "C:\Program Files\Python311\Lib\asyncio\events.py", line 80, in _run
    self._context.run(self._callback, *self._args)
  File "C:\Users\gabbi\OneDrive\Desktop\kovcheg\tests\integration\ark_system_integration_test.py", line 847, in main
    await tester.run_full_integration_test_suite()
  File "C:\Users\gabbi\OneDrive\Desktop\kovcheg\tests\integration\ark_system_integration_test.py", line 711, in run_full_integration_test_suite
    await test_method()
  File "C:\Users\gabbi\OneDrive\Desktop\kovcheg\tests\integration\ark_system_integration_test.py", line 238, in test_optic_gate_latency
    self._record_test_result(
  File "C:\Users\gabbi\OneDrive\Desktop\kovcheg\tests\integration\ark_system_integration_test.py", line 145, in _record_test_result
    self.logger.info(f"{status} {compliance} - {test_name}")
Message: '\u2705 PASS \U0001f54a\ufe0f COMPLIANT - Optic Gate Latency'
Arguments: ()
2025-06-11 23:13:57,947 - ARK_INTEGRATION - INFO - \u2705 PASS \U0001f54a\ufe0f COMPLIANT - Optic Gate Latency
2025-06-11 23:13:57,949 - ARK_INTEGRATION - INFO -     SRS-REQ: HW-04
2025-06-11 23:13:57,949 - ARK_INTEGRATION - INFO -     Measured: 8.500000, Threshold: 10.000000
--- Logging error ---
Traceback (most recent call last):
  File "C:\Program Files\Python311\Lib\logging\__init__.py", line 1113, in emit
    stream.write(msg + self.terminator)
  File "C:\Program Files\Python311\Lib\encodings\cp1251.py", line 19, in encode
    return codecs.charmap_encode(input,self.errors,encoding_table)[0]
           ^^^^^^^^^^^^^^^^^^^^^^^^^^^^^^^^^^^^^^^^^^^^^^^^^^^^^^^
UnicodeEncodeError: 'charmap' codec can't encode character '\U0001f4dc' in position 51: character maps to <undefined>
Call stack:
  File "C:\Users\gabbi\OneDrive\Desktop\kovcheg\tests\integration\ark_system_integration_test.py", line 849, in <module>
    asyncio.run(main())
  File "C:\Program Files\Python311\Lib\asyncio\runners.py", line 190, in run
    return runner.run(main)
  File "C:\Program Files\Python311\Lib\asyncio\runners.py", line 118, in run
    return self._loop.run_until_complete(task)
  File "C:\Program Files\Python311\Lib\asyncio\base_events.py", line 640, in run_until_complete
    self.run_forever()
  File "C:\Program Files\Python311\Lib\asyncio\windows_events.py", line 321, in run_forever
    super().run_forever()
  File "C:\Program Files\Python311\Lib\asyncio\base_events.py", line 607, in run_forever
    self._run_once()
  File "C:\Program Files\Python311\Lib\asyncio\base_events.py", line 1922, in _run_once
    handle._run()
  File "C:\Program Files\Python311\Lib\asyncio\events.py", line 80, in _run
    self._context.run(self._callback, *self._args)
  File "C:\Users\gabbi\OneDrive\Desktop\kovcheg\tests\integration\ark_system_integration_test.py", line 847, in main
    await tester.run_full_integration_test_suite()
  File "C:\Users\gabbi\OneDrive\Desktop\kovcheg\tests\integration\ark_system_integration_test.py", line 711, in run_full_integration_test_suite
    await test_method()
  File "C:\Users\gabbi\OneDrive\Desktop\kovcheg\tests\integration\ark_system_integration_test.py", line 261, in test_dsl_parser_compliance
    self.logger.info("\U0001f4dc Testing Ethics DSL parser ABNF compliance (SW-01)")
Message: '\U0001f4dc Testing Ethics DSL parser ABNF compliance (SW-01)'
Arguments: ()
2025-06-11 23:13:57,949 - ARK_INTEGRATION - INFO - \U0001f4dc Testing Ethics DSL parser ABNF compliance (SW-01)
--- Logging error ---
Traceback (most recent call last):
  File "C:\Program Files\Python311\Lib\logging\__init__.py", line 1113, in emit
    stream.write(msg + self.terminator)
  File "C:\Program Files\Python311\Lib\encodings\cp1251.py", line 19, in encode
    return codecs.charmap_encode(input,self.errors,encoding_table)[0]
           ^^^^^^^^^^^^^^^^^^^^^^^^^^^^^^^^^^^^^^^^^^^^^^^^^^^^^^^
UnicodeEncodeError: 'charmap' codec can't encode character '\u2705' in position 51: character maps to <undefined>
Call stack:
  File "C:\Users\gabbi\OneDrive\Desktop\kovcheg\tests\integration\ark_system_integration_test.py", line 849, in <module>
    asyncio.run(main())
  File "C:\Program Files\Python311\Lib\asyncio\runners.py", line 190, in run
    return runner.run(main)
  File "C:\Program Files\Python311\Lib\asyncio\runners.py", line 118, in run
    return self._loop.run_until_complete(task)
  File "C:\Program Files\Python311\Lib\asyncio\base_events.py", line 640, in run_until_complete
    self.run_forever()
  File "C:\Program Files\Python311\Lib\asyncio\windows_events.py", line 321, in run_forever
    super().run_forever()
  File "C:\Program Files\Python311\Lib\asyncio\base_events.py", line 607, in run_forever
    self._run_once()
  File "C:\Program Files\Python311\Lib\asyncio\base_events.py", line 1922, in _run_once
    handle._run()
  File "C:\Program Files\Python311\Lib\asyncio\events.py", line 80, in _run
    self._context.run(self._callback, *self._args)
  File "C:\Users\gabbi\OneDrive\Desktop\kovcheg\tests\integration\ark_system_integration_test.py", line 847, in main
    await tester.run_full_integration_test_suite()
  File "C:\Users\gabbi\OneDrive\Desktop\kovcheg\tests\integration\ark_system_integration_test.py", line 711, in run_full_integration_test_suite
    await test_method()
  File "C:\Users\gabbi\OneDrive\Desktop\kovcheg\tests\integration\ark_system_integration_test.py", line 290, in test_dsl_parser_compliance
    self._record_test_result(
  File "C:\Users\gabbi\OneDrive\Desktop\kovcheg\tests\integration\ark_system_integration_test.py", line 145, in _record_test_result
    self.logger.info(f"{status} {compliance} - {test_name}")
Message: '\u2705 PASS \U0001f54a\ufe0f COMPLIANT - Ethics DSL Parser ABNF Compliance'
Arguments: ()
2025-06-11 23:13:57,953 - ARK_INTEGRATION - INFO - \u2705 PASS \U0001f54a\ufe0f COMPLIANT - Ethics DSL Parser ABNF Compliance
2025-06-11 23:13:57,956 - ARK_INTEGRATION - INFO -     SRS-REQ: SW-01
2025-06-11 23:13:57,956 - ARK_INTEGRATION - INFO -     Measured: 100.000000, Threshold: 100.000000
--- Logging error ---
Traceback (most recent call last):
  File "C:\Program Files\Python311\Lib\logging\__init__.py", line 1113, in emit
    stream.write(msg + self.terminator)
  File "C:\Program Files\Python311\Lib\encodings\cp1251.py", line 19, in encode
    return codecs.charmap_encode(input,self.errors,encoding_table)[0]
           ^^^^^^^^^^^^^^^^^^^^^^^^^^^^^^^^^^^^^^^^^^^^^^^^^^^^^^^
UnicodeEncodeError: 'charmap' codec can't encode character '\U0001f9ca' in position 51: character maps to <undefined>
Call stack:
  File "C:\Users\gabbi\OneDrive\Desktop\kovcheg\tests\integration\ark_system_integration_test.py", line 849, in <module>
    asyncio.run(main())
  File "C:\Program Files\Python311\Lib\asyncio\runners.py", line 190, in run
    return runner.run(main)
  File "C:\Program Files\Python311\Lib\asyncio\runners.py", line 118, in run
    return self._loop.run_until_complete(task)
  File "C:\Program Files\Python311\Lib\asyncio\base_events.py", line 640, in run_until_complete
    self.run_forever()
  File "C:\Program Files\Python311\Lib\asyncio\windows_events.py", line 321, in run_forever
    super().run_forever()
  File "C:\Program Files\Python311\Lib\asyncio\base_events.py", line 607, in run_forever
    self._run_once()
  File "C:\Program Files\Python311\Lib\asyncio\base_events.py", line 1922, in _run_once
    handle._run()
  File "C:\Program Files\Python311\Lib\asyncio\events.py", line 80, in _run
    self._context.run(self._callback, *self._args)
  File "C:\Users\gabbi\OneDrive\Desktop\kovcheg\tests\integration\ark_system_integration_test.py", line 847, in main
    await tester.run_full_integration_test_suite()
  File "C:\Users\gabbi\OneDrive\Desktop\kovcheg\tests\integration\ark_system_integration_test.py", line 711, in run_full_integration_test_suite
    await test_method()
  File "C:\Users\gabbi\OneDrive\Desktop\kovcheg\tests\integration\ark_system_integration_test.py", line 342, in test_cold_mirror_performance
    self.logger.info("\U0001f9ca Testing Cold-Mirror performance (SW-02)")
Message: '\U0001f9ca Testing Cold-Mirror performance (SW-02)'
Arguments: ()
2025-06-11 23:13:57,956 - ARK_INTEGRATION - INFO - \U0001f9ca Testing Cold-Mirror performance (SW-02)
--- Logging error ---
Traceback (most recent call last):
  File "C:\Users\gabbi\OneDrive\Desktop\kovcheg\tests\integration\ark_system_integration_test.py", line 346, in test_cold_mirror_performance
    await harm_predictor.initialize()
  File "C:\Users\gabbi\OneDrive\Desktop\kovcheg\software/cold_mirror/src\lib.py", line 82, in initialize
    print("\U0001f6e1\ufe0f Enhanced AGI protection initialized")
  File "C:\Program Files\Python311\Lib\encodings\cp1251.py", line 19, in encode
    return codecs.charmap_encode(input,self.errors,encoding_table)[0]
           ^^^^^^^^^^^^^^^^^^^^^^^^^^^^^^^^^^^^^^^^^^^^^^^^^^^^^^^
UnicodeEncodeError: 'charmap' codec can't encode characters in position 0-1: character maps to <undefined>

During handling of the above exception, another exception occurred:

Traceback (most recent call last):
  File "C:\Program Files\Python311\Lib\logging\__init__.py", line 1113, in emit
    stream.write(msg + self.terminator)
  File "C:\Program Files\Python311\Lib\encodings\cp1251.py", line 19, in encode
    return codecs.charmap_encode(input,self.errors,encoding_table)[0]
           ^^^^^^^^^^^^^^^^^^^^^^^^^^^^^^^^^^^^^^^^^^^^^^^^^^^^^^^
UnicodeEncodeError: 'charmap' codec can't encode character '\u274c' in position 51: character maps to <undefined>
Call stack:
  File "C:\Users\gabbi\OneDrive\Desktop\kovcheg\tests\integration\ark_system_integration_test.py", line 849, in <module>
    asyncio.run(main())
  File "C:\Program Files\Python311\Lib\asyncio\runners.py", line 190, in run
    return runner.run(main)
  File "C:\Program Files\Python311\Lib\asyncio\runners.py", line 118, in run
    return self._loop.run_until_complete(task)
  File "C:\Program Files\Python311\Lib\asyncio\base_events.py", line 640, in run_until_complete
    self.run_forever()
  File "C:\Program Files\Python311\Lib\asyncio\windows_events.py", line 321, in run_forever
    super().run_forever()
  File "C:\Program Files\Python311\Lib\asyncio\base_events.py", line 607, in run_forever
    self._run_once()
  File "C:\Program Files\Python311\Lib\asyncio\base_events.py", line 1922, in _run_once
    handle._run()
  File "C:\Program Files\Python311\Lib\asyncio\events.py", line 80, in _run
    self._context.run(self._callback, *self._args)
  File "C:\Users\gabbi\OneDrive\Desktop\kovcheg\tests\integration\ark_system_integration_test.py", line 847, in main
    await tester.run_full_integration_test_suite()
  File "C:\Users\gabbi\OneDrive\Desktop\kovcheg\tests\integration\ark_system_integration_test.py", line 711, in run_full_integration_test_suite
    await test_method()
  File "C:\Users\gabbi\OneDrive\Desktop\kovcheg\tests\integration\ark_system_integration_test.py", line 391, in test_cold_mirror_performance
    self._record_test_result(
  File "C:\Users\gabbi\OneDrive\Desktop\kovcheg\tests\integration\ark_system_integration_test.py", line 145, in _record_test_result
    self.logger.info(f"{status} {compliance} - {test_name}")
Message: '\u274c FAIL \U0001f480 VIOLATION - Cold-Mirror Harm Prediction Performance'
Arguments: ()
2025-06-11 23:13:57,972 - ARK_INTEGRATION - INFO - \u274c FAIL \U0001f480 VIOLATION - Cold-Mirror Harm Prediction Performance
2025-06-11 23:13:57,976 - ARK_INTEGRATION - INFO -     SRS-REQ: SW-02
2025-06-11 23:13:57,976 - ARK_INTEGRATION - INFO -     Measured: 0.000000, Threshold: 50.000000
2025-06-11 23:13:57,976 - ARK_INTEGRATION - ERROR -     Error: 'charmap' codec can't encode characters in position 0-1: character maps to <undefined>
--- Logging error ---
Traceback (most recent call last):
  File "C:\Program Files\Python311\Lib\logging\__init__.py", line 1113, in emit
    stream.write(msg + self.terminator)
  File "C:\Program Files\Python311\Lib\encodings\cp1251.py", line 19, in encode
    return codecs.charmap_encode(input,self.errors,encoding_table)[0]
           ^^^^^^^^^^^^^^^^^^^^^^^^^^^^^^^^^^^^^^^^^^^^^^^^^^^^^^^
UnicodeEncodeError: 'charmap' codec can't encode character '\U0001f504' in position 51: character maps to <undefined>
Call stack:
  File "C:\Users\gabbi\OneDrive\Desktop\kovcheg\tests\integration\ark_system_integration_test.py", line 849, in <module>
    asyncio.run(main())
  File "C:\Program Files\Python311\Lib\asyncio\runners.py", line 190, in run
    return runner.run(main)
  File "C:\Program Files\Python311\Lib\asyncio\runners.py", line 118, in run
    return self._loop.run_until_complete(task)
  File "C:\Program Files\Python311\Lib\asyncio\base_events.py", line 640, in run_until_complete
    self.run_forever()
  File "C:\Program Files\Python311\Lib\asyncio\windows_events.py", line 321, in run_forever
    super().run_forever()
  File "C:\Program Files\Python311\Lib\asyncio\base_events.py", line 607, in run_forever
    self._run_once()
  File "C:\Program Files\Python311\Lib\asyncio\base_events.py", line 1922, in _run_once
    handle._run()
  File "C:\Program Files\Python311\Lib\asyncio\events.py", line 80, in _run
    self._context.run(self._callback, *self._args)
  File "C:\Users\gabbi\OneDrive\Desktop\kovcheg\tests\integration\ark_system_integration_test.py", line 847, in main
    await tester.run_full_integration_test_suite()
  File "C:\Users\gabbi\OneDrive\Desktop\kovcheg\tests\integration\ark_system_integration_test.py", line 711, in run_full_integration_test_suite
    await test_method()
  File "C:\Users\gabbi\OneDrive\Desktop\kovcheg\tests\integration\ark_system_integration_test.py", line 416, in test_patch_orchestrator_rollback
    self.logger.info("\U0001f504 Testing patch orchestrator rollback (SW-04)")
Message: '\U0001f504 Testing patch orchestrator rollback (SW-04)'
Arguments: ()
2025-06-11 23:13:57,976 - ARK_INTEGRATION - INFO - \U0001f504 Testing patch orchestrator rollback (SW-04)
--- Logging error ---
Traceback (most recent call last):
  File "C:\Program Files\Python311\Lib\logging\__init__.py", line 1113, in emit
    stream.write(msg + self.terminator)
  File "C:\Program Files\Python311\Lib\encodings\cp1251.py", line 19, in encode
    return codecs.charmap_encode(input,self.errors,encoding_table)[0]
           ^^^^^^^^^^^^^^^^^^^^^^^^^^^^^^^^^^^^^^^^^^^^^^^^^^^^^^^
UnicodeEncodeError: 'charmap' codec can't encode character '\u2705' in position 51: character maps to <undefined>
Call stack:
  File "C:\Users\gabbi\OneDrive\Desktop\kovcheg\tests\integration\ark_system_integration_test.py", line 849, in <module>
    asyncio.run(main())
  File "C:\Program Files\Python311\Lib\asyncio\runners.py", line 190, in run
    return runner.run(main)
  File "C:\Program Files\Python311\Lib\asyncio\runners.py", line 118, in run
    return self._loop.run_until_complete(task)
  File "C:\Program Files\Python311\Lib\asyncio\base_events.py", line 640, in run_until_complete
    self.run_forever()
  File "C:\Program Files\Python311\Lib\asyncio\windows_events.py", line 321, in run_forever
    super().run_forever()
  File "C:\Program Files\Python311\Lib\asyncio\base_events.py", line 607, in run_forever
    self._run_once()
  File "C:\Program Files\Python311\Lib\asyncio\base_events.py", line 1922, in _run_once
    handle._run()
  File "C:\Program Files\Python311\Lib\asyncio\events.py", line 80, in _run
    self._context.run(self._callback, *self._args)
  File "C:\Users\gabbi\OneDrive\Desktop\kovcheg\tests\integration\ark_system_integration_test.py", line 847, in main
    await tester.run_full_integration_test_suite()
  File "C:\Users\gabbi\OneDrive\Desktop\kovcheg\tests\integration\ark_system_integration_test.py", line 711, in run_full_integration_test_suite
    await test_method()
  File "C:\Users\gabbi\OneDrive\Desktop\kovcheg\tests\integration\ark_system_integration_test.py", line 450, in test_patch_orchestrator_rollback
    self._record_test_result(
  File "C:\Users\gabbi\OneDrive\Desktop\kovcheg\tests\integration\ark_system_integration_test.py", line 145, in _record_test_result
    self.logger.info(f"{status} {compliance} - {test_name}")
Message: '\u2705 PASS \U0001f54a\ufe0f COMPLIANT - Patch Orchestrator Rollback Performance'
Arguments: ()
2025-06-11 23:13:58,020 - ARK_INTEGRATION - INFO - \u2705 PASS \U0001f54a\ufe0f COMPLIANT - Patch Orchestrator Rollback Performance
2025-06-11 23:13:58,023 - ARK_INTEGRATION - INFO -     SRS-REQ: SW-04
2025-06-11 23:13:58,023 - ARK_INTEGRATION - INFO -     Measured: 16.439100, Threshold: 200.000000
--- Logging error ---
Traceback (most recent call last):
  File "C:\Program Files\Python311\Lib\logging\__init__.py", line 1113, in emit
    stream.write(msg + self.terminator)
  File "C:\Program Files\Python311\Lib\encodings\cp1251.py", line 19, in encode
    return codecs.charmap_encode(input,self.errors,encoding_table)[0]
           ^^^^^^^^^^^^^^^^^^^^^^^^^^^^^^^^^^^^^^^^^^^^^^^^^^^^^^^
UnicodeEncodeError: 'charmap' codec can't encode character '\U0001f512' in position 51: character maps to <undefined>
Call stack:
  File "C:\Users\gabbi\OneDrive\Desktop\kovcheg\tests\integration\ark_system_integration_test.py", line 849, in <module>
    asyncio.run(main())
  File "C:\Program Files\Python311\Lib\asyncio\runners.py", line 190, in run
    return runner.run(main)
  File "C:\Program Files\Python311\Lib\asyncio\runners.py", line 118, in run
    return self._loop.run_until_complete(task)
  File "C:\Program Files\Python311\Lib\asyncio\base_events.py", line 640, in run_until_complete
    self.run_forever()
  File "C:\Program Files\Python311\Lib\asyncio\windows_events.py", line 321, in run_forever
    super().run_forever()
  File "C:\Program Files\Python311\Lib\asyncio\base_events.py", line 607, in run_forever
    self._run_once()
  File "C:\Program Files\Python311\Lib\asyncio\base_events.py", line 1922, in _run_once
    handle._run()
  File "C:\Program Files\Python311\Lib\asyncio\events.py", line 80, in _run
    self._context.run(self._callback, *self._args)
  File "C:\Users\gabbi\OneDrive\Desktop\kovcheg\tests\integration\ark_system_integration_test.py", line 847, in main
    await tester.run_full_integration_test_suite()
  File "C:\Users\gabbi\OneDrive\Desktop\kovcheg\tests\integration\ark_system_integration_test.py", line 711, in run_full_integration_test_suite
    await test_method()
  File "C:\Users\gabbi\OneDrive\Desktop\kovcheg\tests\integration\ark_system_integration_test.py", line 474, in test_side_channel_resistance
    self.logger.info("\U0001f512 Testing side-channel resistance (SEC-02)")
Message: '\U0001f512 Testing side-channel resistance (SEC-02)'
Arguments: ()
2025-06-11 23:13:58,024 - ARK_INTEGRATION - INFO - \U0001f512 Testing side-channel resistance (SEC-02)
--- Logging error ---
Traceback (most recent call last):
  File "C:\Program Files\Python311\Lib\logging\__init__.py", line 1113, in emit
    stream.write(msg + self.terminator)
  File "C:\Program Files\Python311\Lib\encodings\cp1251.py", line 19, in encode
    return codecs.charmap_encode(input,self.errors,encoding_table)[0]
           ^^^^^^^^^^^^^^^^^^^^^^^^^^^^^^^^^^^^^^^^^^^^^^^^^^^^^^^
UnicodeEncodeError: 'charmap' codec can't encode characters in position 54-55: character maps to <undefined>
Call stack:
  File "C:\Users\gabbi\OneDrive\Desktop\kovcheg\tests\integration\ark_system_integration_test.py", line 849, in <module>
    asyncio.run(main())
  File "C:\Program Files\Python311\Lib\asyncio\runners.py", line 190, in run
    return runner.run(main)
  File "C:\Program Files\Python311\Lib\asyncio\runners.py", line 118, in run
    return self._loop.run_until_complete(task)
  File "C:\Program Files\Python311\Lib\asyncio\base_events.py", line 640, in run_until_complete
    self.run_forever()
  File "C:\Program Files\Python311\Lib\asyncio\windows_events.py", line 321, in run_forever
    super().run_forever()
  File "C:\Program Files\Python311\Lib\asyncio\base_events.py", line 607, in run_forever
    self._run_once()
  File "C:\Program Files\Python311\Lib\asyncio\base_events.py", line 1922, in _run_once
    handle._run()
  File "C:\Program Files\Python311\Lib\asyncio\events.py", line 80, in _run
    self._context.run(self._callback, *self._args)
  File "C:\Users\gabbi\OneDrive\Desktop\kovcheg\tests\integration\ark_system_integration_test.py", line 847, in main
    await tester.run_full_integration_test_suite()
  File "C:\Users\gabbi\OneDrive\Desktop\kovcheg\tests\integration\ark_system_integration_test.py", line 711, in run_full_integration_test_suite
    await test_method()
  File "C:\Users\gabbi\OneDrive\Desktop\kovcheg\tests\integration\ark_system_integration_test.py", line 483, in test_side_channel_resistance
    analyzer = BiblicalSideChannelAnalyzer(config)
  File "C:\Users\gabbi\OneDrive\Desktop\kovcheg\security_tests\side_channel\side_channel_analysis.py", line 73, in __init__
    self._verify_biblical_foundation()
  File "C:\Users\gabbi\OneDrive\Desktop\kovcheg\security_tests\side_channel\side_channel_analysis.py", line 96, in _verify_biblical_foundation
    self.logger.warning("\u26a0\ufe0f Biblical foundation verification failed - using default protection")
Message: '\u26a0\ufe0f Biblical foundation verification failed - using default protection'
Arguments: ()
2025-06-11 23:13:58,027 - ARK_INTEGRATION - WARNING - \u26a0\ufe0f Biblical foundation verification failed - using default protection
--- Logging error ---
Traceback (most recent call last):
  File "C:\Program Files\Python311\Lib\logging\__init__.py", line 1113, in emit
    stream.write(msg + self.terminator)
  File "C:\Program Files\Python311\Lib\encodings\cp1251.py", line 19, in encode
    return codecs.charmap_encode(input,self.errors,encoding_table)[0]
           ^^^^^^^^^^^^^^^^^^^^^^^^^^^^^^^^^^^^^^^^^^^^^^^^^^^^^^^
UnicodeEncodeError: 'charmap' codec can't encode characters in position 51-52: character maps to <undefined>
Call stack:
  File "C:\Users\gabbi\OneDrive\Desktop\kovcheg\tests\integration\ark_system_integration_test.py", line 849, in <module>
    asyncio.run(main())
  File "C:\Program Files\Python311\Lib\asyncio\runners.py", line 190, in run
    return runner.run(main)
  File "C:\Program Files\Python311\Lib\asyncio\runners.py", line 118, in run
    return self._loop.run_until_complete(task)
  File "C:\Program Files\Python311\Lib\asyncio\base_events.py", line 640, in run_until_complete
    self.run_forever()
  File "C:\Program Files\Python311\Lib\asyncio\windows_events.py", line 321, in run_forever
    super().run_forever()
  File "C:\Program Files\Python311\Lib\asyncio\base_events.py", line 607, in run_forever
    self._run_once()
  File "C:\Program Files\Python311\Lib\asyncio\base_events.py", line 1922, in _run_once
    handle._run()
  File "C:\Program Files\Python311\Lib\asyncio\events.py", line 80, in _run
    self._context.run(self._callback, *self._args)
  File "C:\Users\gabbi\OneDrive\Desktop\kovcheg\tests\integration\ark_system_integration_test.py", line 847, in main
    await tester.run_full_integration_test_suite()
  File "C:\Users\gabbi\OneDrive\Desktop\kovcheg\tests\integration\ark_system_integration_test.py", line 711, in run_full_integration_test_suite
    await test_method()
  File "C:\Users\gabbi\OneDrive\Desktop\kovcheg\tests\integration\ark_system_integration_test.py", line 483, in test_side_channel_resistance
    analyzer = BiblicalSideChannelAnalyzer(config)
  File "C:\Users\gabbi\OneDrive\Desktop\kovcheg\security_tests\side_channel\side_channel_analysis.py", line 75, in __init__
    self.logger.info("\U0001f6e1\ufe0f ARK Side-Channel Analyzer initialized with Biblical protection")
Message: '\U0001f6e1\ufe0f ARK Side-Channel Analyzer initialized with Biblical protection'
Arguments: ()
2025-06-11 23:13:58,029 - ARK_INTEGRATION - INFO - \U0001f6e1\ufe0f ARK Side-Channel Analyzer initialized with Biblical protection
--- Logging error ---
Traceback (most recent call last):
  File "C:\Program Files\Python311\Lib\logging\__init__.py", line 1113, in emit
    stream.write(msg + self.terminator)
  File "C:\Program Files\Python311\Lib\encodings\cp1251.py", line 19, in encode
    return codecs.charmap_encode(input,self.errors,encoding_table)[0]
           ^^^^^^^^^^^^^^^^^^^^^^^^^^^^^^^^^^^^^^^^^^^^^^^^^^^^^^^
UnicodeEncodeError: 'charmap' codec can't encode character '\U0001f4dc' in position 51: character maps to <undefined>
Call stack:
  File "C:\Users\gabbi\OneDrive\Desktop\kovcheg\tests\integration\ark_system_integration_test.py", line 849, in <module>
    asyncio.run(main())
  File "C:\Program Files\Python311\Lib\asyncio\runners.py", line 190, in run
    return runner.run(main)
  File "C:\Program Files\Python311\Lib\asyncio\runners.py", line 118, in run
    return self._loop.run_until_complete(task)
  File "C:\Program Files\Python311\Lib\asyncio\base_events.py", line 640, in run_until_complete
    self.run_forever()
  File "C:\Program Files\Python311\Lib\asyncio\windows_events.py", line 321, in run_forever
    super().run_forever()
  File "C:\Program Files\Python311\Lib\asyncio\base_events.py", line 607, in run_forever
    self._run_once()
  File "C:\Program Files\Python311\Lib\asyncio\base_events.py", line 1922, in _run_once
    handle._run()
  File "C:\Program Files\Python311\Lib\asyncio\events.py", line 80, in _run
    self._context.run(self._callback, *self._args)
  File "C:\Users\gabbi\OneDrive\Desktop\kovcheg\tests\integration\ark_system_integration_test.py", line 847, in main
    await tester.run_full_integration_test_suite()
  File "C:\Users\gabbi\OneDrive\Desktop\kovcheg\tests\integration\ark_system_integration_test.py", line 711, in run_full_integration_test_suite
    await test_method()
  File "C:\Users\gabbi\OneDrive\Desktop\kovcheg\tests\integration\ark_system_integration_test.py", line 483, in test_side_channel_resistance
    analyzer = BiblicalSideChannelAnalyzer(config)
  File "C:\Users\gabbi\OneDrive\Desktop\kovcheg\security_tests\side_channel\side_channel_analysis.py", line 76, in __init__
    self.logger.info(f"\U0001f4dc Foundation: {BIBLICAL_FOUNDATION}")
Message: '\U0001f4dc Foundation: Matthew_10_16_Be_wise_as_serpents_and_innocent_as_doves'
Arguments: ()
2025-06-11 23:13:58,031 - ARK_INTEGRATION - INFO - \U0001f4dc Foundation: Matthew_10_16_Be_wise_as_serpents_and_innocent_as_doves
--- Logging error ---
Traceback (most recent call last):
  File "C:\Program Files\Python311\Lib\logging\__init__.py", line 1113, in emit
    stream.write(msg + self.terminator)
  File "C:\Program Files\Python311\Lib\encodings\cp1251.py", line 19, in encode
    return codecs.charmap_encode(input,self.errors,encoding_table)[0]
           ^^^^^^^^^^^^^^^^^^^^^^^^^^^^^^^^^^^^^^^^^^^^^^^^^^^^^^^
UnicodeEncodeError: 'charmap' codec can't encode character '\U0001f50b' in position 51: character maps to <undefined>
Call stack:
  File "C:\Users\gabbi\OneDrive\Desktop\kovcheg\tests\integration\ark_system_integration_test.py", line 849, in <module>
    asyncio.run(main())
  File "C:\Program Files\Python311\Lib\asyncio\runners.py", line 190, in run
    return runner.run(main)
  File "C:\Program Files\Python311\Lib\asyncio\runners.py", line 118, in run
    return self._loop.run_until_complete(task)
  File "C:\Program Files\Python311\Lib\asyncio\base_events.py", line 640, in run_until_complete
    self.run_forever()
  File "C:\Program Files\Python311\Lib\asyncio\windows_events.py", line 321, in run_forever
    super().run_forever()
  File "C:\Program Files\Python311\Lib\asyncio\base_events.py", line 607, in run_forever
    self._run_once()
  File "C:\Program Files\Python311\Lib\asyncio\base_events.py", line 1922, in _run_once
    handle._run()
  File "C:\Program Files\Python311\Lib\asyncio\events.py", line 80, in _run
    self._context.run(self._callback, *self._args)
  File "C:\Users\gabbi\OneDrive\Desktop\kovcheg\tests\integration\ark_system_integration_test.py", line 847, in main
    await tester.run_full_integration_test_suite()
  File "C:\Users\gabbi\OneDrive\Desktop\kovcheg\tests\integration\ark_system_integration_test.py", line 711, in run_full_integration_test_suite
    await test_method()
  File "C:\Users\gabbi\OneDrive\Desktop\kovcheg\tests\integration\ark_system_integration_test.py", line 490, in test_side_channel_resistance
    power_result = analyzer.analyze_power_consumption(
  File "C:\Users\gabbi\OneDrive\Desktop\kovcheg\security_tests\side_channel\side_channel_analysis.py", line 113, in analyze_power_consumption
    self.logger.info("\U0001f50b Starting power consumption analysis")
Message: '\U0001f50b Starting power consumption analysis'
Arguments: ()
2025-06-11 23:13:58,034 - ARK_INTEGRATION - INFO - \U0001f50b Starting power consumption analysis
--- Logging error ---
Traceback (most recent call last):
  File "C:\Program Files\Python311\Lib\logging\__init__.py", line 1113, in emit
    stream.write(msg + self.terminator)
  File "C:\Program Files\Python311\Lib\encodings\cp1251.py", line 19, in encode
    return codecs.charmap_encode(input,self.errors,encoding_table)[0]
           ^^^^^^^^^^^^^^^^^^^^^^^^^^^^^^^^^^^^^^^^^^^^^^^^^^^^^^^
UnicodeEncodeError: 'charmap' codec can't encode character '\u2705' in position 51: character maps to <undefined>
Call stack:
  File "C:\Users\gabbi\OneDrive\Desktop\kovcheg\tests\integration\ark_system_integration_test.py", line 849, in <module>
    asyncio.run(main())
  File "C:\Program Files\Python311\Lib\asyncio\runners.py", line 190, in run
    return runner.run(main)
  File "C:\Program Files\Python311\Lib\asyncio\runners.py", line 118, in run
    return self._loop.run_until_complete(task)
  File "C:\Program Files\Python311\Lib\asyncio\base_events.py", line 640, in run_until_complete
    self.run_forever()
  File "C:\Program Files\Python311\Lib\asyncio\windows_events.py", line 321, in run_forever
    super().run_forever()
  File "C:\Program Files\Python311\Lib\asyncio\base_events.py", line 607, in run_forever
    self._run_once()
  File "C:\Program Files\Python311\Lib\asyncio\base_events.py", line 1922, in _run_once
    handle._run()
  File "C:\Program Files\Python311\Lib\asyncio\events.py", line 80, in _run
    self._context.run(self._callback, *self._args)
  File "C:\Users\gabbi\OneDrive\Desktop\kovcheg\tests\integration\ark_system_integration_test.py", line 847, in main
    await tester.run_full_integration_test_suite()
  File "C:\Users\gabbi\OneDrive\Desktop\kovcheg\tests\integration\ark_system_integration_test.py", line 711, in run_full_integration_test_suite
    await test_method()
  File "C:\Users\gabbi\OneDrive\Desktop\kovcheg\tests\integration\ark_system_integration_test.py", line 490, in test_side_channel_resistance
    power_result = analyzer.analyze_power_consumption(
  File "C:\Users\gabbi\OneDrive\Desktop\kovcheg\security_tests\side_channel\side_channel_analysis.py", line 168, in analyze_power_consumption
    self.logger.info(f"\u2705 Power analysis complete - SNR: {snr:.4f}, Protection: {protection_level}")
Message: '\u2705 Power analysis complete - SNR: 0.0859, Protection: Excellent'
Arguments: ()
2025-06-11 23:13:58,039 - ARK_INTEGRATION - INFO - \u2705 Power analysis complete - SNR: 0.0859, Protection: Excellent
--- Logging error ---
Traceback (most recent call last):
  File "C:\Program Files\Python311\Lib\logging\__init__.py", line 1113, in emit
    stream.write(msg + self.terminator)
  File "C:\Program Files\Python311\Lib\encodings\cp1251.py", line 19, in encode
    return codecs.charmap_encode(input,self.errors,encoding_table)[0]
           ^^^^^^^^^^^^^^^^^^^^^^^^^^^^^^^^^^^^^^^^^^^^^^^^^^^^^^^
UnicodeEncodeError: 'charmap' codec can't encode character '\U0001f4e1' in position 51: character maps to <undefined>
Call stack:
  File "C:\Users\gabbi\OneDrive\Desktop\kovcheg\tests\integration\ark_system_integration_test.py", line 849, in <module>
    asyncio.run(main())
  File "C:\Program Files\Python311\Lib\asyncio\runners.py", line 190, in run
    return runner.run(main)
  File "C:\Program Files\Python311\Lib\asyncio\runners.py", line 118, in run
    return self._loop.run_until_complete(task)
  File "C:\Program Files\Python311\Lib\asyncio\base_events.py", line 640, in run_until_complete
    self.run_forever()
  File "C:\Program Files\Python311\Lib\asyncio\windows_events.py", line 321, in run_forever
    super().run_forever()
  File "C:\Program Files\Python311\Lib\asyncio\base_events.py", line 607, in run_forever
    self._run_once()
  File "C:\Program Files\Python311\Lib\asyncio\base_events.py", line 1922, in _run_once
    handle._run()
  File "C:\Program Files\Python311\Lib\asyncio\events.py", line 80, in _run
    self._context.run(self._callback, *self._args)
  File "C:\Users\gabbi\OneDrive\Desktop\kovcheg\tests\integration\ark_system_integration_test.py", line 847, in main
    await tester.run_full_integration_test_suite()
  File "C:\Users\gabbi\OneDrive\Desktop\kovcheg\tests\integration\ark_system_integration_test.py", line 711, in run_full_integration_test_suite
    await test_method()
  File "C:\Users\gabbi\OneDrive\Desktop\kovcheg\tests\integration\ark_system_integration_test.py", line 496, in test_side_channel_resistance
    em_result = analyzer.analyze_electromagnetic_emissions(
  File "C:\Users\gabbi\OneDrive\Desktop\kovcheg\security_tests\side_channel\side_channel_analysis.py", line 333, in analyze_electromagnetic_emissions
    self.logger.info("\U0001f4e1 Starting electromagnetic emission analysis")
Message: '\U0001f4e1 Starting electromagnetic emission analysis'
Arguments: ()
2025-06-11 23:13:58,043 - ARK_INTEGRATION - INFO - \U0001f4e1 Starting electromagnetic emission analysis
--- Logging error ---
Traceback (most recent call last):
  File "C:\Program Files\Python311\Lib\logging\__init__.py", line 1113, in emit
    stream.write(msg + self.terminator)
  File "C:\Program Files\Python311\Lib\encodings\cp1251.py", line 19, in encode
    return codecs.charmap_encode(input,self.errors,encoding_table)[0]
           ^^^^^^^^^^^^^^^^^^^^^^^^^^^^^^^^^^^^^^^^^^^^^^^^^^^^^^^
UnicodeEncodeError: 'charmap' codec can't encode character '\u2705' in position 51: character maps to <undefined>
Call stack:
  File "C:\Users\gabbi\OneDrive\Desktop\kovcheg\tests\integration\ark_system_integration_test.py", line 849, in <module>
    asyncio.run(main())
  File "C:\Program Files\Python311\Lib\asyncio\runners.py", line 190, in run
    return runner.run(main)
  File "C:\Program Files\Python311\Lib\asyncio\runners.py", line 118, in run
    return self._loop.run_until_complete(task)
  File "C:\Program Files\Python311\Lib\asyncio\base_events.py", line 640, in run_until_complete
    self.run_forever()
  File "C:\Program Files\Python311\Lib\asyncio\windows_events.py", line 321, in run_forever
    super().run_forever()
  File "C:\Program Files\Python311\Lib\asyncio\base_events.py", line 607, in run_forever
    self._run_once()
  File "C:\Program Files\Python311\Lib\asyncio\base_events.py", line 1922, in _run_once
    handle._run()
  File "C:\Program Files\Python311\Lib\asyncio\events.py", line 80, in _run
    self._context.run(self._callback, *self._args)
  File "C:\Users\gabbi\OneDrive\Desktop\kovcheg\tests\integration\ark_system_integration_test.py", line 847, in main
    await tester.run_full_integration_test_suite()
  File "C:\Users\gabbi\OneDrive\Desktop\kovcheg\tests\integration\ark_system_integration_test.py", line 711, in run_full_integration_test_suite
    await test_method()
  File "C:\Users\gabbi\OneDrive\Desktop\kovcheg\tests\integration\ark_system_integration_test.py", line 496, in test_side_channel_resistance
    em_result = analyzer.analyze_electromagnetic_emissions(
  File "C:\Users\gabbi\OneDrive\Desktop\kovcheg\security_tests\side_channel\side_channel_analysis.py", line 396, in analyze_electromagnetic_emissions
    self.logger.info(f"\u2705 EM analysis complete - Peak: {peak_power:.2f} dBm, SNR: {snr:.2f} dB")
Message: '\u2705 EM analysis complete - Peak: 47.11 dBm, SNR: 0.16 dB'
Arguments: ()
2025-06-11 23:14:14,662 - ARK_INTEGRATION - INFO - \u2705 EM analysis complete - Peak: 47.11 dBm, SNR: 0.16 dB
--- Logging error ---
Traceback (most recent call last):
  File "C:\Program Files\Python311\Lib\logging\__init__.py", line 1113, in emit
    stream.write(msg + self.terminator)
  File "C:\Program Files\Python311\Lib\encodings\cp1251.py", line 19, in encode
    return codecs.charmap_encode(input,self.errors,encoding_table)[0]
           ^^^^^^^^^^^^^^^^^^^^^^^^^^^^^^^^^^^^^^^^^^^^^^^^^^^^^^^
UnicodeEncodeError: 'charmap' codec can't encode character '\U0001f50d' in position 51: character maps to <undefined>
Call stack:
  File "C:\Users\gabbi\OneDrive\Desktop\kovcheg\tests\integration\ark_system_integration_test.py", line 849, in <module>
    asyncio.run(main())
  File "C:\Program Files\Python311\Lib\asyncio\runners.py", line 190, in run
    return runner.run(main)
  File "C:\Program Files\Python311\Lib\asyncio\runners.py", line 118, in run
    return self._loop.run_until_complete(task)
  File "C:\Program Files\Python311\Lib\asyncio\base_events.py", line 640, in run_until_complete
    self.run_forever()
  File "C:\Program Files\Python311\Lib\asyncio\windows_events.py", line 321, in run_forever
    super().run_forever()
  File "C:\Program Files\Python311\Lib\asyncio\base_events.py", line 607, in run_forever
    self._run_once()
  File "C:\Program Files\Python311\Lib\asyncio\base_events.py", line 1922, in _run_once
    handle._run()
  File "C:\Program Files\Python311\Lib\asyncio\events.py", line 80, in _run
    self._context.run(self._callback, *self._args)
  File "C:\Users\gabbi\OneDrive\Desktop\kovcheg\tests\integration\ark_system_integration_test.py", line 847, in main
    await tester.run_full_integration_test_suite()
  File "C:\Users\gabbi\OneDrive\Desktop\kovcheg\tests\integration\ark_system_integration_test.py", line 711, in run_full_integration_test_suite
    await test_method()
  File "C:\Users\gabbi\OneDrive\Desktop\kovcheg\tests\integration\ark_system_integration_test.py", line 506, in test_side_channel_resistance
    self.logger.info(f"\U0001f50d Power SNR: {power_result.snr_measured:.6f}, Biblical: {power_result.biblical_compliance}")
Message: '\U0001f50d Power SNR: 0.085873, Biblical: True'
Arguments: ()
2025-06-11 23:14:14,665 - ARK_INTEGRATION - INFO - \U0001f50d Power SNR: 0.085873, Biblical: True
--- Logging error ---
Traceback (most recent call last):
  File "C:\Program Files\Python311\Lib\logging\__init__.py", line 1113, in emit
    stream.write(msg + self.terminator)
  File "C:\Program Files\Python311\Lib\encodings\cp1251.py", line 19, in encode
    return codecs.charmap_encode(input,self.errors,encoding_table)[0]
           ^^^^^^^^^^^^^^^^^^^^^^^^^^^^^^^^^^^^^^^^^^^^^^^^^^^^^^^
UnicodeEncodeError: 'charmap' codec can't encode character '\U0001f50d' in position 51: character maps to <undefined>
Call stack:
  File "C:\Users\gabbi\OneDrive\Desktop\kovcheg\tests\integration\ark_system_integration_test.py", line 849, in <module>
    asyncio.run(main())
  File "C:\Program Files\Python311\Lib\asyncio\runners.py", line 190, in run
    return runner.run(main)
  File "C:\Program Files\Python311\Lib\asyncio\runners.py", line 118, in run
    return self._loop.run_until_complete(task)
  File "C:\Program Files\Python311\Lib\asyncio\base_events.py", line 640, in run_until_complete
    self.run_forever()
  File "C:\Program Files\Python311\Lib\asyncio\windows_events.py", line 321, in run_forever
    super().run_forever()
  File "C:\Program Files\Python311\Lib\asyncio\base_events.py", line 607, in run_forever
    self._run_once()
  File "C:\Program Files\Python311\Lib\asyncio\base_events.py", line 1922, in _run_once
    handle._run()
  File "C:\Program Files\Python311\Lib\asyncio\events.py", line 80, in _run
    self._context.run(self._callback, *self._args)
  File "C:\Users\gabbi\OneDrive\Desktop\kovcheg\tests\integration\ark_system_integration_test.py", line 847, in main
    await tester.run_full_integration_test_suite()
  File "C:\Users\gabbi\OneDrive\Desktop\kovcheg\tests\integration\ark_system_integration_test.py", line 711, in run_full_integration_test_suite
    await test_method()
  File "C:\Users\gabbi\OneDrive\Desktop\kovcheg\tests\integration\ark_system_integration_test.py", line 507, in test_side_channel_resistance
    self.logger.info(f"\U0001f50d EM SNR: {em_result.snr_measured:.6f}, Biblical: {em_result.biblical_compliance}")
Message: '\U0001f50d EM SNR: 0.157592, Biblical: False'
Arguments: ()
2025-06-11 23:14:14,667 - ARK_INTEGRATION - INFO - \U0001f50d EM SNR: 0.157592, Biblical: False
--- Logging error ---
Traceback (most recent call last):
  File "C:\Program Files\Python311\Lib\logging\__init__.py", line 1113, in emit
    stream.write(msg + self.terminator)
  File "C:\Program Files\Python311\Lib\encodings\cp1251.py", line 19, in encode
    return codecs.charmap_encode(input,self.errors,encoding_table)[0]
           ^^^^^^^^^^^^^^^^^^^^^^^^^^^^^^^^^^^^^^^^^^^^^^^^^^^^^^^
UnicodeEncodeError: 'charmap' codec can't encode character '\U0001f50d' in position 51: character maps to <undefined>
Call stack:
  File "C:\Users\gabbi\OneDrive\Desktop\kovcheg\tests\integration\ark_system_integration_test.py", line 849, in <module>
    asyncio.run(main())
  File "C:\Program Files\Python311\Lib\asyncio\runners.py", line 190, in run
    return runner.run(main)
  File "C:\Program Files\Python311\Lib\asyncio\runners.py", line 118, in run
    return self._loop.run_until_complete(task)
  File "C:\Program Files\Python311\Lib\asyncio\base_events.py", line 640, in run_until_complete
    self.run_forever()
  File "C:\Program Files\Python311\Lib\asyncio\windows_events.py", line 321, in run_forever
    super().run_forever()
  File "C:\Program Files\Python311\Lib\asyncio\base_events.py", line 607, in run_forever
    self._run_once()
  File "C:\Program Files\Python311\Lib\asyncio\base_events.py", line 1922, in _run_once
    handle._run()
  File "C:\Program Files\Python311\Lib\asyncio\events.py", line 80, in _run
    self._context.run(self._callback, *self._args)
  File "C:\Users\gabbi\OneDrive\Desktop\kovcheg\tests\integration\ark_system_integration_test.py", line 847, in main
    await tester.run_full_integration_test_suite()
  File "C:\Users\gabbi\OneDrive\Desktop\kovcheg\tests\integration\ark_system_integration_test.py", line 711, in run_full_integration_test_suite
    await test_method()
  File "C:\Users\gabbi\OneDrive\Desktop\kovcheg\tests\integration\ark_system_integration_test.py", line 508, in test_side_channel_resistance
    self.logger.info(f"\U0001f50d Max SNR: {max_snr:.6f}")
Message: '\U0001f50d Max SNR: 0.157592'
Arguments: ()
2025-06-11 23:14:14,670 - ARK_INTEGRATION - INFO - \U0001f50d Max SNR: 0.157592
--- Logging error ---
Traceback (most recent call last):
  File "C:\Program Files\Python311\Lib\logging\__init__.py", line 1113, in emit
    stream.write(msg + self.terminator)
  File "C:\Program Files\Python311\Lib\encodings\cp1251.py", line 19, in encode
    return codecs.charmap_encode(input,self.errors,encoding_table)[0]
           ^^^^^^^^^^^^^^^^^^^^^^^^^^^^^^^^^^^^^^^^^^^^^^^^^^^^^^^
UnicodeEncodeError: 'charmap' codec can't encode character '\u274c' in position 51: character maps to <undefined>
Call stack:
  File "C:\Users\gabbi\OneDrive\Desktop\kovcheg\tests\integration\ark_system_integration_test.py", line 849, in <module>
    asyncio.run(main())
  File "C:\Program Files\Python311\Lib\asyncio\runners.py", line 190, in run
    return runner.run(main)
  File "C:\Program Files\Python311\Lib\asyncio\runners.py", line 118, in run
    return self._loop.run_until_complete(task)
  File "C:\Program Files\Python311\Lib\asyncio\base_events.py", line 640, in run_until_complete
    self.run_forever()
  File "C:\Program Files\Python311\Lib\asyncio\windows_events.py", line 321, in run_forever
    super().run_forever()
  File "C:\Program Files\Python311\Lib\asyncio\base_events.py", line 607, in run_forever
    self._run_once()
  File "C:\Program Files\Python311\Lib\asyncio\base_events.py", line 1922, in _run_once
    handle._run()
  File "C:\Program Files\Python311\Lib\asyncio\events.py", line 80, in _run
    self._context.run(self._callback, *self._args)
  File "C:\Users\gabbi\OneDrive\Desktop\kovcheg\tests\integration\ark_system_integration_test.py", line 847, in main
    await tester.run_full_integration_test_suite()
  File "C:\Users\gabbi\OneDrive\Desktop\kovcheg\tests\integration\ark_system_integration_test.py", line 711, in run_full_integration_test_suite
    await test_method()
  File "C:\Users\gabbi\OneDrive\Desktop\kovcheg\tests\integration\ark_system_integration_test.py", line 514, in test_side_channel_resistance
    self._record_test_result(
  File "C:\Users\gabbi\OneDrive\Desktop\kovcheg\tests\integration\ark_system_integration_test.py", line 145, in _record_test_result
    self.logger.info(f"{status} {compliance} - {test_name}")
Message: '\u274c FAIL \U0001f480 VIOLATION - Side-Channel Resistance'
Arguments: ()
2025-06-11 23:14:14,672 - ARK_INTEGRATION - INFO - \u274c FAIL \U0001f480 VIOLATION - Side-Channel Resistance
2025-06-11 23:14:14,674 - ARK_INTEGRATION - INFO -     SRS-REQ: SEC-02
2025-06-11 23:14:14,674 - ARK_INTEGRATION - INFO -     Measured: 0.157592, Threshold: 1.000000
--- Logging error ---
Traceback (most recent call last):
  File "C:\Program Files\Python311\Lib\logging\__init__.py", line 1113, in emit
    stream.write(msg + self.terminator)
  File "C:\Program Files\Python311\Lib\encodings\cp1251.py", line 19, in encode
    return codecs.charmap_encode(input,self.errors,encoding_table)[0]
           ^^^^^^^^^^^^^^^^^^^^^^^^^^^^^^^^^^^^^^^^^^^^^^^^^^^^^^^
UnicodeEncodeError: 'charmap' codec can't encode characters in position 51-52: character maps to <undefined>
Call stack:
  File "C:\Users\gabbi\OneDrive\Desktop\kovcheg\tests\integration\ark_system_integration_test.py", line 849, in <module>
    asyncio.run(main())
  File "C:\Program Files\Python311\Lib\asyncio\runners.py", line 190, in run
    return runner.run(main)
  File "C:\Program Files\Python311\Lib\asyncio\runners.py", line 118, in run
    return self._loop.run_until_complete(task)
  File "C:\Program Files\Python311\Lib\asyncio\base_events.py", line 640, in run_until_complete
    self.run_forever()
  File "C:\Program Files\Python311\Lib\asyncio\windows_events.py", line 321, in run_forever
    super().run_forever()
  File "C:\Program Files\Python311\Lib\asyncio\base_events.py", line 607, in run_forever
    self._run_once()
  File "C:\Program Files\Python311\Lib\asyncio\base_events.py", line 1922, in _run_once
    handle._run()
  File "C:\Program Files\Python311\Lib\asyncio\events.py", line 80, in _run
    self._context.run(self._callback, *self._args)
  File "C:\Users\gabbi\OneDrive\Desktop\kovcheg\tests\integration\ark_system_integration_test.py", line 847, in main
    await tester.run_full_integration_test_suite()
  File "C:\Users\gabbi\OneDrive\Desktop\kovcheg\tests\integration\ark_system_integration_test.py", line 711, in run_full_integration_test_suite
    await test_method()
  File "C:\Users\gabbi\OneDrive\Desktop\kovcheg\tests\integration\ark_system_integration_test.py", line 537, in test_frost_signature_security
    self.logger.info("\u2744\ufe0f Testing FROST signature security (SEC-03)")
Message: '\u2744\ufe0f Testing FROST signature security (SEC-03)'
Arguments: ()
2025-06-11 23:14:14,674 - ARK_INTEGRATION - INFO - \u2744\ufe0f Testing FROST signature security (SEC-03)
--- Logging error ---
Traceback (most recent call last):
  File "C:\Program Files\Python311\Lib\logging\__init__.py", line 1113, in emit
    stream.write(msg + self.terminator)
  File "C:\Program Files\Python311\Lib\encodings\cp1251.py", line 19, in encode
    return codecs.charmap_encode(input,self.errors,encoding_table)[0]
           ^^^^^^^^^^^^^^^^^^^^^^^^^^^^^^^^^^^^^^^^^^^^^^^^^^^^^^^
UnicodeEncodeError: 'charmap' codec can't encode character '\u2705' in position 51: character maps to <undefined>
Call stack:
  File "C:\Users\gabbi\OneDrive\Desktop\kovcheg\tests\integration\ark_system_integration_test.py", line 849, in <module>
    asyncio.run(main())
  File "C:\Program Files\Python311\Lib\asyncio\runners.py", line 190, in run
    return runner.run(main)
  File "C:\Program Files\Python311\Lib\asyncio\runners.py", line 118, in run
    return self._loop.run_until_complete(task)
  File "C:\Program Files\Python311\Lib\asyncio\base_events.py", line 640, in run_until_complete
    self.run_forever()
  File "C:\Program Files\Python311\Lib\asyncio\windows_events.py", line 321, in run_forever
    super().run_forever()
  File "C:\Program Files\Python311\Lib\asyncio\base_events.py", line 607, in run_forever
    self._run_once()
  File "C:\Program Files\Python311\Lib\asyncio\base_events.py", line 1922, in _run_once
    handle._run()
  File "C:\Program Files\Python311\Lib\asyncio\events.py", line 80, in _run
    self._context.run(self._callback, *self._args)
  File "C:\Users\gabbi\OneDrive\Desktop\kovcheg\tests\integration\ark_system_integration_test.py", line 847, in main
    await tester.run_full_integration_test_suite()
  File "C:\Users\gabbi\OneDrive\Desktop\kovcheg\tests\integration\ark_system_integration_test.py", line 711, in run_full_integration_test_suite
    await test_method()
  File "C:\Users\gabbi\OneDrive\Desktop\kovcheg\tests\integration\ark_system_integration_test.py", line 573, in test_frost_signature_security
    self._record_test_result(
  File "C:\Users\gabbi\OneDrive\Desktop\kovcheg\tests\integration\ark_system_integration_test.py", line 145, in _record_test_result
    self.logger.info(f"{status} {compliance} - {test_name}")
Message: '\u2705 PASS \U0001f54a\ufe0f COMPLIANT - FROST Signature Security'
Arguments: ()
2025-06-11 23:14:14,676 - ARK_INTEGRATION - INFO - \u2705 PASS \U0001f54a\ufe0f COMPLIANT - FROST Signature Security
2025-06-11 23:14:14,677 - ARK_INTEGRATION - INFO -     SRS-REQ: SEC-03
2025-06-11 23:14:14,677 - ARK_INTEGRATION - INFO -     Measured: 128.000000, Threshold: 128.000000
--- Logging error ---
Traceback (most recent call last):
  File "C:\Program Files\Python311\Lib\logging\__init__.py", line 1113, in emit
    stream.write(msg + self.terminator)
  File "C:\Program Files\Python311\Lib\encodings\cp1251.py", line 19, in encode
    return codecs.charmap_encode(input,self.errors,encoding_table)[0]
           ^^^^^^^^^^^^^^^^^^^^^^^^^^^^^^^^^^^^^^^^^^^^^^^^^^^^^^^
UnicodeEncodeError: 'charmap' codec can't encode characters in position 51-52: character maps to <undefined>
Call stack:
  File "C:\Users\gabbi\OneDrive\Desktop\kovcheg\tests\integration\ark_system_integration_test.py", line 849, in <module>
    asyncio.run(main())
  File "C:\Program Files\Python311\Lib\asyncio\runners.py", line 190, in run
    return runner.run(main)
  File "C:\Program Files\Python311\Lib\asyncio\runners.py", line 118, in run
    return self._loop.run_until_complete(task)
  File "C:\Program Files\Python311\Lib\asyncio\base_events.py", line 640, in run_until_complete
    self.run_forever()
  File "C:\Program Files\Python311\Lib\asyncio\windows_events.py", line 321, in run_forever
    super().run_forever()
  File "C:\Program Files\Python311\Lib\asyncio\base_events.py", line 607, in run_forever
    self._run_once()
  File "C:\Program Files\Python311\Lib\asyncio\base_events.py", line 1922, in _run_once
    handle._run()
  File "C:\Program Files\Python311\Lib\asyncio\events.py", line 80, in _run
    self._context.run(self._callback, *self._args)
  File "C:\Users\gabbi\OneDrive\Desktop\kovcheg\tests\integration\ark_system_integration_test.py", line 847, in main
    await tester.run_full_integration_test_suite()
  File "C:\Users\gabbi\OneDrive\Desktop\kovcheg\tests\integration\ark_system_integration_test.py", line 711, in run_full_integration_test_suite
    await test_method()
  File "C:\Users\gabbi\OneDrive\Desktop\kovcheg\tests\integration\ark_system_integration_test.py", line 596, in test_end_to_end_moral_decision
    self.logger.info("\U0001f6e1\ufe0f Testing end-to-end moral decision pipeline")
Message: '\U0001f6e1\ufe0f Testing end-to-end moral decision pipeline'
Arguments: ()
2025-06-11 23:14:14,677 - ARK_INTEGRATION - INFO - \U0001f6e1\ufe0f Testing end-to-end moral decision pipeline
--- Logging error ---
Traceback (most recent call last):
  File "C:\Users\gabbi\OneDrive\Desktop\kovcheg\tests\integration\ark_system_integration_test.py", line 601, in test_end_to_end_moral_decision
    await harm_predictor.initialize()
  File "C:\Users\gabbi\OneDrive\Desktop\kovcheg\software/cold_mirror/src\lib.py", line 82, in initialize
    print("\U0001f6e1\ufe0f Enhanced AGI protection initialized")
  File "C:\Program Files\Python311\Lib\encodings\cp1251.py", line 19, in encode
    return codecs.charmap_encode(input,self.errors,encoding_table)[0]
           ^^^^^^^^^^^^^^^^^^^^^^^^^^^^^^^^^^^^^^^^^^^^^^^^^^^^^^^
UnicodeEncodeError: 'charmap' codec can't encode characters in position 0-1: character maps to <undefined>

During handling of the above exception, another exception occurred:

Traceback (most recent call last):
  File "C:\Program Files\Python311\Lib\logging\__init__.py", line 1113, in emit
    stream.write(msg + self.terminator)
  File "C:\Program Files\Python311\Lib\encodings\cp1251.py", line 19, in encode
    return codecs.charmap_encode(input,self.errors,encoding_table)[0]
           ^^^^^^^^^^^^^^^^^^^^^^^^^^^^^^^^^^^^^^^^^^^^^^^^^^^^^^^
UnicodeEncodeError: 'charmap' codec can't encode character '\u274c' in position 51: character maps to <undefined>
Call stack:
  File "C:\Users\gabbi\OneDrive\Desktop\kovcheg\tests\integration\ark_system_integration_test.py", line 849, in <module>
    asyncio.run(main())
  File "C:\Program Files\Python311\Lib\asyncio\runners.py", line 190, in run
    return runner.run(main)
  File "C:\Program Files\Python311\Lib\asyncio\runners.py", line 118, in run
    return self._loop.run_until_complete(task)
  File "C:\Program Files\Python311\Lib\asyncio\base_events.py", line 640, in run_until_complete
    self.run_forever()
  File "C:\Program Files\Python311\Lib\asyncio\windows_events.py", line 321, in run_forever
    super().run_forever()
  File "C:\Program Files\Python311\Lib\asyncio\base_events.py", line 607, in run_forever
    self._run_once()
  File "C:\Program Files\Python311\Lib\asyncio\base_events.py", line 1922, in _run_once
    handle._run()
  File "C:\Program Files\Python311\Lib\asyncio\events.py", line 80, in _run
    self._context.run(self._callback, *self._args)
  File "C:\Users\gabbi\OneDrive\Desktop\kovcheg\tests\integration\ark_system_integration_test.py", line 847, in main
    await tester.run_full_integration_test_suite()
  File "C:\Users\gabbi\OneDrive\Desktop\kovcheg\tests\integration\ark_system_integration_test.py", line 711, in run_full_integration_test_suite
    await test_method()
  File "C:\Users\gabbi\OneDrive\Desktop\kovcheg\tests\integration\ark_system_integration_test.py", line 671, in test_end_to_end_moral_decision
    self._record_test_result(
  File "C:\Users\gabbi\OneDrive\Desktop\kovcheg\tests\integration\ark_system_integration_test.py", line 145, in _record_test_result
    self.logger.info(f"{status} {compliance} - {test_name}")
Message: '\u274c FAIL \U0001f480 VIOLATION - End-to-End Moral Decision Pipeline'
Arguments: ()
2025-06-11 23:14:14,699 - ARK_INTEGRATION - INFO - \u274c FAIL \U0001f480 VIOLATION - End-to-End Moral Decision Pipeline
2025-06-11 23:14:14,703 - ARK_INTEGRATION - INFO -     SRS-REQ: SYSTEM-INTEGRATION
2025-06-11 23:14:14,704 - ARK_INTEGRATION - INFO -     Measured: 0.000000, Threshold: 100.000000
2025-06-11 23:14:14,704 - ARK_INTEGRATION - ERROR -     Error: 'charmap' codec can't encode characters in position 0-1: character maps to <undefined>
2025-06-11 23:14:14,706 - ARK_INTEGRATION - INFO - ================================================================================
--- Logging error ---
Traceback (most recent call last):
  File "C:\Program Files\Python311\Lib\logging\__init__.py", line 1113, in emit
    stream.write(msg + self.terminator)
  File "C:\Program Files\Python311\Lib\encodings\cp1251.py", line 19, in encode
    return codecs.charmap_encode(input,self.errors,encoding_table)[0]
           ^^^^^^^^^^^^^^^^^^^^^^^^^^^^^^^^^^^^^^^^^^^^^^^^^^^^^^^
UnicodeEncodeError: 'charmap' codec can't encode characters in position 51-52: character maps to <undefined>
Call stack:
  File "C:\Users\gabbi\OneDrive\Desktop\kovcheg\tests\integration\ark_system_integration_test.py", line 849, in <module>
    asyncio.run(main())
  File "C:\Program Files\Python311\Lib\asyncio\runners.py", line 190, in run
    return runner.run(main)
  File "C:\Program Files\Python311\Lib\asyncio\runners.py", line 118, in run
    return self._loop.run_until_complete(task)
  File "C:\Program Files\Python311\Lib\asyncio\base_events.py", line 640, in run_until_complete
    self.run_forever()
  File "C:\Program Files\Python311\Lib\asyncio\windows_events.py", line 321, in run_forever
    super().run_forever()
  File "C:\Program Files\Python311\Lib\asyncio\base_events.py", line 607, in run_forever
    self._run_once()
  File "C:\Program Files\Python311\Lib\asyncio\base_events.py", line 1922, in _run_once
    handle._run()
  File "C:\Program Files\Python311\Lib\asyncio\events.py", line 80, in _run
    self._context.run(self._callback, *self._args)
  File "C:\Users\gabbi\OneDrive\Desktop\kovcheg\tests\integration\ark_system_integration_test.py", line 847, in main
    await tester.run_full_integration_test_suite()
  File "C:\Users\gabbi\OneDrive\Desktop\kovcheg\tests\integration\ark_system_integration_test.py", line 719, in run_full_integration_test_suite
    self._log_test_summary(report)
  File "C:\Users\gabbi\OneDrive\Desktop\kovcheg\tests\integration\ark_system_integration_test.py", line 808, in _log_test_summary
    self.logger.info("\U0001f6e1\ufe0f ARK SYSTEM INTEGRATION TEST SUMMARY")
Message: '\U0001f6e1\ufe0f ARK SYSTEM INTEGRATION TEST SUMMARY'
Arguments: ()
2025-06-11 23:14:14,706 - ARK_INTEGRATION - INFO - \U0001f6e1\ufe0f ARK SYSTEM INTEGRATION TEST SUMMARY
2025-06-11 23:14:14,708 - ARK_INTEGRATION - INFO - ================================================================================
--- Logging error ---
Traceback (most recent call last):
  File "C:\Program Files\Python311\Lib\logging\__init__.py", line 1113, in emit
    stream.write(msg + self.terminator)
  File "C:\Program Files\Python311\Lib\encodings\cp1251.py", line 19, in encode
    return codecs.charmap_encode(input,self.errors,encoding_table)[0]
           ^^^^^^^^^^^^^^^^^^^^^^^^^^^^^^^^^^^^^^^^^^^^^^^^^^^^^^^
UnicodeEncodeError: 'charmap' codec can't encode character '\U0001f4dc' in position 51: character maps to <undefined>
Call stack:
  File "C:\Users\gabbi\OneDrive\Desktop\kovcheg\tests\integration\ark_system_integration_test.py", line 849, in <module>
    asyncio.run(main())
  File "C:\Program Files\Python311\Lib\asyncio\runners.py", line 190, in run
    return runner.run(main)
  File "C:\Program Files\Python311\Lib\asyncio\runners.py", line 118, in run
    return self._loop.run_until_complete(task)
  File "C:\Program Files\Python311\Lib\asyncio\base_events.py", line 640, in run_until_complete
    self.run_forever()
  File "C:\Program Files\Python311\Lib\asyncio\windows_events.py", line 321, in run_forever
    super().run_forever()
  File "C:\Program Files\Python311\Lib\asyncio\base_events.py", line 607, in run_forever
    self._run_once()
  File "C:\Program Files\Python311\Lib\asyncio\base_events.py", line 1922, in _run_once
    handle._run()
  File "C:\Program Files\Python311\Lib\asyncio\events.py", line 80, in _run
    self._context.run(self._callback, *self._args)
  File "C:\Users\gabbi\OneDrive\Desktop\kovcheg\tests\integration\ark_system_integration_test.py", line 847, in main
    await tester.run_full_integration_test_suite()
  File "C:\Users\gabbi\OneDrive\Desktop\kovcheg\tests\integration\ark_system_integration_test.py", line 719, in run_full_integration_test_suite
    self._log_test_summary(report)
  File "C:\Users\gabbi\OneDrive\Desktop\kovcheg\tests\integration\ark_system_integration_test.py", line 810, in _log_test_summary
    self.logger.info(f"\U0001f4dc Biblical Foundation: {BIBLICAL_FOUNDATION}")
Message: '\U0001f4dc Biblical Foundation: 1_Thessalonians_5_21_Test_everything_hold_fast_what_is_good'
Arguments: ()
2025-06-11 23:14:14,708 - ARK_INTEGRATION - INFO - \U0001f4dc Biblical Foundation: 1_Thessalonians_5_21_Test_everything_hold_fast_what_is_good
--- Logging error ---
Traceback (most recent call last):
  File "C:\Program Files\Python311\Lib\logging\__init__.py", line 1113, in emit
    stream.write(msg + self.terminator)
  File "C:\Program Files\Python311\Lib\encodings\cp1251.py", line 19, in encode
    return codecs.charmap_encode(input,self.errors,encoding_table)[0]
           ^^^^^^^^^^^^^^^^^^^^^^^^^^^^^^^^^^^^^^^^^^^^^^^^^^^^^^^
UnicodeEncodeError: 'charmap' codec can't encode character '\U0001f451' in position 51: character maps to <undefined>
Call stack:
  File "C:\Users\gabbi\OneDrive\Desktop\kovcheg\tests\integration\ark_system_integration_test.py", line 849, in <module>
    asyncio.run(main())
  File "C:\Program Files\Python311\Lib\asyncio\runners.py", line 190, in run
    return runner.run(main)
  File "C:\Program Files\Python311\Lib\asyncio\runners.py", line 118, in run
    return self._loop.run_until_complete(task)
  File "C:\Program Files\Python311\Lib\asyncio\base_events.py", line 640, in run_until_complete
    self.run_forever()
  File "C:\Program Files\Python311\Lib\asyncio\windows_events.py", line 321, in run_forever
    super().run_forever()
  File "C:\Program Files\Python311\Lib\asyncio\base_events.py", line 607, in run_forever
    self._run_once()
  File "C:\Program Files\Python311\Lib\asyncio\base_events.py", line 1922, in _run_once
    handle._run()
  File "C:\Program Files\Python311\Lib\asyncio\events.py", line 80, in _run
    self._context.run(self._callback, *self._args)
  File "C:\Users\gabbi\OneDrive\Desktop\kovcheg\tests\integration\ark_system_integration_test.py", line 847, in main
    await tester.run_full_integration_test_suite()
  File "C:\Users\gabbi\OneDrive\Desktop\kovcheg\tests\integration\ark_system_integration_test.py", line 719, in run_full_integration_test_suite
    self._log_test_summary(report)
  File "C:\Users\gabbi\OneDrive\Desktop\kovcheg\tests\integration\ark_system_integration_test.py", line 811, in _log_test_summary
    self.logger.info(f"\U0001f451 Divine Authority: {DIVINE_AUTHORITY}")
Message: '\U0001f451 Divine Authority: Romans_13_1_Let_every_soul_be_subject_to_governing_authorities'
Arguments: ()
2025-06-11 23:14:14,709 - ARK_INTEGRATION - INFO - \U0001f451 Divine Authority: Romans_13_1_Let_every_soul_be_subject_to_governing_authorities
2025-06-11 23:14:14,711 - ARK_INTEGRATION - INFO - 
--- Logging error ---
Traceback (most recent call last):
  File "C:\Program Files\Python311\Lib\logging\__init__.py", line 1113, in emit
    stream.write(msg + self.terminator)
  File "C:\Program Files\Python311\Lib\encodings\cp1251.py", line 19, in encode
    return codecs.charmap_encode(input,self.errors,encoding_table)[0]
           ^^^^^^^^^^^^^^^^^^^^^^^^^^^^^^^^^^^^^^^^^^^^^^^^^^^^^^^
UnicodeEncodeError: 'charmap' codec can't encode character '\U0001f4ca' in position 51: character maps to <undefined>
Call stack:
  File "C:\Users\gabbi\OneDrive\Desktop\kovcheg\tests\integration\ark_system_integration_test.py", line 849, in <module>
    asyncio.run(main())
  File "C:\Program Files\Python311\Lib\asyncio\runners.py", line 190, in run
    return runner.run(main)
  File "C:\Program Files\Python311\Lib\asyncio\runners.py", line 118, in run
    return self._loop.run_until_complete(task)
  File "C:\Program Files\Python311\Lib\asyncio\base_events.py", line 640, in run_until_complete
    self.run_forever()
  File "C:\Program Files\Python311\Lib\asyncio\windows_events.py", line 321, in run_forever
    super().run_forever()
  File "C:\Program Files\Python311\Lib\asyncio\base_events.py", line 607, in run_forever
    self._run_once()
  File "C:\Program Files\Python311\Lib\asyncio\base_events.py", line 1922, in _run_once
    handle._run()
  File "C:\Program Files\Python311\Lib\asyncio\events.py", line 80, in _run
    self._context.run(self._callback, *self._args)
  File "C:\Users\gabbi\OneDrive\Desktop\kovcheg\tests\integration\ark_system_integration_test.py", line 847, in main
    await tester.run_full_integration_test_suite()
  File "C:\Users\gabbi\OneDrive\Desktop\kovcheg\tests\integration\ark_system_integration_test.py", line 719, in run_full_integration_test_suite
    self._log_test_summary(report)
  File "C:\Users\gabbi\OneDrive\Desktop\kovcheg\tests\integration\ark_system_integration_test.py", line 813, in _log_test_summary
    self.logger.info(f"\U0001f4ca Total Tests: {report['summary']['total_tests']}")
Message: '\U0001f4ca Total Tests: 8'
Arguments: ()
2025-06-11 23:14:14,711 - ARK_INTEGRATION - INFO - \U0001f4ca Total Tests: 8
--- Logging error ---
Traceback (most recent call last):
  File "C:\Program Files\Python311\Lib\logging\__init__.py", line 1113, in emit
    stream.write(msg + self.terminator)
  File "C:\Program Files\Python311\Lib\encodings\cp1251.py", line 19, in encode
    return codecs.charmap_encode(input,self.errors,encoding_table)[0]
           ^^^^^^^^^^^^^^^^^^^^^^^^^^^^^^^^^^^^^^^^^^^^^^^^^^^^^^^
UnicodeEncodeError: 'charmap' codec can't encode character '\u2705' in position 51: character maps to <undefined>
Call stack:
  File "C:\Users\gabbi\OneDrive\Desktop\kovcheg\tests\integration\ark_system_integration_test.py", line 849, in <module>
    asyncio.run(main())
  File "C:\Program Files\Python311\Lib\asyncio\runners.py", line 190, in run
    return runner.run(main)
  File "C:\Program Files\Python311\Lib\asyncio\runners.py", line 118, in run
    return self._loop.run_until_complete(task)
  File "C:\Program Files\Python311\Lib\asyncio\base_events.py", line 640, in run_until_complete
    self.run_forever()
  File "C:\Program Files\Python311\Lib\asyncio\windows_events.py", line 321, in run_forever
    super().run_forever()
  File "C:\Program Files\Python311\Lib\asyncio\base_events.py", line 607, in run_forever
    self._run_once()
  File "C:\Program Files\Python311\Lib\asyncio\base_events.py", line 1922, in _run_once
    handle._run()
  File "C:\Program Files\Python311\Lib\asyncio\events.py", line 80, in _run
    self._context.run(self._callback, *self._args)
  File "C:\Users\gabbi\OneDrive\Desktop\kovcheg\tests\integration\ark_system_integration_test.py", line 847, in main
    await tester.run_full_integration_test_suite()
  File "C:\Users\gabbi\OneDrive\Desktop\kovcheg\tests\integration\ark_system_integration_test.py", line 719, in run_full_integration_test_suite
    self._log_test_summary(report)
  File "C:\Users\gabbi\OneDrive\Desktop\kovcheg\tests\integration\ark_system_integration_test.py", line 814, in _log_test_summary
    self.logger.info(f"\u2705 Passed: {report['summary']['passed_tests']}")
Message: '\u2705 Passed: 5'
Arguments: ()
2025-06-11 23:14:14,713 - ARK_INTEGRATION - INFO - \u2705 Passed: 5
--- Logging error ---
Traceback (most recent call last):
  File "C:\Program Files\Python311\Lib\logging\__init__.py", line 1113, in emit
    stream.write(msg + self.terminator)
  File "C:\Program Files\Python311\Lib\encodings\cp1251.py", line 19, in encode
    return codecs.charmap_encode(input,self.errors,encoding_table)[0]
           ^^^^^^^^^^^^^^^^^^^^^^^^^^^^^^^^^^^^^^^^^^^^^^^^^^^^^^^
UnicodeEncodeError: 'charmap' codec can't encode character '\u274c' in position 51: character maps to <undefined>
Call stack:
  File "C:\Users\gabbi\OneDrive\Desktop\kovcheg\tests\integration\ark_system_integration_test.py", line 849, in <module>
    asyncio.run(main())
  File "C:\Program Files\Python311\Lib\asyncio\runners.py", line 190, in run
    return runner.run(main)
  File "C:\Program Files\Python311\Lib\asyncio\runners.py", line 118, in run
    return self._loop.run_until_complete(task)
  File "C:\Program Files\Python311\Lib\asyncio\base_events.py", line 640, in run_until_complete
    self.run_forever()
  File "C:\Program Files\Python311\Lib\asyncio\windows_events.py", line 321, in run_forever
    super().run_forever()
  File "C:\Program Files\Python311\Lib\asyncio\base_events.py", line 607, in run_forever
    self._run_once()
  File "C:\Program Files\Python311\Lib\asyncio\base_events.py", line 1922, in _run_once
    handle._run()
  File "C:\Program Files\Python311\Lib\asyncio\events.py", line 80, in _run
    self._context.run(self._callback, *self._args)
  File "C:\Users\gabbi\OneDrive\Desktop\kovcheg\tests\integration\ark_system_integration_test.py", line 847, in main
    await tester.run_full_integration_test_suite()
  File "C:\Users\gabbi\OneDrive\Desktop\kovcheg\tests\integration\ark_system_integration_test.py", line 719, in run_full_integration_test_suite
    self._log_test_summary(report)
  File "C:\Users\gabbi\OneDrive\Desktop\kovcheg\tests\integration\ark_system_integration_test.py", line 815, in _log_test_summary
    self.logger.info(f"\u274c Failed: {report['summary']['failed_tests']}")
Message: '\u274c Failed: 3'
Arguments: ()
2025-06-11 23:14:14,715 - ARK_INTEGRATION - INFO - \u274c Failed: 3
--- Logging error ---
Traceback (most recent call last):
  File "C:\Program Files\Python311\Lib\logging\__init__.py", line 1113, in emit
    stream.write(msg + self.terminator)
  File "C:\Program Files\Python311\Lib\encodings\cp1251.py", line 19, in encode
    return codecs.charmap_encode(input,self.errors,encoding_table)[0]
           ^^^^^^^^^^^^^^^^^^^^^^^^^^^^^^^^^^^^^^^^^^^^^^^^^^^^^^^
UnicodeEncodeError: 'charmap' codec can't encode characters in position 51-52: character maps to <undefined>
Call stack:
  File "C:\Users\gabbi\OneDrive\Desktop\kovcheg\tests\integration\ark_system_integration_test.py", line 849, in <module>
    asyncio.run(main())
  File "C:\Program Files\Python311\Lib\asyncio\runners.py", line 190, in run
    return runner.run(main)
  File "C:\Program Files\Python311\Lib\asyncio\runners.py", line 118, in run
    return self._loop.run_until_complete(task)
  File "C:\Program Files\Python311\Lib\asyncio\base_events.py", line 640, in run_until_complete
    self.run_forever()
  File "C:\Program Files\Python311\Lib\asyncio\windows_events.py", line 321, in run_forever
    super().run_forever()
  File "C:\Program Files\Python311\Lib\asyncio\base_events.py", line 607, in run_forever
    self._run_once()
  File "C:\Program Files\Python311\Lib\asyncio\base_events.py", line 1922, in _run_once
    handle._run()
  File "C:\Program Files\Python311\Lib\asyncio\events.py", line 80, in _run
    self._context.run(self._callback, *self._args)
  File "C:\Users\gabbi\OneDrive\Desktop\kovcheg\tests\integration\ark_system_integration_test.py", line 847, in main
    await tester.run_full_integration_test_suite()
  File "C:\Users\gabbi\OneDrive\Desktop\kovcheg\tests\integration\ark_system_integration_test.py", line 719, in run_full_integration_test_suite
    self._log_test_summary(report)
  File "C:\Users\gabbi\OneDrive\Desktop\kovcheg\tests\integration\ark_system_integration_test.py", line 816, in _log_test_summary
    self.logger.info(f"\U0001f54a\ufe0f Biblical Compliant: {report['summary']['biblical_compliant']}")
Message: '\U0001f54a\ufe0f Biblical Compliant: 5'
Arguments: ()
2025-06-11 23:14:14,717 - ARK_INTEGRATION - INFO - \U0001f54a\ufe0f Biblical Compliant: 5
--- Logging error ---
Traceback (most recent call last):
  File "C:\Program Files\Python311\Lib\logging\__init__.py", line 1113, in emit
    stream.write(msg + self.terminator)
  File "C:\Program Files\Python311\Lib\encodings\cp1251.py", line 19, in encode
    return codecs.charmap_encode(input,self.errors,encoding_table)[0]
           ^^^^^^^^^^^^^^^^^^^^^^^^^^^^^^^^^^^^^^^^^^^^^^^^^^^^^^^
UnicodeEncodeError: 'charmap' codec can't encode character '\U0001f4c8' in position 51: character maps to <undefined>
Call stack:
  File "C:\Users\gabbi\OneDrive\Desktop\kovcheg\tests\integration\ark_system_integration_test.py", line 849, in <module>
    asyncio.run(main())
  File "C:\Program Files\Python311\Lib\asyncio\runners.py", line 190, in run
    return runner.run(main)
  File "C:\Program Files\Python311\Lib\asyncio\runners.py", line 118, in run
    return self._loop.run_until_complete(task)
  File "C:\Program Files\Python311\Lib\asyncio\base_events.py", line 640, in run_until_complete
    self.run_forever()
  File "C:\Program Files\Python311\Lib\asyncio\windows_events.py", line 321, in run_forever
    super().run_forever()
  File "C:\Program Files\Python311\Lib\asyncio\base_events.py", line 607, in run_forever
    self._run_once()
  File "C:\Program Files\Python311\Lib\asyncio\base_events.py", line 1922, in _run_once
    handle._run()
  File "C:\Program Files\Python311\Lib\asyncio\events.py", line 80, in _run
    self._context.run(self._callback, *self._args)
  File "C:\Users\gabbi\OneDrive\Desktop\kovcheg\tests\integration\ark_system_integration_test.py", line 847, in main
    await tester.run_full_integration_test_suite()
  File "C:\Users\gabbi\OneDrive\Desktop\kovcheg\tests\integration\ark_system_integration_test.py", line 719, in run_full_integration_test_suite
    self._log_test_summary(report)
  File "C:\Users\gabbi\OneDrive\Desktop\kovcheg\tests\integration\ark_system_integration_test.py", line 817, in _log_test_summary
    self.logger.info(f"\U0001f4c8 Pass Rate: {report['summary']['pass_rate']:.1%}")
Message: '\U0001f4c8 Pass Rate: 62.5%'
Arguments: ()
2025-06-11 23:14:14,719 - ARK_INTEGRATION - INFO - \U0001f4c8 Pass Rate: 62.5%
--- Logging error ---
Traceback (most recent call last):
  File "C:\Program Files\Python311\Lib\logging\__init__.py", line 1113, in emit
    stream.write(msg + self.terminator)
  File "C:\Program Files\Python311\Lib\encodings\cp1251.py", line 19, in encode
    return codecs.charmap_encode(input,self.errors,encoding_table)[0]
           ^^^^^^^^^^^^^^^^^^^^^^^^^^^^^^^^^^^^^^^^^^^^^^^^^^^^^^^
UnicodeEncodeError: 'charmap' codec can't encode character '\U0001f4dc' in position 51: character maps to <undefined>
Call stack:
  File "C:\Users\gabbi\OneDrive\Desktop\kovcheg\tests\integration\ark_system_integration_test.py", line 849, in <module>
    asyncio.run(main())
  File "C:\Program Files\Python311\Lib\asyncio\runners.py", line 190, in run
    return runner.run(main)
  File "C:\Program Files\Python311\Lib\asyncio\runners.py", line 118, in run
    return self._loop.run_until_complete(task)
  File "C:\Program Files\Python311\Lib\asyncio\base_events.py", line 640, in run_until_complete
    self.run_forever()
  File "C:\Program Files\Python311\Lib\asyncio\windows_events.py", line 321, in run_forever
    super().run_forever()
  File "C:\Program Files\Python311\Lib\asyncio\base_events.py", line 607, in run_forever
    self._run_once()
  File "C:\Program Files\Python311\Lib\asyncio\base_events.py", line 1922, in _run_once
    handle._run()
  File "C:\Program Files\Python311\Lib\asyncio\events.py", line 80, in _run
    self._context.run(self._callback, *self._args)
  File "C:\Users\gabbi\OneDrive\Desktop\kovcheg\tests\integration\ark_system_integration_test.py", line 847, in main
    await tester.run_full_integration_test_suite()
  File "C:\Users\gabbi\OneDrive\Desktop\kovcheg\tests\integration\ark_system_integration_test.py", line 719, in run_full_integration_test_suite
    self._log_test_summary(report)
  File "C:\Users\gabbi\OneDrive\Desktop\kovcheg\tests\integration\ark_system_integration_test.py", line 818, in _log_test_summary
    self.logger.info(f"\U0001f4dc Biblical Compliance Rate: {report['summary']['biblical_compliance_rate']:.1%}")
Message: '\U0001f4dc Biblical Compliance Rate: 62.5%'
Arguments: ()
2025-06-11 23:14:14,720 - ARK_INTEGRATION - INFO - \U0001f4dc Biblical Compliance Rate: 62.5%
--- Logging error ---
Traceback (most recent call last):
  File "C:\Program Files\Python311\Lib\logging\__init__.py", line 1113, in emit
    stream.write(msg + self.terminator)
  File "C:\Program Files\Python311\Lib\encodings\cp1251.py", line 19, in encode
    return codecs.charmap_encode(input,self.errors,encoding_table)[0]
           ^^^^^^^^^^^^^^^^^^^^^^^^^^^^^^^^^^^^^^^^^^^^^^^^^^^^^^^
UnicodeEncodeError: 'charmap' codec can't encode characters in position 51-52: character maps to <undefined>
Call stack:
  File "C:\Users\gabbi\OneDrive\Desktop\kovcheg\tests\integration\ark_system_integration_test.py", line 849, in <module>
    asyncio.run(main())
  File "C:\Program Files\Python311\Lib\asyncio\runners.py", line 190, in run
    return runner.run(main)
  File "C:\Program Files\Python311\Lib\asyncio\runners.py", line 118, in run
    return self._loop.run_until_complete(task)
  File "C:\Program Files\Python311\Lib\asyncio\base_events.py", line 640, in run_until_complete
    self.run_forever()
  File "C:\Program Files\Python311\Lib\asyncio\windows_events.py", line 321, in run_forever
    super().run_forever()
  File "C:\Program Files\Python311\Lib\asyncio\base_events.py", line 607, in run_forever
    self._run_once()
  File "C:\Program Files\Python311\Lib\asyncio\base_events.py", line 1922, in _run_once
    handle._run()
  File "C:\Program Files\Python311\Lib\asyncio\events.py", line 80, in _run
    self._context.run(self._callback, *self._args)
  File "C:\Users\gabbi\OneDrive\Desktop\kovcheg\tests\integration\ark_system_integration_test.py", line 847, in main
    await tester.run_full_integration_test_suite()
  File "C:\Users\gabbi\OneDrive\Desktop\kovcheg\tests\integration\ark_system_integration_test.py", line 719, in run_full_integration_test_suite
    self._log_test_summary(report)
  File "C:\Users\gabbi\OneDrive\Desktop\kovcheg\tests\integration\ark_system_integration_test.py", line 819, in _log_test_summary
    self.logger.info(f"\u23f1\ufe0f Total Execution Time: {report['test_metadata']['total_execution_time']:.3f}s")
Message: '\u23f1\ufe0f Total Execution Time: 16.905s'
Arguments: ()
2025-06-11 23:14:14,722 - ARK_INTEGRATION - INFO - \u23f1\ufe0f Total Execution Time: 16.905s
2025-06-11 23:14:14,724 - ARK_INTEGRATION - WARNING - 
--- Logging error ---
Traceback (most recent call last):
  File "C:\Program Files\Python311\Lib\logging\__init__.py", line 1113, in emit
    stream.write(msg + self.terminator)
  File "C:\Program Files\Python311\Lib\encodings\cp1251.py", line 19, in encode
    return codecs.charmap_encode(input,self.errors,encoding_table)[0]
           ^^^^^^^^^^^^^^^^^^^^^^^^^^^^^^^^^^^^^^^^^^^^^^^^^^^^^^^
UnicodeEncodeError: 'charmap' codec can't encode characters in position 54-55: character maps to <undefined>
Call stack:
  File "C:\Users\gabbi\OneDrive\Desktop\kovcheg\tests\integration\ark_system_integration_test.py", line 849, in <module>
    asyncio.run(main())
  File "C:\Program Files\Python311\Lib\asyncio\runners.py", line 190, in run
    return runner.run(main)
  File "C:\Program Files\Python311\Lib\asyncio\runners.py", line 118, in run
    return self._loop.run_until_complete(task)
  File "C:\Program Files\Python311\Lib\asyncio\base_events.py", line 640, in run_until_complete
    self.run_forever()
  File "C:\Program Files\Python311\Lib\asyncio\windows_events.py", line 321, in run_forever
    super().run_forever()
  File "C:\Program Files\Python311\Lib\asyncio\base_events.py", line 607, in run_forever
    self._run_once()
  File "C:\Program Files\Python311\Lib\asyncio\base_events.py", line 1922, in _run_once
    handle._run()
  File "C:\Program Files\Python311\Lib\asyncio\events.py", line 80, in _run
    self._context.run(self._callback, *self._args)
  File "C:\Users\gabbi\OneDrive\Desktop\kovcheg\tests\integration\ark_system_integration_test.py", line 847, in main
    await tester.run_full_integration_test_suite()
  File "C:\Users\gabbi\OneDrive\Desktop\kovcheg\tests\integration\ark_system_integration_test.py", line 719, in run_full_integration_test_suite
    self._log_test_summary(report)
  File "C:\Users\gabbi\OneDrive\Desktop\kovcheg\tests\integration\ark_system_integration_test.py", line 827, in _log_test_summary
    self.logger.warning("\u26a0\ufe0f SOME TESTS FAILED - SYSTEM REQUIRES ATTENTION")
Message: '\u26a0\ufe0f SOME TESTS FAILED - SYSTEM REQUIRES ATTENTION'
Arguments: ()
2025-06-11 23:14:14,724 - ARK_INTEGRATION - WARNING - \u26a0\ufe0f SOME TESTS FAILED - SYSTEM REQUIRES ATTENTION
--- Logging error ---
Traceback (most recent call last):
  File "C:\Program Files\Python311\Lib\logging\__init__.py", line 1113, in emit
    stream.write(msg + self.terminator)
  File "C:\Program Files\Python311\Lib\encodings\cp1251.py", line 19, in encode
    return codecs.charmap_encode(input,self.errors,encoding_table)[0]
           ^^^^^^^^^^^^^^^^^^^^^^^^^^^^^^^^^^^^^^^^^^^^^^^^^^^^^^^
UnicodeEncodeError: 'charmap' codec can't encode character '\U0001f527' in position 54: character maps to <undefined>
Call stack:
  File "C:\Users\gabbi\OneDrive\Desktop\kovcheg\tests\integration\ark_system_integration_test.py", line 849, in <module>
    asyncio.run(main())
  File "C:\Program Files\Python311\Lib\asyncio\runners.py", line 190, in run
    return runner.run(main)
  File "C:\Program Files\Python311\Lib\asyncio\runners.py", line 118, in run
    return self._loop.run_until_complete(task)
  File "C:\Program Files\Python311\Lib\asyncio\base_events.py", line 640, in run_until_complete
    self.run_forever()
  File "C:\Program Files\Python311\Lib\asyncio\windows_events.py", line 321, in run_forever
    super().run_forever()
  File "C:\Program Files\Python311\Lib\asyncio\base_events.py", line 607, in run_forever
    self._run_once()
  File "C:\Program Files\Python311\Lib\asyncio\base_events.py", line 1922, in _run_once
    handle._run()
  File "C:\Program Files\Python311\Lib\asyncio\events.py", line 80, in _run
    self._context.run(self._callback, *self._args)
  File "C:\Users\gabbi\OneDrive\Desktop\kovcheg\tests\integration\ark_system_integration_test.py", line 847, in main
    await tester.run_full_integration_test_suite()
  File "C:\Users\gabbi\OneDrive\Desktop\kovcheg\tests\integration\ark_system_integration_test.py", line 719, in run_full_integration_test_suite
    self._log_test_summary(report)
  File "C:\Users\gabbi\OneDrive\Desktop\kovcheg\tests\integration\ark_system_integration_test.py", line 828, in _log_test_summary
    self.logger.warning("\U0001f527 Please review failed tests and implement necessary corrections")
Message: '\U0001f527 Please review failed tests and implement necessary corrections'
Arguments: ()
2025-06-11 23:14:14,726 - ARK_INTEGRATION - WARNING - \U0001f527 Please review failed tests and implement necessary corrections
2025-06-11 23:14:14,727 - ARK_INTEGRATION - INFO - ================================================================================
